Workbook

Sheet Dashboard
A1: Parabolic Motion Radar + Topography Parameter Model
A2: Use Inputs!C27 to apply/remove topography from the main outputs and charts. Inputs!C47 changes the terrain seed. Long-pass scenario ranges use Europa spherical curvature instead of flat Cartesian range. Off-nadir means the side-looking target at Inputs!C6, while nadir means straight below the spacecraft.
A4: Key Output Results
A5: Output | B5: Value | C5: Unit | D5: What it means
A6: Topography toggle | B6: =IF(OR(Inputs!$C$27=TRUE,Inputs!$C$27="TRUE",Inputs!$C$27=1),"Topography ON","Topography OFF") | D6: Set Inputs!C27 to TRUE to include terrain, or FALSE to return to a flat surface. Change Inputs!C47 to test a new terrain case.
A7: Flat apparent depth at mid-pass | B7: =Model_Data!F122 | C7: m | D7: Original flat-surface result.
A8: Topo apparent depth at mid-pass | B8: =Model_Data!AC122 | C8: m | D8: Apparent depth after terrain height changes the range geometry.
A9: Depth change from topography | B9: =Model_Data!AI122 | C9: m | D9: Topo apparent depth minus flat apparent depth.
A10: Topo extra two-way delay | B10: =Model_Data!AD122 | C10: us | D10: Two-way delay after topography is included.
A11: Topo VHF interferometric phase | B11: =Model_Data!AF122 | C11: deg | D11: VHF phase after topography changes the look geometry.
A12: Max target terrain height | B12: =MAX(Model_Data!Y2:Y242) | C12: m | D12: Highest modeled terrain at the side-offset target path.
A13: Min target terrain height | B13: =MIN(Model_Data!Y2:Y242) | C13: m | D13: Lowest modeled terrain at the side-offset target path.
A14: Max absolute topo depth change | B14: =MAX(MAX(Model_Data!AI2:AI242),-MIN(Model_Data!AI2:AI242)) | C14: m | D14: Largest magnitude of topography-driven apparent-depth change.
A15: Max topo VHF Doppler magnitude | B15: =MAX(Model_Data!AO2:AO242) | C15: Hz | D15: Largest VHF Doppler after topography is included.
A16: Simple minimum PRF with topo | B16: =2*B15 | C16: Hz | D16: Twice max topo VHF Doppler, a simple no-alias floor.
A17: Topo depth uncertainty band | B17: =Model_Data!AQ122 | C17: m | D17: Representative vertical uncertainty converted to apparent-depth uncertainty.
A19: PRF Choices
A20: PRF (Hz) | B20: Pulse interval (ms) | C20: Along-track spacing (m) | D20: Unambiguous range (km) | E20: Pulses in air at z0 | F20: Status
A21: =PRF_Results!A4 | B21: =PRF_Results!B4 | C21: =PRF_Results!C4 | D21: =PRF_Results!D4 | E21: =PRF_Results!E4 | F21: =PRF_Results!F4
A22: =PRF_Results!A5 | B22: =PRF_Results!B5 | C22: =PRF_Results!C5 | D22: =PRF_Results!D5 | E22: =PRF_Results!E5 | F22: =PRF_Results!F5
A23: =PRF_Results!A6 | B23: =PRF_Results!B6 | C23: =PRF_Results!C6 | D23: =PRF_Results!D6 | E23: =PRF_Results!E6 | F23: =PRF_Results!F6
A25: How to read this model
A26: The chain is: parabolic motion changes z(x); topography adds h(x,y); the radar then turns that real surface pattern into an apparent range/depth shift. The off-nadir target is the side-looking point at y = Inputs!C6; nadir is the straight-down reference. Flat means flat surface, not straight spacecraft motion.
A114: Paper Pass Scenario Comparison
A115: Scenario | B115: Show | C115: z0 (km) | D115: Length (km) | E115: Edge alt (km) | F115: Mid depth (m) | G115: Max VHF (Hz) | H115: PRF floor (Hz) | I115: Basis
A116: =Inputs!G6 | B116: =Inputs!F6 | C116: =Inputs!H6 | D116: =Inputs!J6-Inputs!I6 | E116: =Inputs!M6 | F116: =Scenario_Data!AF122 | G116: =MAX(MAX(Scenario_Data!AL2:AL242),-MIN(Scenario_Data!AL2:AL242)) | H116: =2*G116 | I116: Current editable
A117: =Inputs!G7 | B117: =Inputs!F7 | C117: =Inputs!H7 | D117: =Inputs!J7-Inputs!I7 | E117: =Inputs!M7 | F117: =Scenario_Data!AG122 | G117: =MAX(MAX(Scenario_Data!AM2:AM242),-MIN(Scenario_Data!AM2:AM242)) | H117: =2*G117 | I117: 800 km below 400
A118: =Inputs!G8 | B118: =Inputs!F8 | C118: =Inputs!H8 | D118: =Inputs!J8-Inputs!I8 | E118: =Inputs!M8 | F118: =Scenario_Data!AH122 | G118: =MAX(MAX(Scenario_Data!AN2:AN242),-MIN(Scenario_Data!AN2:AN242)) | H118: =2*G118 | I118: 1600 km below 1000
A119: =Inputs!G9 | B119: =Inputs!F9 | C119: =Inputs!H9 | D119: =Inputs!J9-Inputs!I9 | E119: =Inputs!M9 | F119: =Scenario_Data!AI122 | G119: =MAX(MAX(Scenario_Data!AO2:AO242),-MIN(Scenario_Data!AO2:AO242)) | H119: =2*G119 | I119: 25-1000 km range
A120: Scenario note | B120: Paper numbers are converted into this workbook's simplified parabola so the outcomes can be compared. The paper states altitude ranges and groundtrack requirements, not an exact parabolic spacecraft trajectory.
A122: Quick Graph Guide
A123: Graph | B123: What it is trying to show | F123: How to read the baseline
A124: Apparent depth | B124: Motion and topography change the apparent radar depth relative to the nadir reference. | F124: Grey zero line is a reference, not a plotted terrain/run result.
A125: Surface height | B125: Shows the generated topography used as the reference floor, plus the off-nadir target and nadir terrain heights. The satellite path is curved/parabolic, not flat. | F125: Grey floor now follows the generated topography instead of 0 m; colored lines show target and nadir terrain.
A126: Doppler | B126: Range-rate-driven VHF/HF Doppler, with flat geometry compared against topography-adjusted geometry. | F126: Crossing 0 Hz means the radial motion changes sign near closest approach.
A127: Motion-only / scenarios | B127: The motion-only chart is a radar reading from flat ground. It is not ground height; the curve comes from satellite path and slant-range geometry. | F127: Scenario baselines are grey reference floors; they are intentionally not orange model lines.
A128: Detailed notes | B128: See the Graph_Guide tab for every chart, source range, formula basis, and audit status. | F128: Checks!B4:B23 remains the formula-health checklist.

Sheet Subsurface_Dashboard
A1: Europa Ice Subsurface Interface
A2: Live subsurface outputs from Subsurface_Inputs. The model is synthetic: it helps test what radar might see below icy topography, but it does not prove real Europa layers by itself.
A4: Key Subsurface Results | F4: Realism / Proof Strength
A5: Output | B5: Value | C5: Unit | D5: What it means | F5: Score | G5: Value | H5: Meaning | I5: Improve by
A6: Average bottom depth | B6: =AVERAGE(Subsurface_Live_Data!K2:K242) | C6: m | D6: Mean proposed ice-ocean boundary depth. | F6: Concept realism | G6: 0.7 | H6: Good for showing layered-ice radar behavior. | I6: Compare more scenarios.
A7: Boundary uncertainty band | B7: =Subsurface_Inputs!$C$44 | C7: m | D7: Plus/minus range around bottom reflector. | F7: Europa prediction realism | G7: =MIN(0.75,0.25+Subsurface_Materials_Evidence!D14/100*0.45) | H7: Plausible, but synthetic and not measured. | I7: Use published constraints or real mission data.
A8: Best ocean echo margin | B8: =MAX(Subsurface_Live_Data!Y2:Y242) | C8: dB | D8: How far deep reflector rises above/below threshold. | F8: Proof strength | G8: =MIN(0.6,0.15+Subsurface_Materials_Evidence!D14/100*0.35) | H8: Supports a hypothesis; does not prove a real layer. | I8: Validate with radar, thermal, composition, and magnetic/plasma data.
A9: Best lens echo margin | B9: =MAX(Subsurface_Live_Data!X2:X242) | C9: dB | D9: How far internal lens return rises above/below threshold.
A10: Likely visible ocean samples | B10: =COUNTIF(Subsurface_Live_Data!V2:V242,"Likely visible") | C10: count | D10: Pass samples clearing the detection threshold.
A11: Total evidence support | B11: =Subsurface_Materials_Evidence!D14 | C11: % | D11: Radar + thermal + composition + magnetic/plasma support.
A13: Subsurface Graph Guide
A14: Graph | B14: What it shows | C14: How to read it | F14: Graph | G14: What it shows | H14: How to read it
A15: Icy layers | B15: Top surface, internal ice, lens, and possible ocean boundary. | C15: Lower lines are deeper. | F15: Scenarios | G15: Thin / medium / thick ice shell cases. | H15: Different assumptions change boundary depth.
A16: Uncertainty | B16: Mean bottom boundary with lower/upper bounds. | C16: Band width comes from Subsurface_Inputs. | F16: Control | G16: Ocean model compared with no-ocean control. | H16: Positive margin clears threshold.
A17: Radargram timing | B17: Return delay with surface clutter and jitter. | C17: Later delay means deeper reflector. | F17: Detectability | G17: Lens/ocean echo margin above threshold. | H17: Above 0 dB is easier to detect.
A18: Materials | B18: Reflector strength by material/interface. | C18: Less negative is stronger. | F18: Evidence | G18: Radar, thermal, composition, magnetic/plasma support. | H18: Higher percent means stronger support.

Sheet Doppler_Depth_Inversion
A1: Doppler-Angle Depth Inversion
A2: Main view only: charts plus key live results. The detailed row-by-row numbers that feed the graphs were moved to the Doppler_Depth_Data tab.
A5: Main result | F5: Live inputs | K5: Sample depth point | P5: Simplified method
A6: Mean raw slant error | B6: =SUMPRODUCT(ABS(Doppler_Depth_Data!N4:N244))/ROWS(Doppler_Depth_Data!N4:N244) | C6: m | F6: VHF wavelength | G6: =Inputs!$C$13 | H6: m | K6: x position | L6: =Doppler_Depth_Data!A4 | M6: km | P6: 1 | Q6: Doppler shift gives line-of-sight velocity
A7: Mean corrected error | B7: =SUMPRODUCT(ABS(Doppler_Depth_Data!O4:O244))/ROWS(Doppler_Depth_Data!O4:O244) | C7: m | F7: Spacecraft speed | G7: =Inputs!$C$11*1000 | H7: m/s | K7: True ocean depth | L7: =Doppler_Depth_Data!H4 | M7: m | P7: 2 | Q7: Velocity gives look angle
A8: Max Doppler angle | B8: =MAX(Doppler_Depth_Data!D4:D244) | C8: deg | F8: Ice refractive index | G8: =Inputs!$C$12 | H8: n | K8: Raw slant depth | L8: =Doppler_Depth_Data!L4 | M8: m | P8: 3 | Q8: Echo delay gives slant depth
A9: Depth correction status | B9: =IF(SUMPRODUCT(ABS(Doppler_Depth_Data!O4:O244))/ROWS(Doppler_Depth_Data!O4:O244)<0.000001,"PASS","CHECK") | F9: Speed of light | G9: =Inputs!$C$21 | H9: m/s | K9: Corrected ocean depth | L9: =Doppler_Depth_Data!M4 | M9: m | P9: 4 | Q9: Angle correction gives actual depth
A11: NASA context source | B11: https://science.nasa.gov/mission/europa-clipper/spacecraft-instruments/

Sheet Doppler_Depth_Data
A1: Detailed Doppler Depth Data - feeds the Doppler dashboard charts
A3: x_km | B3: vhf_doppler_hz | C3: radial_velocity_m_s | D3: doppler_angle_deg | E3: geometry_look_angle_deg | F3: true_upper_depth_m | G3: true_lens_depth_m | H3: true_ocean_depth_m | I3: upper_slant_delay_us | J3: lens_slant_delay_us | K3: ocean_slant_delay_us | L3: raw_ocean_slant_depth_m | M3: doppler_corrected_ocean_depth_m | N3: uncorrected_ocean_error_m | O3: corrected_ocean_error_m | P3: correction_removed_m | Q3: raw_lens_slant_depth_m | R3: doppler_corrected_lens_depth_m | S3: doppler_corrected_upper_depth_m
A4: =Subsurface_Live_Data!A2 | B4: =Model_Data!P2 | C4: =ABS(B4)*Inputs!$C$13/2 | D4: =DEGREES(ASIN(MIN(1,C4/(Inputs!$C$11*1000)))) | E4: =Model_Data!I2 | F4: =Subsurface_Live_Data!F2 | G4: =Subsurface_Live_Data!I2 | H4: =Subsurface_Live_Data!K2 | I4: =Subsurface_Live_Data!M2/COS(RADIANS(D4)) | J4: =Subsurface_Live_Data!N2/COS(RADIANS(D4)) | K4: =Subsurface_Live_Data!O2/COS(RADIANS(D4)) | L4: =Inputs!$C$21*K4/(2*Inputs!$C$12*1000000) | M4: =L4*COS(RADIANS(D4)) | N4: =L4-H4 | O4: =M4-H4 | P4: =N4-O4 | Q4: =Inputs!$C$21*J4/(2*Inputs!$C$12*1000000) | R4: =Q4*COS(RADIANS(D4)) | S4: =Inputs!$C$21*I4/(2*Inputs!$C$12*1000000)*COS(RADIANS(D4))
A5: =Subsurface_Live_Data!A3 | B5: =Model_Data!P3 | C5: =ABS(B5)*Inputs!$C$13/2 | D5: =DEGREES(ASIN(MIN(1,C5/(Inputs!$C$11*1000)))) | E5: =Model_Data!I3 | F5: =Subsurface_Live_Data!F3 | G5: =Subsurface_Live_Data!I3 | H5: =Subsurface_Live_Data!K3 | I5: =Subsurface_Live_Data!M3/COS(RADIANS(D5)) | J5: =Subsurface_Live_Data!N3/COS(RADIANS(D5)) | K5: =Subsurface_Live_Data!O3/COS(RADIANS(D5)) | L5: =Inputs!$C$21*K5/(2*Inputs!$C$12*1000000) | M5: =L5*COS(RADIANS(D5)) | N5: =L5-H5 | O5: =M5-H5 | P5: =N5-O5 | Q5: =Inputs!$C$21*J5/(2*Inputs!$C$12*1000000) | R5: =Q5*COS(RADIANS(D5)) | S5: =Inputs!$C$21*I5/(2*Inputs!$C$12*1000000)*COS(RADIANS(D5))
A6: =Subsurface_Live_Data!A4 | B6: =Model_Data!P4 | C6: =ABS(B6)*Inputs!$C$13/2 | D6: =DEGREES(ASIN(MIN(1,C6/(Inputs!$C$11*1000)))) | E6: =Model_Data!I4 | F6: =Subsurface_Live_Data!F4 | G6: =Subsurface_Live_Data!I4 | H6: =Subsurface_Live_Data!K4 | I6: =Subsurface_Live_Data!M4/COS(RADIANS(D6)) | J6: =Subsurface_Live_Data!N4/COS(RADIANS(D6)) | K6: =Subsurface_Live_Data!O4/COS(RADIANS(D6)) | L6: =Inputs!$C$21*K6/(2*Inputs!$C$12*1000000) | M6: =L6*COS(RADIANS(D6)) | N6: =L6-H6 | O6: =M6-H6 | P6: =N6-O6 | Q6: =Inputs!$C$21*J6/(2*Inputs!$C$12*1000000) | R6: =Q6*COS(RADIANS(D6)) | S6: =Inputs!$C$21*I6/(2*Inputs!$C$12*1000000)*COS(RADIANS(D6))
A7: =Subsurface_Live_Data!A5 | B7: =Model_Data!P5 | C7: =ABS(B7)*Inputs!$C$13/2 | D7: =DEGREES(ASIN(MIN(1,C7/(Inputs!$C$11*1000)))) | E7: =Model_Data!I5 | F7: =Subsurface_Live_Data!F5 | G7: =Subsurface_Live_Data!I5 | H7: =Subsurface_Live_Data!K5 | I7: =Subsurface_Live_Data!M5/COS(RADIANS(D7)) | J7: =Subsurface_Live_Data!N5/COS(RADIANS(D7)) | K7: =Subsurface_Live_Data!O5/COS(RADIANS(D7)) | L7: =Inputs!$C$21*K7/(2*Inputs!$C$12*1000000) | M7: =L7*COS(RADIANS(D7)) | N7: =L7-H7 | O7: =M7-H7 | P7: =N7-O7 | Q7: =Inputs!$C$21*J7/(2*Inputs!$C$12*1000000) | R7: =Q7*COS(RADIANS(D7)) | S7: =Inputs!$C$21*I7/(2*Inputs!$C$12*1000000)*COS(RADIANS(D7))
A8: =Subsurface_Live_Data!A6 | B8: =Model_Data!P6 | C8: =ABS(B8)*Inputs!$C$13/2 | D8: =DEGREES(ASIN(MIN(1,C8/(Inputs!$C$11*1000)))) | E8: =Model_Data!I6 | F8: =Subsurface_Live_Data!F6 | G8: =Subsurface_Live_Data!I6 | H8: =Subsurface_Live_Data!K6 | I8: =Subsurface_Live_Data!M6/COS(RADIANS(D8)) | J8: =Subsurface_Live_Data!N6/COS(RADIANS(D8)) | K8: =Subsurface_Live_Data!O6/COS(RADIANS(D8)) | L8: =Inputs!$C$21*K8/(2*Inputs!$C$12*1000000) | M8: =L8*COS(RADIANS(D8)) | N8: =L8-H8 | O8: =M8-H8 | P8: =N8-O8 | Q8: =Inputs!$C$21*J8/(2*Inputs!$C$12*1000000) | R8: =Q8*COS(RADIANS(D8)) | S8: =Inputs!$C$21*I8/(2*Inputs!$C$12*1000000)*COS(RADIANS(D8))
A9: =Subsurface_Live_Data!A7 | B9: =Model_Data!P7 | C9: =ABS(B9)*Inputs!$C$13/2 | D9: =DEGREES(ASIN(MIN(1,C9/(Inputs!$C$11*1000)))) | E9: =Model_Data!I7 | F9: =Subsurface_Live_Data!F7 | G9: =Subsurface_Live_Data!I7 | H9: =Subsurface_Live_Data!K7 | I9: =Subsurface_Live_Data!M7/COS(RADIANS(D9)) | J9: =Subsurface_Live_Data!N7/COS(RADIANS(D9)) | K9: =Subsurface_Live_Data!O7/COS(RADIANS(D9)) | L9: =Inputs!$C$21*K9/(2*Inputs!$C$12*1000000) | M9: =L9*COS(RADIANS(D9)) | N9: =L9-H9 | O9: =M9-H9 | P9: =N9-O9 | Q9: =Inputs!$C$21*J9/(2*Inputs!$C$12*1000000) | R9: =Q9*COS(RADIANS(D9)) | S9: =Inputs!$C$21*I9/(2*Inputs!$C$12*1000000)*COS(RADIANS(D9))
A10: =Subsurface_Live_Data!A8 | B10: =Model_Data!P8 | C10: =ABS(B10)*Inputs!$C$13/2 | D10: =DEGREES(ASIN(MIN(1,C10/(Inputs!$C$11*1000)))) | E10: =Model_Data!I8 | F10: =Subsurface_Live_Data!F8 | G10: =Subsurface_Live_Data!I8 | H10: =Subsurface_Live_Data!K8 | I10: =Subsurface_Live_Data!M8/COS(RADIANS(D10)) | J10: =Subsurface_Live_Data!N8/COS(RADIANS(D10)) | K10: =Subsurface_Live_Data!O8/COS(RADIANS(D10)) | L10: =Inputs!$C$21*K10/(2*Inputs!$C$12*1000000) | M10: =L10*COS(RADIANS(D10)) | N10: =L10-H10 | O10: =M10-H10 | P10: =N10-O10 | Q10: =Inputs!$C$21*J10/(2*Inputs!$C$12*1000000) | R10: =Q10*COS(RADIANS(D10)) | S10: =Inputs!$C$21*I10/(2*Inputs!$C$12*1000000)*COS(RADIANS(D10))
A11: =Subsurface_Live_Data!A9 | B11: =Model_Data!P9 | C11: =ABS(B11)*Inputs!$C$13/2 | D11: =DEGREES(ASIN(MIN(1,C11/(Inputs!$C$11*1000)))) | E11: =Model_Data!I9 | F11: =Subsurface_Live_Data!F9 | G11: =Subsurface_Live_Data!I9 | H11: =Subsurface_Live_Data!K9 | I11: =Subsurface_Live_Data!M9/COS(RADIANS(D11)) | J11: =Subsurface_Live_Data!N9/COS(RADIANS(D11)) | K11: =Subsurface_Live_Data!O9/COS(RADIANS(D11)) | L11: =Inputs!$C$21*K11/(2*Inputs!$C$12*1000000) | M11: =L11*COS(RADIANS(D11)) | N11: =L11-H11 | O11: =M11-H11 | P11: =N11-O11 | Q11: =Inputs!$C$21*J11/(2*Inputs!$C$12*1000000) | R11: =Q11*COS(RADIANS(D11)) | S11: =Inputs!$C$21*I11/(2*Inputs!$C$12*1000000)*COS(RADIANS(D11))
A12: =Subsurface_Live_Data!A10 | B12: =Model_Data!P10 | C12: =ABS(B12)*Inputs!$C$13/2 | D12: =DEGREES(ASIN(MIN(1,C12/(Inputs!$C$11*1000)))) | E12: =Model_Data!I10 | F12: =Subsurface_Live_Data!F10 | G12: =Subsurface_Live_Data!I10 | H12: =Subsurface_Live_Data!K10 | I12: =Subsurface_Live_Data!M10/COS(RADIANS(D12)) | J12: =Subsurface_Live_Data!N10/COS(RADIANS(D12)) | K12: =Subsurface_Live_Data!O10/COS(RADIANS(D12)) | L12: =Inputs!$C$21*K12/(2*Inputs!$C$12*1000000) | M12: =L12*COS(RADIANS(D12)) | N12: =L12-H12 | O12: =M12-H12 | P12: =N12-O12 | Q12: =Inputs!$C$21*J12/(2*Inputs!$C$12*1000000) | R12: =Q12*COS(RADIANS(D12)) | S12: =Inputs!$C$21*I12/(2*Inputs!$C$12*1000000)*COS(RADIANS(D12))
A13: =Subsurface_Live_Data!A11 | B13: =Model_Data!P11 | C13: =ABS(B13)*Inputs!$C$13/2 | D13: =DEGREES(ASIN(MIN(1,C13/(Inputs!$C$11*1000)))) | E13: =Model_Data!I11 | F13: =Subsurface_Live_Data!F11 | G13: =Subsurface_Live_Data!I11 | H13: =Subsurface_Live_Data!K11 | I13: =Subsurface_Live_Data!M11/COS(RADIANS(D13)) | J13: =Subsurface_Live_Data!N11/COS(RADIANS(D13)) | K13: =Subsurface_Live_Data!O11/COS(RADIANS(D13)) | L13: =Inputs!$C$21*K13/(2*Inputs!$C$12*1000000) | M13: =L13*COS(RADIANS(D13)) | N13: =L13-H13 | O13: =M13-H13 | P13: =N13-O13 | Q13: =Inputs!$C$21*J13/(2*Inputs!$C$12*1000000) | R13: =Q13*COS(RADIANS(D13)) | S13: =Inputs!$C$21*I13/(2*Inputs!$C$12*1000000)*COS(RADIANS(D13))
A14: =Subsurface_Live_Data!A12 | B14: =Model_Data!P12 | C14: =ABS(B14)*Inputs!$C$13/2 | D14: =DEGREES(ASIN(MIN(1,C14/(Inputs!$C$11*1000)))) | E14: =Model_Data!I12 | F14: =Subsurface_Live_Data!F12 | G14: =Subsurface_Live_Data!I12 | H14: =Subsurface_Live_Data!K12 | I14: =Subsurface_Live_Data!M12/COS(RADIANS(D14)) | J14: =Subsurface_Live_Data!N12/COS(RADIANS(D14)) | K14: =Subsurface_Live_Data!O12/COS(RADIANS(D14)) | L14: =Inputs!$C$21*K14/(2*Inputs!$C$12*1000000) | M14: =L14*COS(RADIANS(D14)) | N14: =L14-H14 | O14: =M14-H14 | P14: =N14-O14 | Q14: =Inputs!$C$21*J14/(2*Inputs!$C$12*1000000) | R14: =Q14*COS(RADIANS(D14)) | S14: =Inputs!$C$21*I14/(2*Inputs!$C$12*1000000)*COS(RADIANS(D14))
A15: =Subsurface_Live_Data!A13 | B15: =Model_Data!P13 | C15: =ABS(B15)*Inputs!$C$13/2 | D15: =DEGREES(ASIN(MIN(1,C15/(Inputs!$C$11*1000)))) | E15: =Model_Data!I13 | F15: =Subsurface_Live_Data!F13 | G15: =Subsurface_Live_Data!I13 | H15: =Subsurface_Live_Data!K13 | I15: =Subsurface_Live_Data!M13/COS(RADIANS(D15)) | J15: =Subsurface_Live_Data!N13/COS(RADIANS(D15)) | K15: =Subsurface_Live_Data!O13/COS(RADIANS(D15)) | L15: =Inputs!$C$21*K15/(2*Inputs!$C$12*1000000) | M15: =L15*COS(RADIANS(D15)) | N15: =L15-H15 | O15: =M15-H15 | P15: =N15-O15 | Q15: =Inputs!$C$21*J15/(2*Inputs!$C$12*1000000) | R15: =Q15*COS(RADIANS(D15)) | S15: =Inputs!$C$21*I15/(2*Inputs!$C$12*1000000)*COS(RADIANS(D15))
... A244: =Subsurface_Live_Data!A242 | B244: =Model_Data!P242 | C244: =ABS(B244)*Inputs!$C$13/2 | D244: =DEGREES(ASIN(MIN(1,C244/(Inputs!$C$11*1000)))) | E244: =Model_Data!I242 | F244: =Subsurface_Live_Data!F242 | G244: =Subsurface_Live_Data!I242 | H244: =Subsurface_Live_Data!K242 | I244: =Subsurface_Live_Data!M242/COS(RADIANS(D244)) | J244: =Subsurface_Live_Data!N242/COS(RADIANS(D244)) | K244: =Subsurface_Live_Data!O242/COS(RADIANS(D244)) | L244: =Inputs!$C$21*K244/(2*Inputs!$C$12*1000000) | M244: =L244*COS(RADIANS(D244)) | N244: =L244-H244 | O244: =M244-H244 | P244: =N244-O244 | Q244: =Inputs!$C$21*J244/(2*Inputs!$C$12*1000000) | R244: =Q244*COS(RADIANS(D244)) | S244: =Inputs!$C$21*I244/(2*Inputs!$C$12*1000000)*COS(RADIANS(D244))

Sheet Research_Gaps
A1: NASA Research Gap Check - Europa Radar Model
A2: Best framing for your project: NASA is already checking Europa's ice thickness, surface roughness, topography, radar returns, Doppler/gravity evidence, and cross-instrument data. Your strongest angle is not 'NASA forgot this.' It is: this workbook stress-tests one specific interpretation problem where rough ice topography plus Doppler/look-angle correction can make the bottom layer depth look wrong or create a false subsurface signal.
A6: Main research question to use
A7: Question | B7: Can rough/generated Europa ice topography plus Doppler/look-angle correction cause the radar-inferred bottom layer or ocean boundary to be overestimated, underestimated, or confused with a shallow briny layer?
A8: Why it matters | B8: NASA will use radar echoes, surface elevations/roughness, and gravity/Doppler-type measurements together. A small geometry error can turn a slant-path echo into the wrong actual depth.
A9: What your model can add | B9: A simple live sensitivity test showing when topography amplitude, local slope, off-nadir geometry, ice refractive index, and briny lens attenuation push the bottom-layer answer outside a safe error range.
A10: Best claim wording | B10: This simulation tests a possible radar interpretation risk; it does not claim NASA missed the whole problem or that Europa's ocean is proven.
A13: Gap candidates ranked for your workbook
A14: Rank | B14: Possible topic | C14: NASA/source already covers | D14: Possible under-tested angle | E14: Workbook test to add | F14: Best graph | G14: Evidence strength | H14: Difficulty | I14: Use this? | J14: Notes
A15: 1 | B15: Topography + Doppler/look-angle depth error | C15: NASA says REASON studies ice structure/thickness plus surface elevations and roughness; NASA also uses frequency shifts for gravity/radio science. | D15: Public summaries do not show a simple combined sensitivity threshold for generated topography + off-nadir angle + radar depth conversion. | E15: Sweep topography amplitude/slope and off-nadir angle; calculate raw slant depth, corrected depth, and remaining bottom-layer error. | F15: Heatmap: local surface slope vs look angle, colored by bottom-depth error. | G15: Strong | H15: Medium | I15: YES - strongest | J15: This directly matches your current model and new Doppler tab.
A16: 2 | B16: False bottom layer from multiple thin internal layers | C16: REASON will analyze bounced radar signals to see internal features. Mars radar studies show bright reflectors can come from layer interference, not liquid water. | D16: Test whether Europa-like internal layer spacing can combine into a bright return that looks like an ocean boundary. | E16: Add repeated thin layers with small dielectric contrasts; compare true ocean echo vs false bright stacked-layer echo. | F16: False-interface count vs layer spacing and dielectric contrast. | G16: Strong analog | H16: Medium-high | I16: YES | J16: This is a clean 'problem NASA must avoid' angle without claiming they ignored it.
A17: 3 | B17: Briny/warm lens masks deeper ocean return | C17: NASA is searching for shallow subsurface water and the ice-ocean interface. | D17: A shallow conductive briny lens could absorb or reflect energy enough that the deeper bottom layer becomes weak or invisible. | E17: Sweep lens thickness, salinity/attenuation, and depth; calculate ocean echo margin after passing through lens. | F17: Echo margin vs briny lens strength. | G17: Medium-strong | H17: Medium | I17: YES | J17: Your workbook already has lens and ocean echo margins, so this is easy to extend.
A18: 4 | B18: Radar depth vs gravity/topography mismatch | C18: Gravity studies use Doppler/range measurements; gravity-topography admittance can complement radar for shell thickness. | D18: Radar sees local structure; gravity/topography can average broad structure. A local anomaly may disagree with global shell estimates. | E18: Compare local radar-inferred shell thickness with smoothed gravity/topography proxy and flag mismatches. | F18: Radar thickness minus gravity-proxy thickness along track. | G18: Medium | H18: Medium-high | I18: Maybe | J18: Good extension after the radar-only model is solid.
A19: 5 | B19: Plasma/ionosphere delay plus angle correction | C19: NASA uses PIMS to separate plasma distortion from Europa's induced magnetic signal; prior work studies Europa ionosphere effects on radar propagation. | D19: Small path-delay or phase distortion could combine with geometry correction and move a weak bottom echo. | E19: Add a tunable ionosphere/plasma delay term and compare corrected depth with/without it. | F19: Depth bias vs plasma delay and look angle. | G19: Medium | H19: Higher | I19: Later | J19: Useful but harder to explain unless the radar model is already polished.
A22: Research loop checklist
A23: Step | B23: What to check | C23: Pass condition
A24: 1 | B24: Find a NASA/primary source that says what the mission already measures. | C24: You can cite the exact instrument or paper.
A25: 2 | B25: Mark whether NASA already clearly covers the same exact issue. | C25: If yes, reframe as a sensitivity test, not a discovery claim.
A26: 3 | B26: Ask what your workbook can calculate that the source summary does not show. | C26: It produces a number, threshold, or graph.
A27: 4 | B27: Check whether the result could change interpretation of an ocean, briny lens, or shell thickness. | C27: It affects a science conclusion or measurement confidence.
A28: 5 | B28: Write a careful claim. | C28: Use 'possible interpretation risk' or 'stress test,' not 'NASA did not think of it.'
A31: Source evidence used
A32: ID | B32: Source | C32: What it supports | D32: Link
A33: S1 | B33: NASA Europa Clipper instruments page | C33: REASON probes ice shell, studies structure/thickness, surface elevations, roughness; gravity/radio science analyzes frequency shifts. | D33: https://science.nasa.gov/mission/europa-clipper/spacecraft-instruments/
A34: S2 | B34: NASA Europa Clipper mission page | C34: Mission carries nine instruments plus gravity experiment; instruments operate together on each flyby; main goal is habitability below surface. | D34: https://science.nasa.gov/mission/europa-clipper/
A35: S3 | B35: Verma & Margot 2018, Expected Precision of Europa Clipper Gravity Measurements | C35: Radio science uses two-way Doppler and radar altimeter crossover ranges; results depend on DSN tracking and crossover performance. | D35: https://arxiv.org/abs/1801.08946
A36: S4 | B36: Akiba, Ermakov & Militzer 2021, gravity-topography admittance | C36: Gravity/topography can complement ice-penetrating radar, and simple Airy models may not work across all wavelengths. | D36: https://arxiv.org/abs/2105.02790
A37: S5 | B37: Lalich, Hayes & Poggiali 2021, bright radar reflections without liquid water | C37: Radar simulations can explain bright basal reflectors through multiple-layer interference rather than liquid water; useful analog warning. | D37: https://arxiv.org/abs/2107.03497
A40: Do not claim
A41: Do not claim NASA forgot Doppler, roughness, topography, or radar clutter. | B41: The sources show these are already in the mission/instrument plan.
A42: Do not claim the model proves an ocean exists. | B42: The workbook is a simulated stress test, not Europa flight data.
A43: Do not claim one graph is enough. | B43: The stronger project is a loop: source -> possible risk -> formula -> graph -> threshold -> careful conclusion.

Sheet Inputs
A1: Parabolic Motion Radar Model - Editable Inputs
A2: Change the yellow cells in column C for the custom model. Use the TRUE/FALSE scenario toggles at the right to overlay paper-derived pass cases on the Dashboard charts.
A4: Parameter | B4: Symbol | C4: Value | D4: Unit | E4: Notes | F4: Paper-Derived Pass Scenario Overlays
A5: Closest altitude | B5: z0 | C5: 400 | D5: km | E5: Altitude at closest approach. Change this to test other flyby heights. | F5: Show | G5: Scenario | H5: z0 | I5: x_min | J5: x_max | K5: x_edge | L5: Delta_z_edge | M5: Edge altitude | N5: Paper basis / meaning
A6: Side/cross-track offset | B6: y | C6: 25 | D6: km | E6: Horizontal offset of the modeled target from nadir. | F6: TRUE | G6: Current custom inputs | H6: =C5 | I6: =C7 | J6: =C8 | K6: =C10 | L6: =C9 | M6: =C5+C9 | N6: Your editable custom case from the left table. It remains the main model used by the topography dashboard.
A7: Along-track minimum | B7: x_min | C7: -60 | D7: km | E7: Left/start side of the modeled pass. | F7: TRUE | G7: Paper low-altitude 800-km pass | H7: 35 | I7: -400 | J7: 400 | K7: 400 | L7: 365 | M7: 400 | N7: Paper coverage requirement: groundtrack segments at least 800 km long below 400 km for most REASON datasets. This model makes that a parabola.
A8: Along-track maximum | B8: x_max | C8: 60 | D8: km | E8: Right/end side of the modeled pass. | F8: TRUE | G8: Paper ice-ocean 1600-km pass | H8: 35 | I8: -800 | J8: 800 | K8: 800 | L8: 965 | M8: 1000 | N8: Paper ice-ocean interface requirement: at least 1600 km below 1000 km. This model makes that a parabola.
A9: Altitude rise at edge | B9: Delta_z_edge | C9: 4 | D9: km | E9: How much altitude rises at +/- x_edge. | F9: TRUE | G9: Paper operating 25-to-1000-km pass | H9: 25 | I9: -800 | J9: 800 | K9: 800 | L9: 975 | M9: 1000 | N9: Paper instrument table lists operational altitudes of 25 km to 1000 km. This shows the lower-bound closest-approach case.
A10: Parabola edge location | B10: x_edge | C10: 60 | D10: km | E10: Controls curvature together with Delta_z_edge.
A11: Along-track speed | B11: v | C11: 4 | D11: km/s | E11: Used for range rate, Doppler, and pulse spacing. | F11: Scenario note | G11: The paper gives altitude ranges and required groundtrack lengths, not exact parabolic equations. These rows convert those paper values into the same simplified parabola equation so outcomes can be compared on one dashboard.
A12: Ice refractive index | B12: n | C12: 1.78 | E12: Used to convert extra slant path into apparent depth.
A13: VHF wavelength | B13: lambda_vhf | C13: 5 | D13: m | E13: REASON-like VHF wavelength.
A14: HF wavelength | B14: lambda_hf | C14: 33.3 | D14: m | E14: REASON-like HF wavelength.
A15: Interferometer baseline | B15: b | C15: 5 | D15: m | E15: Used for VHF phase estimate.
A16: VHF range resolution | B16: res_vhf | C16: 30 | D16: m | E16: Used for VHF apparent-depth uncertainty band.
A17: HF range resolution | B17: res_hf | C17: 300 | D17: m | E17: Used for HF apparent-depth uncertainty band.
A18: PRF choice 1 | B18: PRF_1 | C18: 50 | D18: Hz | E18: Example low PRF.
A19: PRF choice 2 | B19: PRF_2 | C19: 500 | D19: Hz | E19: Example medium PRF.
A20: PRF choice 3 | B20: PRF_3 | C20: 3000 | D20: Hz | E20: Example high PRF.
A21: Speed of light | B21: c | C21: 299792458 | D21: m/s | E21: Physical constant used for delay and timing.
A23: Model note | B23: The parabola is a simplified local path, not a real mission trajectory. Use it to see how geometry changes radar outputs.
A25: Representative Europa Topography Controls
A26: Parameter | B26: Symbol | C26: Value | D26: Unit | E26: Notes
A27: Topography enabled | B27: topography_on | C27: TRUE | E27: Dropdown-style toggle. TRUE adds terrain height to the radar geometry; FALSE returns to flat surface.
A28: Ridge height | B28: A_ridge | C28: 350 | D28: m | E28: Positive height for a representative double-ridge / raised band.
A29: Ridge center x | B29: ridge_x0 | C29: 0 | D29: km | E29: Along-track center of the ridge.
A30: Ridge center y | B30: ridge_y0 | C30: 25 | D30: km | E30: Cross-track center of the ridge.
A31: Ridge length sigma | B31: ridge_sigma_x | C31: 24 | D31: km | E31: Long direction of the ridge feature.
A32: Ridge width sigma | B32: ridge_sigma_y | C32: 3.5 | D32: km | E32: Narrow cross-track width of the ridge.
A33: Crater/depression depth | B33: D_crater | C33: 180 | D33: m | E33: Positive number becomes a negative depression in the surface model.
A34: Crater center x | B34: crater_x0 | C34: -18 | D34: km | E34: Along-track center of depression.
A35: Crater center y | B35: crater_y0 | C35: 8 | D35: km | E35: Cross-track center of depression.
A36: Crater width sigma | B36: crater_sigma | C36: 8 | D36: km | E36: Controls how broad the depression is.
A37: Chaos amplitude | B37: A_chaos | C37: 65 | D37: m | E37: Mixed sinusoidal terrain term for irregular chaos-like height variation.
A38: Fine roughness amplitude | B38: A_rough | C38: 35 | D38: m | E38: Smaller surface roughness term.
A39: Roughness wavelength x | B39: Lx | C39: 18 | D39: km | E39: Along-track roughness wavelength.
... A46: Terrain vertical uncertainty | B46: sigma_h | C46: 75 | D46: m | E46: Representative uncertainty band for the topographic height model.
A47: Terrain seed | B47: terrain_seed | C47: 7 | E47: Change this number to generate a different repeatable random-looking surface. Same seed gives the same graphs.
A48: Seeded random amplitude | B48: A_seeded | C48: 45 | D48: m | E48: Strength of the generated terrain added on top of the DEM-style surface.
A49: Seeded random scale x | B49: L_seed_x | C49: 12 | D49: km | E49: Along-track scale for seeded terrain waves.
...

Sheet Subsurface_Inputs
A1: Europa Ice Subsurface Editable Inputs
A2: Change the yellow values in column C. Subsurface_Live_Data and Subsurface_Dashboard update from these formulas. | E2: All editable values live on this tab. Subsurface_Dashboard is output-only.
A3: Section | B3: Parameter | C3: Value | D3: Unit | E3: Notes
A4: Surface | B4: Use generated icy topography | C4: TRUE | E4: Surface/topography is modeled as icy terrain, not rock.
A5: Shallow ice | B5: Upper ice layer mean depth | C5: 1150 | D5: m | E5: Depth below the local icy surface.
A6: Shallow ice | B6: Upper ice sine amplitude | C6: 160 | D6: m | E6: Smooth undulation in shallow internal ice.
A7: Shallow ice | B7: Upper ice phase shift | C7: 10 | D7: km | E7: Moves the shallow layer pattern left/right.
A8: Shallow ice | B8: Upper ice sine wavelength | C8: 42 | D8: km | E8: Longer number means smoother/larger features.
A9: Shallow ice | B9: Upper ice cosine amplitude | C9: 60 | D9: m | E9: Secondary shallow-layer variation.
A10: Shallow ice | B10: Upper ice cosine wavelength | C10: 23 | D10: km | E10: Secondary shallow-layer spacing.
A11: Shallow ice | B11: Surface coupling factor | C11: 0.04 | E11: How much surface relief carries into shallow ice.
A13: Warm/briny lens | B13: Lens A strength | C13: 0.95 | D13: 0-1 | E13: Local possible warm/briny contrast, not proven.
A14: Warm/briny lens | B14: Lens A center | C14: -24 | D14: km | E14: Along-track center of first possible lens.
A15: Warm/briny lens | B15: Lens A width | C15: 10 | D15: km | E15: Controls how broad lens A is.
A16: Warm/briny lens | B16: Lens B strength | C16: 0.7 | D16: 0-1 | E16: Second possible lens.
A17: Warm/briny lens | B17: Lens B center | C17: 30 | D17: km | E17: Along-track center of second possible lens.
A18: Warm/briny lens | B18: Lens B width | C18: 8 | D18: km | E18: Controls how broad lens B is.
A19: Warm/briny lens | B19: Lens mean depth | C19: 5100 | D19: m | E19: Depth below local surface.
A20: Warm/briny lens | B20: Lens depth wave amplitude | C20: 520 | D20: m | E20: Broad depth variation.
A21: Warm/briny lens | B21: Lens depth phase shift | C21: 6 | D21: km | E21: Moves lens-depth wave left/right.
A22: Warm/briny lens | B22: Lens depth wavelength | C22: 82 | D22: km | E22: Lens-depth wave spacing.
A23: Warm/briny lens | B23: Lens uplift when strong | C23: 240 | D23: m | E23: Strong lens sits slightly shallower.
A25: Ice-ocean boundary | B25: Nominal ice shell thickness | C25: 15000 | D25: m | E25: Possible bottom reflector depth.
... A31: Ice-ocean boundary | B31: Ocean boundary cosine wavelength | C31: 62 | D31: km | E31: Secondary basal spacing.
A32: Ice-ocean boundary | B32: Surface anti-coupling factor | C32: 0.14 | E32: Surface highs slightly reduce thickness.
A34: Radar | B34: Ice refractive index | C34: =Inputs!$C$12 | E34: Uses workbook ice index by default.
A35: Radar | B35: Speed of light | C35: 299792458 | D35: m/s | E35: Used for two-way delay.
A36: Radar | B36: One-way ice attenuation | C36: 0.9 | D36: dB/km | E36: Simple signal loss through ice.
A37: Radar | B37: Shallow layer base echo | C37: -10 | D37: dB | E37: Relative reflector strength before attenuation.
A38: Radar | B38: Lens base echo | C38: -24 | D38: dB | E38: Relative lens strength before lens multiplier and attenuation.
A39: Radar | B39: Lens strength echo bonus | C39: 9 | D39: dB | E39: A stronger lens creates a stronger reflector.
A40: Radar | B40: Ocean boundary base echo | C40: -6 | D40: dB | E40: Large material contrast from ice to possible ocean.
A41: Radar | B41: Basal roughness penalty | C41: 0.004 | D41: dB/m | E41: Rougher boundary weakens coherent echo.
A42: Radar | B42: Lens display threshold | C42: 0.18 | D42: 0-1 | E42: Below this, lens is treated as too weak for chart focus.
A43: Radar | B43: Detection threshold | C43: -45 | D43: dB | E43: Simple threshold for treating a return as easier to see.
A44: Uncertainty | B44: Boundary uncertainty band | C44: 1500 | D44: m | E44: Plus/minus range around the possible ice-ocean boundary.
A45: Scenario | B45: Thin shell multiplier | C45: 0.55 | E45: Creates a thinner-shell scenario from the live depth.
A46: Scenario | B46: Thick shell multiplier | C46: 1.75 | E46: Creates a thicker-shell scenario from the live depth.
A47: Scenario | B47: No-ocean control echo | C47: -60 | D47: dB | E47: Weak baseline return for a no-bottom-reflector control case.
A48: Evidence | B48: Radar support score | C48: 55 | D48: % | E48: How strongly radar outputs support the proposed subsurface.
...

Sheet Model_Data
A1: x_km | B1: z_km | C1: R_nadir_km | D1: R_off_km | E1: Delta_R_m | F1: apparent_depth_m | G1: extra_delay_us | H1: horizontal_offset_km | I1: look_angle_deg | J1: vhf_phase_deg | K1: relative_power | L1: power_dB | M1: dz_dx | N1: dz_dt_km_s | O1: range_rate_m_s | P1: vhf_doppler_hz | Q1: hf_doppler_hz | R1: vhf_band_low_m | S1: vhf_band_high_m | T1: hf_band_low_m | U1: hf_band_high_m | V1: abs_vhf_doppler_hz | W1: abs_hf_doppler_hz | X1: h_nadir_m | Y1: h_target_m | Z1: R_nadir_topo_km | AA1: R_off_topo_km | AB1: Delta_R_topo_m | AC1: apparent_depth_topo_m | AD1: extra_delay_topo_us | AE1: look_angle_topo_deg | AF1: vhf_phase_topo_deg | AG1: relative_power_topo | AH1: power_dB_topo | AI1: depth_change_topo_minus_flat_m | AJ1: delay_change_topo_minus_flat_us | AK1: target_minus_nadir_height_m | AL1: range_rate_topo_m_s | AM1: vhf_doppler_topo_hz | AN1: hf_doppler_topo_hz | AO1: abs_vhf_doppler_topo_hz | AP1: abs_hf_doppler_topo_hz | AQ1: topo_depth_uncertainty_m | AR1: topo_depth_low_m | AS1: topo_depth_high_m
A2: =Inputs!$C$7+0*(Inputs!$C$8-Inputs!$C$7)/240 | B2: =Inputs!$C$5+Inputs!$C$9*(A2/Inputs!$C$10)^2 | C2: =B2 | D2: =SQRT((Inputs!$C$52+B2)^2+Inputs!$C$52^2-2*(Inputs!$C$52+B2)*Inputs!$C$52*COS(SQRT(A2^2+Inputs!$C$6^2)/Inputs!$C$52)) | E2: =(D2-C2)*1000 | F2: =E2/Inputs!$C$12 | G2: =2*E2/Inputs!$C$21*1000000 | H2: =SQRT(A2^2+Inputs!$C$6^2) | I2: =DEGREES(ATAN(H2/B2)) | J2: =DEGREES((2*PI()/Inputs!$C$13)*Inputs!$C$15*SIN(RADIANS(I2))) | K2: =(C2/D2)^4 | L2: =10*LOG10(K2) | M2: =2*(Inputs!$C$9/(Inputs!$C$10^2))*A2 | N2: =M2*Inputs!$C$11 | O2: =1000*(D3-D2)/(A3-A2)*Inputs!$C$11 | P2: =-2*O2/Inputs!$C$13 | Q2: =-2*O2/Inputs!$C$14 | R2: =F2-Inputs!$C$16/2 | S2: =F2+Inputs!$C$16/2 | T2: =F2-Inputs!$C$17/2 | U2: =F2+Inputs!$C$17/2 | V2: =ABS(P2) | W2: =ABS(Q2) | X2: =IF(OR(Inputs!$C$27=TRUE,Inputs!$C$27="TRUE",Inputs!$C$27=1),1,0)*(Inputs!$C$51*(115*EXP(-(((0)-25)^2)/(4.5^2))+70*EXP(-(((0)+38)^2)/(7^2))*(0.55+0.45*SIN(2*PI()*(A2)/45))+24*SIN(2*PI()*(0)/9+(A2)/18)*EXP(-(((0)+5)^2)/(22^2))+18*SIN(2*PI()*(A2)/70))+Inputs!$C$28*EXP(-(((A2)-Inputs!$C$29)^2)/(2*Inputs!$C$31^2))*EXP(-(((0)-Inputs!$C$30)^2)/(2*Inputs!$C$32^2))+-Inputs!$C$33*EXP(-(((((A2)-Inputs!$C$34)^2)+(((0)-Inputs!$C$35)^2))/(2*Inputs!$C$36^2)))+Inputs!$C$37*(0.55*SIN(2*PI()*(A2)/Inputs!$C$39)+0.35*COS(2*PI()*(0)/Inputs!$C$40)+0.2*SIN(2*PI()*((A2)+(0))/(0.5*(Inputs!$C$39+Inputs!$C$40))))+Inputs!$C$38*SIN(2*PI()*(A2)/Inputs!$C$39)*SIN(2*PI()*(0)/Inputs!$C$40)+-Inputs!$C$41*EXP(-(((0)-Inputs!$C$43)^2)/(2*Inputs!$C$44^2))*EXP(-(((A2)-Inputs!$C$42)^2)/(2*Inputs!$C$45^2))+Inputs!$C$48*(0.7*(0.45*SIN(2*PI()*(((A2)/Inputs!$C$49)+Inputs!$C$47*0.137))+0.35*COS(2*PI()*(((0)/Inputs!$C$50)+Inputs!$C$47*0.173))+0.2*SIN(2*PI()*(((A2)+(0))/(0.5*(Inputs!$C$49+Inputs!$C$50))+Inputs!$C$47*0.097)))+0.3*(2*((SIN(((A2)*12.9898+(0)*78.233+Inputs!$C$47*37.719))*43758.5453)-INT((SIN(((A2)*12.9898+(0)*78.233+Inputs!$C$47*37.719))*43758.5453)))-1))) | Y2: =IF(OR(Inputs!$C$27=TRUE,Inputs!$C$27="TRUE",Inputs!$C$27=1),1,0)*(Inputs!$C$51*(115*EXP(-(((Inputs!$C$6)-25)^2)/(4.5^2))+70*EXP(-(((Inputs!$C$6)+38)^2)/(7^2))*(0.55+0.45*SIN(2*PI()*(A2)/45))+24*SIN(2*PI()*(Inputs!$C$6)/9+(A2)/18)*EXP(-(((Inputs!$C$6)+5)^2)/(22^2))+18*SIN(2*PI()*(A2)/70))+Inputs!$C$28*EXP(-(((A2)-Inputs!$C$29)^2)/(2*Inputs!$C$31^2))*EXP(-(((Inputs!$C$6)-Inputs!$C$30)^2)/(2*Inputs!$C$32^2))+-Inputs!$C$33*EXP(-(((((A2)-Inputs!$C$34)^2)+(((Inputs!$C$6)-Inputs!$C$35)^2))/(2*Inputs!$C$36^2)))+Inputs!$C$37*(0.55*SIN(2*PI()*(A2)/Inputs!$C$39)+0.35*COS(2*PI()*(Inputs!$C$6)/Inputs!$C$40)+0.2*SIN(2*PI()*((A2)+(Inputs!$C$6))/(0.5*(Inputs!$C$39+Inputs!$C$40))))+Inputs!$C$38*SIN(2*PI()*(A2)/Inputs!$C$39)*SIN(2*PI()*(Inputs!$C$6)/Inputs!$C$40)+-Inputs!$C$41*EXP(-(((Inputs!$C$6)-Inputs!$C$43)^2)/(2*Inputs!$C$44^2))*EXP(-(((A2)-Inputs!$C$42)^2)/(2*Inputs!$C$45^2))+Inputs!$C$48*(0.7*(0.45*SIN(2*PI()*(((A2)/Inputs!$C$49)+Inputs!$C$47*0.137))+0.35*COS(2*PI()*(((Inputs!$C$6)/Inputs!$C$50)+Inputs!$C$47*0.173))+0.2*SIN(2*PI()*(((A2)+(Inputs!$C$6))/(0.5*(Inputs!$C$49+Inputs!$C$50))+Inputs!$C$47*0.097)))+0.3*(2*((SIN(((A2)*12.9898+(Inputs!$C$6)*78.233+Inputs!$C$47*37.719))*43758.5453)-INT((SIN(((A2)*12.9898+(Inputs!$C$6)*78.233+Inputs!$C$47*37.719))*43758.5453)))-1))) | Z2: =B2-X2/1000 | AA2: =SQRT((Inputs!$C$52+B2)^2+(Inputs!$C$52+Y2/1000)^2-2*(Inputs!$C$52+B2)*(Inputs!$C$52+Y2/1000)*COS(SQRT(A2^2+Inputs!$C$6^2)/Inputs!$C$52)) | AB2: =(AA2-Z2)*1000 | AC2: =AB2/Inputs!$C$12 | AD2: =2*AB2/Inputs!$C$21*1000000 | AE2: =DEGREES(ATAN(H2/(B2-Y2/1000))) | AF2: =DEGREES((2*PI()/Inputs!$C$13)*Inputs!$C$15*SIN(RADIANS(AE2))) | AG2: =(Z2/AA2)^4 | AH2: =10*LOG10(AG2) | AI2: =AC2-F2 | AJ2: =AD2-G2 | AK2: =Y2-X2 | AL2: =1000*(AA3-AA2)/(A3-A2)*Inputs!$C$11 | AM2: =-2*AL2/Inputs!$C$13 | AN2: =-2*AL2/Inputs!$C$14 | AO2: =ABS(AM2) | AP2: =ABS(AN2) | AQ2: =IF(OR(Inputs!$C$27=TRUE,Inputs!$C$27="TRUE",Inputs!$C$27=1),Inputs!$C$46/Inputs!$C$12,0) | AR2: =AC2-AQ2 | AS2: =AC2+AQ2
A3: =Inputs!$C$7+1*(Inputs!$C$8-Inputs!$C$7)/240 | B3: =Inputs!$C$5+Inputs!$C$9*(A3/Inputs!$C$10)^2 | C3: =B3 | D3: =SQRT((Inputs!$C$52+B3)^2+Inputs!$C$52^2-2*(Inputs!$C$52+B3)*Inputs!$C$52*COS(SQRT(A3^2+Inputs!$C$6^2)/Inputs!$C$52)) | E3: =(D3-C3)*1000 | F3: =E3/Inputs!$C$12 | G3: =2*E3/Inputs!$C$21*1000000 | H3: =SQRT(A3^2+Inputs!$C$6^2) | I3: =DEGREES(ATAN(H3/B3)) | J3: =DEGREES((2*PI()/Inputs!$C$13)*Inputs!$C$15*SIN(RADIANS(I3))) | K3: =(C3/D3)^4 | L3: =10*LOG10(K3) | M3: =2*(Inputs!$C$9/(Inputs!$C$10^2))*A3 | N3: =M3*Inputs!$C$11 | O3: =1000*(D4-D2)/(A4-A2)*Inputs!$C$11 | P3: =-2*O3/Inputs!$C$13 | Q3: =-2*O3/Inputs!$C$14 | R3: =F3-Inputs!$C$16/2 | S3: =F3+Inputs!$C$16/2 | T3: =F3-Inputs!$C$17/2 | U3: =F3+Inputs!$C$17/2 | V3: =ABS(P3) | W3: =ABS(Q3) | X3: =IF(OR(Inputs!$C$27=TRUE,Inputs!$C$27="TRUE",Inputs!$C$27=1),1,0)*(Inputs!$C$51*(115*EXP(-(((0)-25)^2)/(4.5^2))+70*EXP(-(((0)+38)^2)/(7^2))*(0.55+0.45*SIN(2*PI()*(A3)/45))+24*SIN(2*PI()*(0)/9+(A3)/18)*EXP(-(((0)+5)^2)/(22^2))+18*SIN(2*PI()*(A3)/70))+Inputs!$C$28*EXP(-(((A3)-Inputs!$C$29)^2)/(2*Inputs!$C$31^2))*EXP(-(((0)-Inputs!$C$30)^2)/(2*Inputs!$C$32^2))+-Inputs!$C$33*EXP(-(((((A3)-Inputs!$C$34)^2)+(((0)-Inputs!$C$35)^2))/(2*Inputs!$C$36^2)))+Inputs!$C$37*(0.55*SIN(2*PI()*(A3)/Inputs!$C$39)+0.35*COS(2*PI()*(0)/Inputs!$C$40)+0.2*SIN(2*PI()*((A3)+(0))/(0.5*(Inputs!$C$39+Inputs!$C$40))))+Inputs!$C$38*SIN(2*PI()*(A3)/Inputs!$C$39)*SIN(2*PI()*(0)/Inputs!$C$40)+-Inputs!$C$41*EXP(-(((0)-Inputs!$C$43)^2)/(2*Inputs!$C$44^2))*EXP(-(((A3)-Inputs!$C$42)^2)/(2*Inputs!$C$45^2))+Inputs!$C$48*(0.7*(0.45*SIN(2*PI()*(((A3)/Inputs!$C$49)+Inputs!$C$47*0.137))+0.35*COS(2*PI()*(((0)/Inputs!$C$50)+Inputs!$C$47*0.173))+0.2*SIN(2*PI()*(((A3)+(0))/(0.5*(Inputs!$C$49+Inputs!$C$50))+Inputs!$C$47*0.097)))+0.3*(2*((SIN(((A3)*12.9898+(0)*78.233+Inputs!$C$47*37.719))*43758.5453)-INT((SIN(((A3)*12.9898+(0)*78.233+Inputs!$C$47*37.719))*43758.5453)))-1))) | Y3: =IF(OR(Inputs!$C$27=TRUE,Inputs!$C$27="TRUE",Inputs!$C$27=1),1,0)*(Inputs!$C$51*(115*EXP(-(((Inputs!$C$6)-25)^2)/(4.5^2))+70*EXP(-(((Inputs!$C$6)+38)^2)/(7^2))*(0.55+0.45*SIN(2*PI()*(A3)/45))+24*SIN(2*PI()*(Inputs!$C$6)/9+(A3)/18)*EXP(-(((Inputs!$C$6)+5)^2)/(22^2))+18*SIN(2*PI()*(A3)/70))+Inputs!$C$28*EXP(-(((A3)-Inputs!$C$29)^2)/(2*Inputs!$C$31^2))*EXP(-(((Inputs!$C$6)-Inputs!$C$30)^2)/(2*Inputs!$C$32^2))+-Inputs!$C$33*EXP(-(((((A3)-Inputs!$C$34)^2)+(((Inputs!$C$6)-Inputs!$C$35)^2))/(2*Inputs!$C$36^2)))+Inputs!$C$37*(0.55*SIN(2*PI()*(A3)/Inputs!$C$39)+0.35*COS(2*PI()*(Inputs!$C$6)/Inputs!$C$40)+0.2*SIN(2*PI()*((A3)+(Inputs!$C$6))/(0.5*(Inputs!$C$39+Inputs!$C$40))))+Inputs!$C$38*SIN(2*PI()*(A3)/Inputs!$C$39)*SIN(2*PI()*(Inputs!$C$6)/Inputs!$C$40)+-Inputs!$C$41*EXP(-(((Inputs!$C$6)-Inputs!$C$43)^2)/(2*Inputs!$C$44^2))*EXP(-(((A3)-Inputs!$C$42)^2)/(2*Inputs!$C$45^2))+Inputs!$C$48*(0.7*(0.45*SIN(2*PI()*(((A3)/Inputs!$C$49)+Inputs!$C$47*0.137))+0.35*COS(2*PI()*(((Inputs!$C$6)/Inputs!$C$50)+Inputs!$C$47*0.173))+0.2*SIN(2*PI()*(((A3)+(Inputs!$C$6))/(0.5*(Inputs!$C$49+Inputs!$C$50))+Inputs!$C$47*0.097)))+0.3*(2*((SIN(((A3)*12.9898+(Inputs!$C$6)*78.233+Inputs!$C$47*37.719))*43758.5453)-INT((SIN(((A3)*12.9898+(Inputs!$C$6)*78.233+Inputs!$C$47*37.719))*43758.5453)))-1))) | Z3: =B3-X3/1000 | AA3: =SQRT((Inputs!$C$52+B3)^2+(Inputs!$C$52+Y3/1000)^2-2*(Inputs!$C$52+B3)*(Inputs!$C$52+Y3/1000)*COS(SQRT(A3^2+Inputs!$C$6^2)/Inputs!$C$52)) | AB3: =(AA3-Z3)*1000 | AC3: =AB3/Inputs!$C$12 | AD3: =2*AB3/Inputs!$C$21*1000000 | AE3: =DEGREES(ATAN(H3/(B3-Y3/1000))) | AF3: =DEGREES((2*PI()/Inputs!$C$13)*Inputs!$C$15*SIN(RADIANS(AE3))) | AG3: =(Z3/AA3)^4 | AH3: =10*LOG10(AG3) | AI3: =AC3-F3 | AJ3: =AD3-G3 | AK3: =Y3-X3 | AL3: =1000*(AA4-AA2)/(A4-A2)*Inputs!$C$11 | AM3: =-2*AL3/Inputs!$C$13 | AN3: =-2*AL3/Inputs!$C$14 | AO3: =ABS(AM3) | AP3: =ABS(AN3) | AQ3: =IF(OR(Inputs!$C$27=TRUE,Inputs!$C$27="TRUE",Inputs!$C$27=1),Inputs!$C$46/Inputs!$C$12,0) | AR3: =AC3-AQ3 | AS3: =AC3+AQ3
A4: =Inputs!$C$7+2*(Inputs!$C$8-Inputs!$C$7)/240 | B4: =Inputs!$C$5+Inputs!$C$9*(A4/Inputs!$C$10)^2 | C4: =B4 | D4: =SQRT((Inputs!$C$52+B4)^2+Inputs!$C$52^2-2*(Inputs!$C$52+B4)*Inputs!$C$52*COS(SQRT(A4^2+Inputs!$C$6^2)/Inputs!$C$52)) | E4: =(D4-C4)*1000 | F4: =E4/Inputs!$C$12 | G4: =2*E4/Inputs!$C$21*1000000 | H4: =SQRT(A4^2+Inputs!$C$6^2) | I4: =DEGREES(ATAN(H4/B4)) | J4: =DEGREES((2*PI()/Inputs!$C$13)*Inputs!$C$15*SIN(RADIANS(I4))) | K4: =(C4/D4)^4 | L4: =10*LOG10(K4) | M4: =2*(Inputs!$C$9/(Inputs!$C$10^2))*A4 | N4: =M4*Inputs!$C$11 | O4: =1000*(D5-D3)/(A5-A3)*Inputs!$C$11 | P4: =-2*O4/Inputs!$C$13 | Q4: =-2*O4/Inputs!$C$14 | R4: =F4-Inputs!$C$16/2 | S4: =F4+Inputs!$C$16/2 | T4: =F4-Inputs!$C$17/2 | U4: =F4+Inputs!$C$17/2 | V4: =ABS(P4) | W4: =ABS(Q4) | X4: =IF(OR(Inputs!$C$27=TRUE,Inputs!$C$27="TRUE",Inputs!$C$27=1),1,0)*(Inputs!$C$51*(115*EXP(-(((0)-25)^2)/(4.5^2))+70*EXP(-(((0)+38)^2)/(7^2))*(0.55+0.45*SIN(2*PI()*(A4)/45))+24*SIN(2*PI()*(0)/9+(A4)/18)*EXP(-(((0)+5)^2)/(22^2))+18*SIN(2*PI()*(A4)/70))+Inputs!$C$28*EXP(-(((A4)-Inputs!$C$29)^2)/(2*Inputs!$C$31^2))*EXP(-(((0)-Inputs!$C$30)^2)/(2*Inputs!$C$32^2))+-Inputs!$C$33*EXP(-(((((A4)-Inputs!$C$34)^2)+(((0)-Inputs!$C$35)^2))/(2*Inputs!$C$36^2)))+Inputs!$C$37*(0.55*SIN(2*PI()*(A4)/Inputs!$C$39)+0.35*COS(2*PI()*(0)/Inputs!$C$40)+0.2*SIN(2*PI()*((A4)+(0))/(0.5*(Inputs!$C$39+Inputs!$C$40))))+Inputs!$C$38*SIN(2*PI()*(A4)/Inputs!$C$39)*SIN(2*PI()*(0)/Inputs!$C$40)+-Inputs!$C$41*EXP(-(((0)-Inputs!$C$43)^2)/(2*Inputs!$C$44^2))*EXP(-(((A4)-Inputs!$C$42)^2)/(2*Inputs!$C$45^2))+Inputs!$C$48*(0.7*(0.45*SIN(2*PI()*(((A4)/Inputs!$C$49)+Inputs!$C$47*0.137))+0.35*COS(2*PI()*(((0)/Inputs!$C$50)+Inputs!$C$47*0.173))+0.2*SIN(2*PI()*(((A4)+(0))/(0.5*(Inputs!$C$49+Inputs!$C$50))+Inputs!$C$47*0.097)))+0.3*(2*((SIN(((A4)*12.9898+(0)*78.233+Inputs!$C$47*37.719))*43758.5453)-INT((SIN(((A4)*12.9898+(0)*78.233+Inputs!$C$47*37.719))*43758.5453)))-1))) | Y4: =IF(OR(Inputs!$C$27=TRUE,Inputs!$C$27="TRUE",Inputs!$C$27=1),1,0)*(Inputs!$C$51*(115*EXP(-(((Inputs!$C$6)-25)^2)/(4.5^2))+70*EXP(-(((Inputs!$C$6)+38)^2)/(7^2))*(0.55+0.45*SIN(2*PI()*(A4)/45))+24*SIN(2*PI()*(Inputs!$C$6)/9+(A4)/18)*EXP(-(((Inputs!$C$6)+5)^2)/(22^2))+18*SIN(2*PI()*(A4)/70))+Inputs!$C$28*EXP(-(((A4)-Inputs!$C$29)^2)/(2*Inputs!$C$31^2))*EXP(-(((Inputs!$C$6)-Inputs!$C$30)^2)/(2*Inputs!$C$32^2))+-Inputs!$C$33*EXP(-(((((A4)-Inputs!$C$34)^2)+(((Inputs!$C$6)-Inputs!$C$35)^2))/(2*Inputs!$C$36^2)))+Inputs!$C$37*(0.55*SIN(2*PI()*(A4)/Inputs!$C$39)+0.35*COS(2*PI()*(Inputs!$C$6)/Inputs!$C$40)+0.2*SIN(2*PI()*((A4)+(Inputs!$C$6))/(0.5*(Inputs!$C$39+Inputs!$C$40))))+Inputs!$C$38*SIN(2*PI()*(A4)/Inputs!$C$39)*SIN(2*PI()*(Inputs!$C$6)/Inputs!$C$40)+-Inputs!$C$41*EXP(-(((Inputs!$C$6)-Inputs!$C$43)^2)/(2*Inputs!$C$44^2))*EXP(-(((A4)-Inputs!$C$42)^2)/(2*Inputs!$C$45^2))+Inputs!$C$48*(0.7*(0.45*SIN(2*PI()*(((A4)/Inputs!$C$49)+Inputs!$C$47*0.137))+0.35*COS(2*PI()*(((Inputs!$C$6)/Inputs!$C$50)+Inputs!$C$47*0.173))+0.2*SIN(2*PI()*(((A4)+(Inputs!$C$6))/(0.5*(Inputs!$C$49+Inputs!$C$50))+Inputs!$C$47*0.097)))+0.3*(2*((SIN(((A4)*12.9898+(Inputs!$C$6)*78.233+Inputs!$C$47*37.719))*43758.5453)-INT((SIN(((A4)*12.9898+(Inputs!$C$6)*78.233+Inputs!$C$47*37.719))*43758.5453)))-1))) | Z4: =B4-X4/1000 | AA4: =SQRT((Inputs!$C$52+B4)^2+(Inputs!$C$52+Y4/1000)^2-2*(Inputs!$C$52+B4)*(Inputs!$C$52+Y4/1000)*COS(SQRT(A4^2+Inputs!$C$6^2)/Inputs!$C$52)) | AB4: =(AA4-Z4)*1000 | AC4: =AB4/Inputs!$C$12 | AD4: =2*AB4/Inputs!$C$21*1000000 | AE4: =DEGREES(ATAN(H4/(B4-Y4/1000))) | AF4: =DEGREES((2*PI()/Inputs!$C$13)*Inputs!$C$15*SIN(RADIANS(AE4))) | AG4: =(Z4/AA4)^4 | AH4: =10*LOG10(AG4) | AI4: =AC4-F4 | AJ4: =AD4-G4 | AK4: =Y4-X4 | AL4: =1000*(AA5-AA3)/(A5-A3)*Inputs!$C$11 | AM4: =-2*AL4/Inputs!$C$13 | AN4: =-2*AL4/Inputs!$C$14 | AO4: =ABS(AM4) | AP4: =ABS(AN4) | AQ4: =IF(OR(Inputs!$C$27=TRUE,Inputs!$C$27="TRUE",Inputs!$C$27=1),Inputs!$C$46/Inputs!$C$12,0) | AR4: =AC4-AQ4 | AS4: =AC4+AQ4
A5: =Inputs!$C$7+3*(Inputs!$C$8-Inputs!$C$7)/240 | B5: =Inputs!$C$5+Inputs!$C$9*(A5/Inputs!$C$10)^2 | C5: =B5 | D5: =SQRT((Inputs!$C$52+B5)^2+Inputs!$C$52^2-2*(Inputs!$C$52+B5)*Inputs!$C$52*COS(SQRT(A5^2+Inputs!$C$6^2)/Inputs!$C$52)) | E5: =(D5-C5)*1000 | F5: =E5/Inputs!$C$12 | G5: =2*E5/Inputs!$C$21*1000000 | H5: =SQRT(A5^2+Inputs!$C$6^2) | I5: =DEGREES(ATAN(H5/B5)) | J5: =DEGREES((2*PI()/Inputs!$C$13)*Inputs!$C$15*SIN(RADIANS(I5))) | K5: =(C5/D5)^4 | L5: =10*LOG10(K5) | M5: =2*(Inputs!$C$9/(Inputs!$C$10^2))*A5 | N5: =M5*Inputs!$C$11 | O5: =1000*(D6-D4)/(A6-A4)*Inputs!$C$11 | P5: =-2*O5/Inputs!$C$13 | Q5: =-2*O5/Inputs!$C$14 | R5: =F5-Inputs!$C$16/2 | S5: =F5+Inputs!$C$16/2 | T5: =F5-Inputs!$C$17/2 | U5: =F5+Inputs!$C$17/2 | V5: =ABS(P5) | W5: =ABS(Q5) | X5: =IF(OR(Inputs!$C$27=TRUE,Inputs!$C$27="TRUE",Inputs!$C$27=1),1,0)*(Inputs!$C$51*(115*EXP(-(((0)-25)^2)/(4.5^2))+70*EXP(-(((0)+38)^2)/(7^2))*(0.55+0.45*SIN(2*PI()*(A5)/45))+24*SIN(2*PI()*(0)/9+(A5)/18)*EXP(-(((0)+5)^2)/(22^2))+18*SIN(2*PI()*(A5)/70))+Inputs!$C$28*EXP(-(((A5)-Inputs!$C$29)^2)/(2*Inputs!$C$31^2))*EXP(-(((0)-Inputs!$C$30)^2)/(2*Inputs!$C$32^2))+-Inputs!$C$33*EXP(-(((((A5)-Inputs!$C$34)^2)+(((0)-Inputs!$C$35)^2))/(2*Inputs!$C$36^2)))+Inputs!$C$37*(0.55*SIN(2*PI()*(A5)/Inputs!$C$39)+0.35*COS(2*PI()*(0)/Inputs!$C$40)+0.2*SIN(2*PI()*((A5)+(0))/(0.5*(Inputs!$C$39+Inputs!$C$40))))+Inputs!$C$38*SIN(2*PI()*(A5)/Inputs!$C$39)*SIN(2*PI()*(0)/Inputs!$C$40)+-Inputs!$C$41*EXP(-(((0)-Inputs!$C$43)^2)/(2*Inputs!$C$44^2))*EXP(-(((A5)-Inputs!$C$42)^2)/(2*Inputs!$C$45^2))+Inputs!$C$48*(0.7*(0.45*SIN(2*PI()*(((A5)/Inputs!$C$49)+Inputs!$C$47*0.137))+0.35*COS(2*PI()*(((0)/Inputs!$C$50)+Inputs!$C$47*0.173))+0.2*SIN(2*PI()*(((A5)+(0))/(0.5*(Inputs!$C$49+Inputs!$C$50))+Inputs!$C$47*0.097)))+0.3*(2*((SIN(((A5)*12.9898+(0)*78.233+Inputs!$C$47*37.719))*43758.5453)-INT((SIN(((A5)*12.9898+(0)*78.233+Inputs!$C$47*37.719))*43758.5453)))-1))) | Y5: =IF(OR(Inputs!$C$27=TRUE,Inputs!$C$27="TRUE",Inputs!$C$27=1),1,0)*(Inputs!$C$51*(115*EXP(-(((Inputs!$C$6)-25)^2)/(4.5^2))+70*EXP(-(((Inputs!$C$6)+38)^2)/(7^2))*(0.55+0.45*SIN(2*PI()*(A5)/45))+24*SIN(2*PI()*(Inputs!$C$6)/9+(A5)/18)*EXP(-(((Inputs!$C$6)+5)^2)/(22^2))+18*SIN(2*PI()*(A5)/70))+Inputs!$C$28*EXP(-(((A5)-Inputs!$C$29)^2)/(2*Inputs!$C$31^2))*EXP(-(((Inputs!$C$6)-Inputs!$C$30)^2)/(2*Inputs!$C$32^2))+-Inputs!$C$33*EXP(-(((((A5)-Inputs!$C$34)^2)+(((Inputs!$C$6)-Inputs!$C$35)^2))/(2*Inputs!$C$36^2)))+Inputs!$C$37*(0.55*SIN(2*PI()*(A5)/Inputs!$C$39)+0.35*COS(2*PI()*(Inputs!$C$6)/Inputs!$C$40)+0.2*SIN(2*PI()*((A5)+(Inputs!$C$6))/(0.5*(Inputs!$C$39+Inputs!$C$40))))+Inputs!$C$38*SIN(2*PI()*(A5)/Inputs!$C$39)*SIN(2*PI()*(Inputs!$C$6)/Inputs!$C$40)+-Inputs!$C$41*EXP(-(((Inputs!$C$6)-Inputs!$C$43)^2)/(2*Inputs!$C$44^2))*EXP(-(((A5)-Inputs!$C$42)^2)/(2*Inputs!$C$45^2))+Inputs!$C$48*(0.7*(0.45*SIN(2*PI()*(((A5)/Inputs!$C$49)+Inputs!$C$47*0.137))+0.35*COS(2*PI()*(((Inputs!$C$6)/Inputs!$C$50)+Inputs!$C$47*0.173))+0.2*SIN(2*PI()*(((A5)+(Inputs!$C$6))/(0.5*(Inputs!$C$49+Inputs!$C$50))+Inputs!$C$47*0.097)))+0.3*(2*((SIN(((A5)*12.9898+(Inputs!$C$6)*78.233+Inputs!$C$47*37.719))*43758.5453)-INT((SIN(((A5)*12.9898+(Inputs!$C$6)*78.233+Inputs!$C$47*37.719))*43758.5453)))-1))) | Z5: =B5-X5/1000 | AA5: =SQRT((Inputs!$C$52+B5)^2+(Inputs!$C$52+Y5/1000)^2-2*(Inputs!$C$52+B5)*(Inputs!$C$52+Y5/1000)*COS(SQRT(A5^2+Inputs!$C$6^2)/Inputs!$C$52)) | AB5: =(AA5-Z5)*1000 | AC5: =AB5/Inputs!$C$12 | AD5: =2*AB5/Inputs!$C$21*1000000 | AE5: =DEGREES(ATAN(H5/(B5-Y5/1000))) | AF5: =DEGREES((2*PI()/Inputs!$C$13)*Inputs!$C$15*SIN(RADIANS(AE5))) | AG5: =(Z5/AA5)^4 | AH5: =10*LOG10(AG5) | AI5: =AC5-F5 | AJ5: =AD5-G5 | AK5: =Y5-X5 | AL5: =1000*(AA6-AA4)/(A6-A4)*Inputs!$C$11 | AM5: =-2*AL5/Inputs!$C$13 | AN5: =-2*AL5/Inputs!$C$14 | AO5: =ABS(AM5) | AP5: =ABS(AN5) | AQ5: =IF(OR(Inputs!$C$27=TRUE,Inputs!$C$27="TRUE",Inputs!$C$27=1),Inputs!$C$46/Inputs!$C$12,0) | AR5: =AC5-AQ5 | AS5: =AC5+AQ5
A6: =Inputs!$C$7+4*(Inputs!$C$8-Inputs!$C$7)/240 | B6: =Inputs!$C$5+Inputs!$C$9*(A6/Inputs!$C$10)^2 | C6: =B6 | D6: =SQRT((Inputs!$C$52+B6)^2+Inputs!$C$52^2-2*(Inputs!$C$52+B6)*Inputs!$C$52*COS(SQRT(A6^2+Inputs!$C$6^2)/Inputs!$C$52)) | E6: =(D6-C6)*1000 | F6: =E6/Inputs!$C$12 | G6: =2*E6/Inputs!$C$21*1000000 | H6: =SQRT(A6^2+Inputs!$C$6^2) | I6: =DEGREES(ATAN(H6/B6)) | J6: =DEGREES((2*PI()/Inputs!$C$13)*Inputs!$C$15*SIN(RADIANS(I6))) | K6: =(C6/D6)^4 | L6: =10*LOG10(K6) | M6: =2*(Inputs!$C$9/(Inputs!$C$10^2))*A6 | N6: =M6*Inputs!$C$11 | O6: =1000*(D7-D5)/(A7-A5)*Inputs!$C$11 | P6: =-2*O6/Inputs!$C$13 | Q6: =-2*O6/Inputs!$C$14 | R6: =F6-Inputs!$C$16/2 | S6: =F6+Inputs!$C$16/2 | T6: =F6-Inputs!$C$17/2 | U6: =F6+Inputs!$C$17/2 | V6: =ABS(P6) | W6: =ABS(Q6) | X6: =IF(OR(Inputs!$C$27=TRUE,Inputs!$C$27="TRUE",Inputs!$C$27=1),1,0)*(Inputs!$C$51*(115*EXP(-(((0)-25)^2)/(4.5^2))+70*EXP(-(((0)+38)^2)/(7^2))*(0.55+0.45*SIN(2*PI()*(A6)/45))+24*SIN(2*PI()*(0)/9+(A6)/18)*EXP(-(((0)+5)^2)/(22^2))+18*SIN(2*PI()*(A6)/70))+Inputs!$C$28*EXP(-(((A6)-Inputs!$C$29)^2)/(2*Inputs!$C$31^2))*EXP(-(((0)-Inputs!$C$30)^2)/(2*Inputs!$C$32^2))+-Inputs!$C$33*EXP(-(((((A6)-Inputs!$C$34)^2)+(((0)-Inputs!$C$35)^2))/(2*Inputs!$C$36^2)))+Inputs!$C$37*(0.55*SIN(2*PI()*(A6)/Inputs!$C$39)+0.35*COS(2*PI()*(0)/Inputs!$C$40)+0.2*SIN(2*PI()*((A6)+(0))/(0.5*(Inputs!$C$39+Inputs!$C$40))))+Inputs!$C$38*SIN(2*PI()*(A6)/Inputs!$C$39)*SIN(2*PI()*(0)/Inputs!$C$40)+-Inputs!$C$41*EXP(-(((0)-Inputs!$C$43)^2)/(2*Inputs!$C$44^2))*EXP(-(((A6)-Inputs!$C$42)^2)/(2*Inputs!$C$45^2))+Inputs!$C$48*(0.7*(0.45*SIN(2*PI()*(((A6)/Inputs!$C$49)+Inputs!$C$47*0.137))+0.35*COS(2*PI()*(((0)/Inputs!$C$50)+Inputs!$C$47*0.173))+0.2*SIN(2*PI()*(((A6)+(0))/(0.5*(Inputs!$C$49+Inputs!$C$50))+Inputs!$C$47*0.097)))+0.3*(2*((SIN(((A6)*12.9898+(0)*78.233+Inputs!$C$47*37.719))*43758.5453)-INT((SIN(((A6)*12.9898+(0)*78.233+Inputs!$C$47*37.719))*43758.5453)))-1))) | Y6: =IF(OR(Inputs!$C$27=TRUE,Inputs!$C$27="TRUE",Inputs!$C$27=1),1,0)*(Inputs!$C$51*(115*EXP(-(((Inputs!$C$6)-25)^2)/(4.5^2))+70*EXP(-(((Inputs!$C$6)+38)^2)/(7^2))*(0.55+0.45*SIN(2*PI()*(A6)/45))+24*SIN(2*PI()*(Inputs!$C$6)/9+(A6)/18)*EXP(-(((Inputs!$C$6)+5)^2)/(22^2))+18*SIN(2*PI()*(A6)/70))+Inputs!$C$28*EXP(-(((A6)-Inputs!$C$29)^2)/(2*Inputs!$C$31^2))*EXP(-(((Inputs!$C$6)-Inputs!$C$30)^2)/(2*Inputs!$C$32^2))+-Inputs!$C$33*EXP(-(((((A6)-Inputs!$C$34)^2)+(((Inputs!$C$6)-Inputs!$C$35)^2))/(2*Inputs!$C$36^2)))+Inputs!$C$37*(0.55*SIN(2*PI()*(A6)/Inputs!$C$39)+0.35*COS(2*PI()*(Inputs!$C$6)/Inputs!$C$40)+0.2*SIN(2*PI()*((A6)+(Inputs!$C$6))/(0.5*(Inputs!$C$39+Inputs!$C$40))))+Inputs!$C$38*SIN(2*PI()*(A6)/Inputs!$C$39)*SIN(2*PI()*(Inputs!$C$6)/Inputs!$C$40)+-Inputs!$C$41*EXP(-(((Inputs!$C$6)-Inputs!$C$43)^2)/(2*Inputs!$C$44^2))*EXP(-(((A6)-Inputs!$C$42)^2)/(2*Inputs!$C$45^2))+Inputs!$C$48*(0.7*(0.45*SIN(2*PI()*(((A6)/Inputs!$C$49)+Inputs!$C$47*0.137))+0.35*COS(2*PI()*(((Inputs!$C$6)/Inputs!$C$50)+Inputs!$C$47*0.173))+0.2*SIN(2*PI()*(((A6)+(Inputs!$C$6))/(0.5*(Inputs!$C$49+Inputs!$C$50))+Inputs!$C$47*0.097)))+0.3*(2*((SIN(((A6)*12.9898+(Inputs!$C$6)*78.233+Inputs!$C$47*37.719))*43758.5453)-INT((SIN(((A6)*12.9898+(Inputs!$C$6)*78.233+Inputs!$C$47*37.719))*43758.5453)))-1))) | Z6: =B6-X6/1000 | AA6: =SQRT((Inputs!$C$52+B6)^2+(Inputs!$C$52+Y6/1000)^2-2*(Inputs!$C$52+B6)*(Inputs!$C$52+Y6/1000)*COS(SQRT(A6^2+Inputs!$C$6^2)/Inputs!$C$52)) | AB6: =(AA6-Z6)*1000 | AC6: =AB6/Inputs!$C$12 | AD6: =2*AB6/Inputs!$C$21*1000000 | AE6: =DEGREES(ATAN(H6/(B6-Y6/1000))) | AF6: =DEGREES((2*PI()/Inputs!$C$13)*Inputs!$C$15*SIN(RADIANS(AE6))) | AG6: =(Z6/AA6)^4 | AH6: =10*LOG10(AG6) | AI6: =AC6-F6 | AJ6: =AD6-G6 | AK6: =Y6-X6 | AL6: =1000*(AA7-AA5)/(A7-A5)*Inputs!$C$11 | AM6: =-2*AL6/Inputs!$C$13 | AN6: =-2*AL6/Inputs!$C$14 | AO6: =ABS(AM6) | AP6: =ABS(AN6) | AQ6: =IF(OR(Inputs!$C$27=TRUE,Inputs!$C$27="TRUE",Inputs!$C$27=1),Inputs!$C$46/Inputs!$C$12,0) | AR6: =AC6-AQ6 | AS6: =AC6+AQ6
