Workbook

Sheet Dashboard
A1: Parabolic Motion Radar + Topography Parameter Model
A2: Use Inputs!C27 to apply/remove topography from the main outputs and charts. Inputs!C47 changes the terrain seed. Long-pass scenario ranges use Europa spherical curvature instead of flat Cartesian range. Off-nadir means the side-looking target at Inputs!C6, while nadir means straight below the spacecraft.
A4: Key Output Results
A5: Output | B5: Value | C5: Unit | D5: What it means
A6: Topography toggle | B6: =IF(OR(Inputs!$C$27=TRUE,Inputs!$C$27="TRUE",Inputs!$C$27=1),"Topography ON","Topography OFF") | D6: Set Inputs!C27 to TRUE to include terrain, or FALSE to return to a flat surface. Change Inputs!C47 to test a new terrain case.
A7: Flat apparent depth at mid-pass | B7: =Model_Data!F122 | C7: m | D7: Original flat-surface result.
A8: Topo apparent depth at mid-pass | B8: =Model_Data!AC122 | C8: m | D8: Apparent depth after terrain height changes the range geometry.
A9: Depth change from topography | B9: =Model_Data!AI122 | C9: m | D9: Topo apparent depth minus flat apparent depth.
A10: Topo extra two-way delay | B10: =Model_Data!AD122 | C10: us | D10: Two-way delay after topography is included.
A11: Topo VHF interferometric phase | B11: =Model_Data!AF122 | C11: deg | D11: VHF phase after topography changes the look geometry.
A12: Max target terrain height | B12: =MAX(Model_Data!Y2:Y242) | C12: m | D12: Highest modeled terrain at the side-offset target path.
A13: Min target terrain height | B13: =MIN(Model_Data!Y2:Y242) | C13: m | D13: Lowest modeled terrain at the side-offset target path.
A14: Max absolute topo depth change | B14: =MAX(MAX(Model_Data!AI2:AI242),-MIN(Model_Data!AI2:AI242)) | C14: m | D14: Largest magnitude of topography-driven apparent-depth change.
A15: Max topo VHF Doppler magnitude | B15: =MAX(Model_Data!AO2:AO242) | C15: Hz | D15: Largest VHF Doppler after topography is included.
A16: Simple minimum PRF with topo | B16: =2*B15 | C16: Hz | D16: Twice max topo VHF Doppler, a simple no-alias floor.
A17: Topo depth uncertainty band | B17: =Model_Data!AQ122 | C17: m | D17: Representative vertical uncertainty converted to apparent-depth uncertainty.
A19: PRF Choices
A20: PRF (Hz) | B20: Pulse interval (ms) | C20: Along-track spacing (m) | D20: Unambiguous range (km) | E20: Pulses in air at z0 | F20: Status
A21: =PRF_Results!A4 | B21: =PRF_Results!B4 | C21: =PRF_Results!C4 | D21: =PRF_Results!D4 | E21: =PRF_Results!E4 | F21: =PRF_Results!F4
A22: =PRF_Results!A5 | B22: =PRF_Results!B5 | C22: =PRF_Results!C5 | D22: =PRF_Results!D5 | E22: =PRF_Results!E5 | F22: =PRF_Results!F5
A23: =PRF_Results!A6 | B23: =PRF_Results!B6 | C23: =PRF_Results!C6 | D23: =PRF_Results!D6 | E23: =PRF_Results!E6 | F23: =PRF_Results!F6
A25: How to read this model
A26: The chain is: parabolic motion changes z(x); topography adds h(x,y); the radar then turns that real surface pattern into an apparent range/depth shift. The off-nadir target is the side-looking point at y = Inputs!C6; nadir is the straight-down reference. Flat means flat surface, not straight spacecraft motion.
A114: Paper Pass Scenario Comparison
A115: Scenario | B115: Show | C115: z0 (km) | D115: Length (km) | E115: Edge alt (km) | F115: Mid depth (m) | G115: Max VHF (Hz) | H115: PRF floor (Hz) | I115: Basis
A116: =Inputs!G6 | B116: =Inputs!F6 | C116: =Inputs!H6 | D116: =Inputs!J6-Inputs!I6 | E116: =Inputs!M6 | F116: =Scenario_Data!AF122 | G116: =MAX(MAX(Scenario_Data!AL2:AL242),-MIN(Scenario_Data!AL2:AL242)) | H116: =2*G116 | I116: Current editable
A117: =Inputs!G7 | B117: =Inputs!F7 | C117: =Inputs!H7 | D117: =Inputs!J7-Inputs!I7 | E117: =Inputs!M7 | F117: =Scenario_Data!AG122 | G117: =MAX(MAX(Scenario_Data!AM2:AM242),-MIN(Scenario_Data!AM2:AM242)) | H117: =2*G117 | I117: 800 km below 400
A118: =Inputs!G8 | B118: =Inputs!F8 | C118: =Inputs!H8 | D118: =Inputs!J8-Inputs!I8 | E118: =Inputs!M8 | F118: =Scenario_Data!AH122 | G118: =MAX(MAX(Scenario_Data!AN2:AN242),-MIN(Scenario_Data!AN2:AN242)) | H118: =2*G118 | I118: 1600 km below 1000
A119: =Inputs!G9 | B119: =Inputs!F9 | C119: =Inputs!H9 | D119: =Inputs!J9-Inputs!I9 | E119: =Inputs!M9 | F119: =Scenario_Data!AI122 | G119: =MAX(MAX(Scenario_Data!AO2:AO242),-MIN(Scenario_Data!AO2:AO242)) | H119: =2*G119 | I119: 25-1000 km range
A120: Scenario note | B120: Paper numbers are converted into this workbook's simplified parabola so the outcomes can be compared. The paper states altitude ranges and groundtrack requirements, not an exact parabolic spacecraft trajectory.
A122: Quick Graph Guide
A123: Graph | B123: What it is trying to show | F123: How to read the baseline
A124: Apparent depth | B124: Motion and topography change the apparent radar depth relative to the nadir reference. | F124: Grey zero line is a reference, not a plotted terrain/run result.
A125: Surface height | B125: Shows the generated topography used as the reference floor, plus the off-nadir target and nadir terrain heights. The satellite path is curved/parabolic, not flat. | F125: Grey floor now follows the generated topography instead of 0 m; colored lines show target and nadir terrain.
A126: Doppler | B126: Range-rate-driven VHF/HF Doppler, with flat geometry compared against topography-adjusted geometry. | F126: Crossing 0 Hz means the radial motion changes sign near closest approach.
A127: Motion-only / scenarios | B127: The motion-only chart is a radar reading from flat ground. It is not ground height; the curve comes from satellite path and slant-range geometry. | F127: Scenario baselines are grey reference floors; they are intentionally not orange model lines.
A128: Detailed notes | B128: See the Graph_Guide tab for every chart, source range, formula basis, and audit status. | F128: Checks!B4:B23 remains the formula-health checklist.

Sheet Inputs
A1: Parabolic Motion Radar Model - Editable Inputs
A2: Change the yellow cells in column C for the custom model. Use the TRUE/FALSE scenario toggles at the right to overlay paper-derived pass cases on the Dashboard charts.
A4: Parameter | B4: Symbol | C4: Value | D4: Unit | E4: Notes | F4: Paper-Derived Pass Scenario Overlays
A5: Closest altitude | B5: z0 | C5: 400 | D5: km | E5: Altitude at closest approach. Change this to test other flyby heights. | F5: Show | G5: Scenario | H5: z0 | I5: x_min | J5: x_max | K5: x_edge | L5: Delta_z_edge | M5: Edge altitude | N5: Paper basis / meaning
A6: Side/cross-track offset | B6: y | C6: 25 | D6: km | E6: Horizontal offset of the modeled target from nadir. | F6: TRUE | G6: Current custom inputs | H6: =C5 | I6: =C7 | J6: =C8 | K6: =C10 | L6: =C9 | M6: =C5+C9 | N6: Your editable custom case from the left table. It remains the main model used by the topography dashboard.
A7: Along-track minimum | B7: x_min | C7: -60 | D7: km | E7: Left/start side of the modeled pass. | F7: TRUE | G7: Paper low-altitude 800-km pass | H7: 35 | I7: -400 | J7: 400 | K7: 400 | L7: 365 | M7: 400 | N7: Paper coverage requirement: groundtrack segments at least 800 km long below 400 km for most REASON datasets. This model makes that a parabola.
A8: Along-track maximum | B8: x_max | C8: 60 | D8: km | E8: Right/end side of the modeled pass. | F8: TRUE | G8: Paper ice-ocean 1600-km pass | H8: 35 | I8: -800 | J8: 800 | K8: 800 | L8: 965 | M8: 1000 | N8: Paper ice-ocean interface requirement: at least 1600 km below 1000 km. This model makes that a parabola.
A9: Altitude rise at edge | B9: Delta_z_edge | C9: 4 | D9: km | E9: How much altitude rises at +/- x_edge. | F9: TRUE | G9: Paper operating 25-to-1000-km pass | H9: 25 | I9: -800 | J9: 800 | K9: 800 | L9: 975 | M9: 1000 | N9: Paper instrument table lists operational altitudes of 25 km to 1000 km. This shows the lower-bound closest-approach case.
A10: Parabola edge location | B10: x_edge | C10: 60 | D10: km | E10: Controls curvature together with Delta_z_edge.
A11: Along-track speed | B11: v | C11: 4 | D11: km/s | E11: Used for range rate, Doppler, and pulse spacing. | F11: Scenario note | G11: The paper gives altitude ranges and required groundtrack lengths, not exact parabolic equations. These rows convert those paper values into the same simplified parabola equation so outcomes can be compared on one dashboard.
A12: Ice refractive index | B12: n | C12: 1.78 | E12: Used to convert extra slant path into apparent depth.
A13: VHF wavelength | B13: lambda_vhf | C13: 5 | D13: m | E13: REASON-like VHF wavelength.
A14: HF wavelength | B14: lambda_hf | C14: 33.3 | D14: m | E14: REASON-like HF wavelength.
A15: Interferometer baseline | B15: b | C15: 5 | D15: m | E15: Used for VHF phase estimate.
A16: VHF range resolution | B16: res_vhf | C16: 30 | D16: m | E16: Used for VHF apparent-depth uncertainty band.
A17: HF range resolution | B17: res_hf | C17: 300 | D17: m | E17: Used for HF apparent-depth uncertainty band.
A18: PRF choice 1 | B18: PRF_1 | C18: 50 | D18: Hz | E18: Example low PRF.
A19: PRF choice 2 | B19: PRF_2 | C19: 500 | D19: Hz | E19: Example medium PRF.
A20: PRF choice 3 | B20: PRF_3 | C20: 3000 | D20: Hz | E20: Example high PRF.
A21: Speed of light | B21: c | C21: 299792458 | D21: m/s | E21: Physical constant used for delay and timing.
A23: Model note | B23: The parabola is a simplified local path, not a real mission trajectory. Use it to see how geometry changes radar outputs.
A25: Representative Europa Topography Controls
A26: Parameter | B26: Symbol | C26: Value | D26: Unit | E26: Notes
A27: Topography enabled | B27: topography_on | C27: TRUE | E27: Dropdown-style toggle. TRUE adds terrain height to the radar geometry; FALSE returns to flat surface.
A28: Ridge height | B28: A_ridge | C28: 350 | D28: m | E28: Positive height for a representative double-ridge / raised band.
A29: Ridge center x | B29: ridge_x0 | C29: 0 | D29: km | E29: Along-track center of the ridge.
A30: Ridge center y | B30: ridge_y0 | C30: 25 | D30: km | E30: Cross-track center of the ridge.
A31: Ridge length sigma | B31: ridge_sigma_x | C31: 24 | D31: km | E31: Long direction of the ridge feature.
A32: Ridge width sigma | B32: ridge_sigma_y | C32: 3.5 | D32: km | E32: Narrow cross-track width of the ridge.
A33: Crater/depression depth | B33: D_crater | C33: 180 | D33: m | E33: Positive number becomes a negative depression in the surface model.
A34: Crater center x | B34: crater_x0 | C34: -18 | D34: km | E34: Along-track center of depression.
A35: Crater center y | B35: crater_y0 | C35: 8 | D35: km | E35: Cross-track center of depression.
A36: Crater width sigma | B36: crater_sigma | C36: 8 | D36: km | E36: Controls how broad the depression is.
A37: Chaos amplitude | B37: A_chaos | C37: 65 | D37: m | E37: Mixed sinusoidal terrain term for irregular chaos-like height variation.
A38: Fine roughness amplitude | B38: A_rough | C38: 35 | D38: m | E38: Smaller surface roughness term.
A39: Roughness wavelength x | B39: Lx | C39: 18 | D39: km | E39: Along-track roughness wavelength.
... A46: Terrain vertical uncertainty | B46: sigma_h | C46: 75 | D46: m | E46: Representative uncertainty band for the topographic height model.
A47: Terrain seed | B47: terrain_seed | C47: 7 | E47: Change this number to generate a different repeatable random-looking surface. Same seed gives the same graphs.
A48: Seeded random amplitude | B48: A_seeded | C48: 45 | D48: m | E48: Strength of the generated terrain added on top of the DEM-style surface.
A49: Seeded random scale x | B49: L_seed_x | C49: 12 | D49: km | E49: Along-track scale for seeded terrain waves.
...

Sheet Model_Data
A1: x_km | B1: z_km | C1: R_nadir_km | D1: R_off_km | E1: Delta_R_m | F1: apparent_depth_m | G1: extra_delay_us | H1: horizontal_offset_km | I1: look_angle_deg | J1: vhf_phase_deg | K1: relative_power | L1: power_dB | M1: dz_dx | N1: dz_dt_km_s | O1: range_rate_m_s | P1: vhf_doppler_hz | Q1: hf_doppler_hz | R1: vhf_band_low_m | S1: vhf_band_high_m | T1: hf_band_low_m | U1: hf_band_high_m | V1: abs_vhf_doppler_hz | W1: abs_hf_doppler_hz | X1: h_nadir_m | Y1: h_target_m | Z1: R_nadir_topo_km | AA1: R_off_topo_km | AB1: Delta_R_topo_m | AC1: apparent_depth_topo_m | AD1: extra_delay_topo_us | AE1: look_angle_topo_deg | AF1: vhf_phase_topo_deg | AG1: relative_power_topo | AH1: power_dB_topo | AI1: depth_change_topo_minus_flat_m | AJ1: delay_change_topo_minus_flat_us | AK1: target_minus_nadir_height_m | AL1: range_rate_topo_m_s | AM1: vhf_doppler_topo_hz | AN1: hf_doppler_topo_hz | AO1: abs_vhf_doppler_topo_hz | AP1: abs_hf_doppler_topo_hz | AQ1: topo_depth_uncertainty_m | AR1: topo_depth_low_m | AS1: topo_depth_high_m
A2: =Inputs!$C$7+0*(Inputs!$C$8-Inputs!$C$7)/240 | B2: =Inputs!$C$5+Inputs!$C$9*(A2/Inputs!$C$10)^2 | C2: =B2 | D2: =SQRT((Inputs!$C$52+B2)^2+Inputs!$C$52^2-2*(Inputs!$C$52+B2)*Inputs!$C$52*COS(SQRT(A2^2+Inputs!$C$6^2)/Inputs!$C$52)) | E2: =(D2-C2)*1000 | F2: =E2/Inputs!$C$12 | G2: =2*E2/Inputs!$C$21*1000000 | H2: =SQRT(A2^2+Inputs!$C$6^2) | I2: =DEGREES(ATAN(H2/B2)) | J2: =DEGREES((2*PI()/Inputs!$C$13)*Inputs!$C$15*SIN(RADIANS(I2))) | K2: =(C2/D2)^4 | L2: =10*LOG10(K2) | M2: =2*(Inputs!$C$9/(Inputs!$C$10^2))*A2 | N2: =M2*Inputs!$C$11 | O2: =1000*(D3-D2)/(A3-A2)*Inputs!$C$11 | P2: =-2*O2/Inputs!$C$13 | Q2: =-2*O2/Inputs!$C$14 | R2: =F2-Inputs!$C$16/2 | S2: =F2+Inputs!$C$16/2 | T2: =F2-Inputs!$C$17/2 | U2: =F2+Inputs!$C$17/2 | V2: =ABS(P2) | W2: =ABS(Q2) | X2: =IF(OR(Inputs!$C$27=TRUE,Inputs!$C$27="TRUE",Inputs!$C$27=1),1,0)*(Inputs!$C$51*(115*EXP(-(((0)-25)^2)/(4.5^2))+70*EXP(-(((0)+38)^2)/(7^2))*(0.55+0.45*SIN(2*PI()*(A2)/45))+24*SIN(2*PI()*(0)/9+(A2)/18)*EXP(-(((0)+5)^2)/(22^2))+18*SIN(2*PI()*(A2)/70))+Inputs!$C$28*EXP(-(((A2)-Inputs!$C$29)^2)/(2*Inputs!$C$31^2))*EXP(-(((0)-Inputs!$C$30)^2)/(2*Inputs!$C$32^2))+-Inputs!$C$33*EXP(-(((((A2)-Inputs!$C$34)^2)+(((0)-Inputs!$C$35)^2))/(2*Inputs!$C$36^2)))+Inputs!$C$37*(0.55*SIN(2*PI()*(A2)/Inputs!$C$39)+0.35*COS(2*PI()*(0)/Inputs!$C$40)+0.2*SIN(2*PI()*((A2)+(0))/(0.5*(Inputs!$C$39+Inputs!$C$40))))+Inputs!$C$38*SIN(2*PI()*(A2)/Inputs!$C$39)*SIN(2*PI()*(0)/Inputs!$C$40)+-Inputs!$C$41*EXP(-(((0)-Inputs!$C$43)^2)/(2*Inputs!$C$44^2))*EXP(-(((A2)-Inputs!$C$42)^2)/(2*Inputs!$C$45^2))+Inputs!$C$48*(0.7*(0.45*SIN(2*PI()*(((A2)/Inputs!$C$49)+Inputs!$C$47*0.137))+0.35*COS(2*PI()*(((0)/Inputs!$C$50)+Inputs!$C$47*0.173))+0.2*SIN(2*PI()*(((A2)+(0))/(0.5*(Inputs!$C$49+Inputs!$C$50))+Inputs!$C$47*0.097)))+0.3*(2*((SIN(((A2)*12.9898+(0)*78.233+Inputs!$C$47*37.719))*43758.5453)-INT((SIN(((A2)*12.9898+(0)*78.233+Inputs!$C$47*37.719))*43758.5453)))-1))) | Y2: =IF(OR(Inputs!$C$27=TRUE,Inputs!$C$27="TRUE",Inputs!$C$27=1),1,0)*(Inputs!$C$51*(115*EXP(-(((Inputs!$C$6)-25)^2)/(4.5^2))+70*EXP(-(((Inputs!$C$6)+38)^2)/(7^2))*(0.55+0.45*SIN(2*PI()*(A2)/45))+24*SIN(2*PI()*(Inputs!$C$6)/9+(A2)/18)*EXP(-(((Inputs!$C$6)+5)^2)/(22^2))+18*SIN(2*PI()*(A2)/70))+Inputs!$C$28*EXP(-(((A2)-Inputs!$C$29)^2)/(2*Inputs!$C$31^2))*EXP(-(((Inputs!$C$6)-Inputs!$C$30)^2)/(2*Inputs!$C$32^2))+-Inputs!$C$33*EXP(-(((((A2)-Inputs!$C$34)^2)+(((Inputs!$C$6)-Inputs!$C$35)^2))/(2*Inputs!$C$36^2)))+Inputs!$C$37*(0.55*SIN(2*PI()*(A2)/Inputs!$C$39)+0.35*COS(2*PI()*(Inputs!$C$6)/Inputs!$C$40)+0.2*SIN(2*PI()*((A2)+(Inputs!$C$6))/(0.5*(Inputs!$C$39+Inputs!$C$40))))+Inputs!$C$38*SIN(2*PI()*(A2)/Inputs!$C$39)*SIN(2*PI()*(Inputs!$C$6)/Inputs!$C$40)+-Inputs!$C$41*EXP(-(((Inputs!$C$6)-Inputs!$C$43)^2)/(2*Inputs!$C$44^2))*EXP(-(((A2)-Inputs!$C$42)^2)/(2*Inputs!$C$45^2))+Inputs!$C$48*(0.7*(0.45*SIN(2*PI()*(((A2)/Inputs!$C$49)+Inputs!$C$47*0.137))+0.35*COS(2*PI()*(((Inputs!$C$6)/Inputs!$C$50)+Inputs!$C$47*0.173))+0.2*SIN(2*PI()*(((A2)+(Inputs!$C$6))/(0.5*(Inputs!$C$49+Inputs!$C$50))+Inputs!$C$47*0.097)))+0.3*(2*((SIN(((A2)*12.9898+(Inputs!$C$6)*78.233+Inputs!$C$47*37.719))*43758.5453)-INT((SIN(((A2)*12.9898+(Inputs!$C$6)*78.233+Inputs!$C$47*37.719))*43758.5453)))-1))) | Z2: =B2-X2/1000 | AA2: =SQRT((Inputs!$C$52+B2)^2+(Inputs!$C$52+Y2/1000)^2-2*(Inputs!$C$52+B2)*(Inputs!$C$52+Y2/1000)*COS(SQRT(A2^2+Inputs!$C$6^2)/Inputs!$C$52)) | AB2: =(AA2-Z2)*1000 | AC2: =AB2/Inputs!$C$12 | AD2: =2*AB2/Inputs!$C$21*1000000 | AE2: =DEGREES(ATAN(H2/(B2-Y2/1000))) | AF2: =DEGREES((2*PI()/Inputs!$C$13)*Inputs!$C$15*SIN(RADIANS(AE2))) | AG2: =(Z2/AA2)^4 | AH2: =10*LOG10(AG2) | AI2: =AC2-F2 | AJ2: =AD2-G2 | AK2: =Y2-X2 | AL2: =1000*(AA3-AA2)/(A3-A2)*Inputs!$C$11 | AM2: =-2*AL2/Inputs!$C$13 | AN2: =-2*AL2/Inputs!$C$14 | AO2: =ABS(AM2) | AP2: =ABS(AN2) | AQ2: =IF(OR(Inputs!$C$27=TRUE,Inputs!$C$27="TRUE",Inputs!$C$27=1),Inputs!$C$46/Inputs!$C$12,0) | AR2: =AC2-AQ2 | AS2: =AC2+AQ2
A3: =Inputs!$C$7+1*(Inputs!$C$8-Inputs!$C$7)/240 | B3: =Inputs!$C$5+Inputs!$C$9*(A3/Inputs!$C$10)^2 | C3: =B3 | D3: =SQRT((Inputs!$C$52+B3)^2+Inputs!$C$52^2-2*(Inputs!$C$52+B3)*Inputs!$C$52*COS(SQRT(A3^2+Inputs!$C$6^2)/Inputs!$C$52)) | E3: =(D3-C3)*1000 | F3: =E3/Inputs!$C$12 | G3: =2*E3/Inputs!$C$21*1000000 | H3: =SQRT(A3^2+Inputs!$C$6^2) | I3: =DEGREES(ATAN(H3/B3)) | J3: =DEGREES((2*PI()/Inputs!$C$13)*Inputs!$C$15*SIN(RADIANS(I3))) | K3: =(C3/D3)^4 | L3: =10*LOG10(K3) | M3: =2*(Inputs!$C$9/(Inputs!$C$10^2))*A3 | N3: =M3*Inputs!$C$11 | O3: =1000*(D4-D2)/(A4-A2)*Inputs!$C$11 | P3: =-2*O3/Inputs!$C$13 | Q3: =-2*O3/Inputs!$C$14 | R3: =F3-Inputs!$C$16/2 | S3: =F3+Inputs!$C$16/2 | T3: =F3-Inputs!$C$17/2 | U3: =F3+Inputs!$C$17/2 | V3: =ABS(P3) | W3: =ABS(Q3) | X3: =IF(OR(Inputs!$C$27=TRUE,Inputs!$C$27="TRUE",Inputs!$C$27=1),1,0)*(Inputs!$C$51*(115*EXP(-(((0)-25)^2)/(4.5^2))+70*EXP(-(((0)+38)^2)/(7^2))*(0.55+0.45*SIN(2*PI()*(A3)/45))+24*SIN(2*PI()*(0)/9+(A3)/18)*EXP(-(((0)+5)^2)/(22^2))+18*SIN(2*PI()*(A3)/70))+Inputs!$C$28*EXP(-(((A3)-Inputs!$C$29)^2)/(2*Inputs!$C$31^2))*EXP(-(((0)-Inputs!$C$30)^2)/(2*Inputs!$C$32^2))+-Inputs!$C$33*EXP(-(((((A3)-Inputs!$C$34)^2)+(((0)-Inputs!$C$35)^2))/(2*Inputs!$C$36^2)))+Inputs!$C$37*(0.55*SIN(2*PI()*(A3)/Inputs!$C$39)+0.35*COS(2*PI()*(0)/Inputs!$C$40)+0.2*SIN(2*PI()*((A3)+(0))/(0.5*(Inputs!$C$39+Inputs!$C$40))))+Inputs!$C$38*SIN(2*PI()*(A3)/Inputs!$C$39)*SIN(2*PI()*(0)/Inputs!$C$40)+-Inputs!$C$41*EXP(-(((0)-Inputs!$C$43)^2)/(2*Inputs!$C$44^2))*EXP(-(((A3)-Inputs!$C$42)^2)/(2*Inputs!$C$45^2))+Inputs!$C$48*(0.7*(0.45*SIN(2*PI()*(((A3)/Inputs!$C$49)+Inputs!$C$47*0.137))+0.35*COS(2*PI()*(((0)/Inputs!$C$50)+Inputs!$C$47*0.173))+0.2*SIN(2*PI()*(((A3)+(0))/(0.5*(Inputs!$C$49+Inputs!$C$50))+Inputs!$C$47*0.097)))+0.3*(2*((SIN(((A3)*12.9898+(0)*78.233+Inputs!$C$47*37.719))*43758.5453)-INT((SIN(((A3)*12.9898+(0)*78.233+Inputs!$C$47*37.719))*43758.5453)))-1))) | Y3: =IF(OR(Inputs!$C$27=TRUE,Inputs!$C$27="TRUE",Inputs!$C$27=1),1,0)*(Inputs!$C$51*(115*EXP(-(((Inputs!$C$6)-25)^2)/(4.5^2))+70*EXP(-(((Inputs!$C$6)+38)^2)/(7^2))*(0.55+0.45*SIN(2*PI()*(A3)/45))+24*SIN(2*PI()*(Inputs!$C$6)/9+(A3)/18)*EXP(-(((Inputs!$C$6)+5)^2)/(22^2))+18*SIN(2*PI()*(A3)/70))+Inputs!$C$28*EXP(-(((A3)-Inputs!$C$29)^2)/(2*Inputs!$C$31^2))*EXP(-(((Inputs!$C$6)-Inputs!$C$30)^2)/(2*Inputs!$C$32^2))+-Inputs!$C$33*EXP(-(((((A3)-Inputs!$C$34)^2)+(((Inputs!$C$6)-Inputs!$C$35)^2))/(2*Inputs!$C$36^2)))+Inputs!$C$37*(0.55*SIN(2*PI()*(A3)/Inputs!$C$39)+0.35*COS(2*PI()*(Inputs!$C$6)/Inputs!$C$40)+0.2*SIN(2*PI()*((A3)+(Inputs!$C$6))/(0.5*(Inputs!$C$39+Inputs!$C$40))))+Inputs!$C$38*SIN(2*PI()*(A3)/Inputs!$C$39)*SIN(2*PI()*(Inputs!$C$6)/Inputs!$C$40)+-Inputs!$C$41*EXP(-(((Inputs!$C$6)-Inputs!$C$43)^2)/(2*Inputs!$C$44^2))*EXP(-(((A3)-Inputs!$C$42)^2)/(2*Inputs!$C$45^2))+Inputs!$C$48*(0.7*(0.45*SIN(2*PI()*(((A3)/Inputs!$C$49)+Inputs!$C$47*0.137))+0.35*COS(2*PI()*(((Inputs!$C$6)/Inputs!$C$50)+Inputs!$C$47*0.173))+0.2*SIN(2*PI()*(((A3)+(Inputs!$C$6))/(0.5*(Inputs!$C$49+Inputs!$C$50))+Inputs!$C$47*0.097)))+0.3*(2*((SIN(((A3)*12.9898+(Inputs!$C$6)*78.233+Inputs!$C$47*37.719))*43758.5453)-INT((SIN(((A3)*12.9898+(Inputs!$C$6)*78.233+Inputs!$C$47*37.719))*43758.5453)))-1))) | Z3: =B3-X3/1000 | AA3: =SQRT((Inputs!$C$52+B3)^2+(Inputs!$C$52+Y3/1000)^2-2*(Inputs!$C$52+B3)*(Inputs!$C$52+Y3/1000)*COS(SQRT(A3^2+Inputs!$C$6^2)/Inputs!$C$52)) | AB3: =(AA3-Z3)*1000 | AC3: =AB3/Inputs!$C$12 | AD3: =2*AB3/Inputs!$C$21*1000000 | AE3: =DEGREES(ATAN(H3/(B3-Y3/1000))) | AF3: =DEGREES((2*PI()/Inputs!$C$13)*Inputs!$C$15*SIN(RADIANS(AE3))) | AG3: =(Z3/AA3)^4 | AH3: =10*LOG10(AG3) | AI3: =AC3-F3 | AJ3: =AD3-G3 | AK3: =Y3-X3 | AL3: =1000*(AA4-AA2)/(A4-A2)*Inputs!$C$11 | AM3: =-2*AL3/Inputs!$C$13 | AN3: =-2*AL3/Inputs!$C$14 | AO3: =ABS(AM3) | AP3: =ABS(AN3) | AQ3: =IF(OR(Inputs!$C$27=TRUE,Inputs!$C$27="TRUE",Inputs!$C$27=1),Inputs!$C$46/Inputs!$C$12,0) | AR3: =AC3-AQ3 | AS3: =AC3+AQ3
A4: =Inputs!$C$7+2*(Inputs!$C$8-Inputs!$C$7)/240 | B4: =Inputs!$C$5+Inputs!$C$9*(A4/Inputs!$C$10)^2 | C4: =B4 | D4: =SQRT((Inputs!$C$52+B4)^2+Inputs!$C$52^2-2*(Inputs!$C$52+B4)*Inputs!$C$52*COS(SQRT(A4^2+Inputs!$C$6^2)/Inputs!$C$52)) | E4: =(D4-C4)*1000 | F4: =E4/Inputs!$C$12 | G4: =2*E4/Inputs!$C$21*1000000 | H4: =SQRT(A4^2+Inputs!$C$6^2) | I4: =DEGREES(ATAN(H4/B4)) | J4: =DEGREES((2*PI()/Inputs!$C$13)*Inputs!$C$15*SIN(RADIANS(I4))) | K4: =(C4/D4)^4 | L4: =10*LOG10(K4) | M4: =2*(Inputs!$C$9/(Inputs!$C$10^2))*A4 | N4: =M4*Inputs!$C$11 | O4: =1000*(D5-D3)/(A5-A3)*Inputs!$C$11 | P4: =-2*O4/Inputs!$C$13 | Q4: =-2*O4/Inputs!$C$14 | R4: =F4-Inputs!$C$16/2 | S4: =F4+Inputs!$C$16/2 | T4: =F4-Inputs!$C$17/2 | U4: =F4+Inputs!$C$17/2 | V4: =ABS(P4) | W4: =ABS(Q4) | X4: =IF(OR(Inputs!$C$27=TRUE,Inputs!$C$27="TRUE",Inputs!$C$27=1),1,0)*(Inputs!$C$51*(115*EXP(-(((0)-25)^2)/(4.5^2))+70*EXP(-(((0)+38)^2)/(7^2))*(0.55+0.45*SIN(2*PI()*(A4)/45))+24*SIN(2*PI()*(0)/9+(A4)/18)*EXP(-(((0)+5)^2)/(22^2))+18*SIN(2*PI()*(A4)/70))+Inputs!$C$28*EXP(-(((A4)-Inputs!$C$29)^2)/(2*Inputs!$C$31^2))*EXP(-(((0)-Inputs!$C$30)^2)/(2*Inputs!$C$32^2))+-Inputs!$C$33*EXP(-(((((A4)-Inputs!$C$34)^2)+(((0)-Inputs!$C$35)^2))/(2*Inputs!$C$36^2)))+Inputs!$C$37*(0.55*SIN(2*PI()*(A4)/Inputs!$C$39)+0.35*COS(2*PI()*(0)/Inputs!$C$40)+0.2*SIN(2*PI()*((A4)+(0))/(0.5*(Inputs!$C$39+Inputs!$C$40))))+Inputs!$C$38*SIN(2*PI()*(A4)/Inputs!$C$39)*SIN(2*PI()*(0)/Inputs!$C$40)+-Inputs!$C$41*EXP(-(((0)-Inputs!$C$43)^2)/(2*Inputs!$C$44^2))*EXP(-(((A4)-Inputs!$C$42)^2)/(2*Inputs!$C$45^2))+Inputs!$C$48*(0.7*(0.45*SIN(2*PI()*(((A4)/Inputs!$C$49)+Inputs!$C$47*0.137))+0.35*COS(2*PI()*(((0)/Inputs!$C$50)+Inputs!$C$47*0.173))+0.2*SIN(2*PI()*(((A4)+(0))/(0.5*(Inputs!$C$49+Inputs!$C$50))+Inputs!$C$47*0.097)))+0.3*(2*((SIN(((A4)*12.9898+(0)*78.233+Inputs!$C$47*37.719))*43758.5453)-INT((SIN(((A4)*12.9898+(0)*78.233+Inputs!$C$47*37.719))*43758.5453)))-1))) | Y4: =IF(OR(Inputs!$C$27=TRUE,Inputs!$C$27="TRUE",Inputs!$C$27=1),1,0)*(Inputs!$C$51*(115*EXP(-(((Inputs!$C$6)-25)^2)/(4.5^2))+70*EXP(-(((Inputs!$C$6)+38)^2)/(7^2))*(0.55+0.45*SIN(2*PI()*(A4)/45))+24*SIN(2*PI()*(Inputs!$C$6)/9+(A4)/18)*EXP(-(((Inputs!$C$6)+5)^2)/(22^2))+18*SIN(2*PI()*(A4)/70))+Inputs!$C$28*EXP(-(((A4)-Inputs!$C$29)^2)/(2*Inputs!$C$31^2))*EXP(-(((Inputs!$C$6)-Inputs!$C$30)^2)/(2*Inputs!$C$32^2))+-Inputs!$C$33*EXP(-(((((A4)-Inputs!$C$34)^2)+(((Inputs!$C$6)-Inputs!$C$35)^2))/(2*Inputs!$C$36^2)))+Inputs!$C$37*(0.55*SIN(2*PI()*(A4)/Inputs!$C$39)+0.35*COS(2*PI()*(Inputs!$C$6)/Inputs!$C$40)+0.2*SIN(2*PI()*((A4)+(Inputs!$C$6))/(0.5*(Inputs!$C$39+Inputs!$C$40))))+Inputs!$C$38*SIN(2*PI()*(A4)/Inputs!$C$39)*SIN(2*PI()*(Inputs!$C$6)/Inputs!$C$40)+-Inputs!$C$41*EXP(-(((Inputs!$C$6)-Inputs!$C$43)^2)/(2*Inputs!$C$44^2))*EXP(-(((A4)-Inputs!$C$42)^2)/(2*Inputs!$C$45^2))+Inputs!$C$48*(0.7*(0.45*SIN(2*PI()*(((A4)/Inputs!$C$49)+Inputs!$C$47*0.137))+0.35*COS(2*PI()*(((Inputs!$C$6)/Inputs!$C$50)+Inputs!$C$47*0.173))+0.2*SIN(2*PI()*(((A4)+(Inputs!$C$6))/(0.5*(Inputs!$C$49+Inputs!$C$50))+Inputs!$C$47*0.097)))+0.3*(2*((SIN(((A4)*12.9898+(Inputs!$C$6)*78.233+Inputs!$C$47*37.719))*43758.5453)-INT((SIN(((A4)*12.9898+(Inputs!$C$6)*78.233+Inputs!$C$47*37.719))*43758.5453)))-1))) | Z4: =B4-X4/1000 | AA4: =SQRT((Inputs!$C$52+B4)^2+(Inputs!$C$52+Y4/1000)^2-2*(Inputs!$C$52+B4)*(Inputs!$C$52+Y4/1000)*COS(SQRT(A4^2+Inputs!$C$6^2)/Inputs!$C$52)) | AB4: =(AA4-Z4)*1000 | AC4: =AB4/Inputs!$C$12 | AD4: =2*AB4/Inputs!$C$21*1000000 | AE4: =DEGREES(ATAN(H4/(B4-Y4/1000))) | AF4: =DEGREES((2*PI()/Inputs!$C$13)*Inputs!$C$15*SIN(RADIANS(AE4))) | AG4: =(Z4/AA4)^4 | AH4: =10*LOG10(AG4) | AI4: =AC4-F4 | AJ4: =AD4-G4 | AK4: =Y4-X4 | AL4: =1000*(AA5-AA3)/(A5-A3)*Inputs!$C$11 | AM4: =-2*AL4/Inputs!$C$13 | AN4: =-2*AL4/Inputs!$C$14 | AO4: =ABS(AM4) | AP4: =ABS(AN4) | AQ4: =IF(OR(Inputs!$C$27=TRUE,Inputs!$C$27="TRUE",Inputs!$C$27=1),Inputs!$C$46/Inputs!$C$12,0) | AR4: =AC4-AQ4 | AS4: =AC4+AQ4
A5: =Inputs!$C$7+3*(Inputs!$C$8-Inputs!$C$7)/240 | B5: =Inputs!$C$5+Inputs!$C$9*(A5/Inputs!$C$10)^2 | C5: =B5 | D5: =SQRT((Inputs!$C$52+B5)^2+Inputs!$C$52^2-2*(Inputs!$C$52+B5)*Inputs!$C$52*COS(SQRT(A5^2+Inputs!$C$6^2)/Inputs!$C$52)) | E5: =(D5-C5)*1000 | F5: =E5/Inputs!$C$12 | G5: =2*E5/Inputs!$C$21*1000000 | H5: =SQRT(A5^2+Inputs!$C$6^2) | I5: =DEGREES(ATAN(H5/B5)) | J5: =DEGREES((2*PI()/Inputs!$C$13)*Inputs!$C$15*SIN(RADIANS(I5))) | K5: =(C5/D5)^4 | L5: =10*LOG10(K5) | M5: =2*(Inputs!$C$9/(Inputs!$C$10^2))*A5 | N5: =M5*Inputs!$C$11 | O5: =1000*(D6-D4)/(A6-A4)*Inputs!$C$11 | P5: =-2*O5/Inputs!$C$13 | Q5: =-2*O5/Inputs!$C$14 | R5: =F5-Inputs!$C$16/2 | S5: =F5+Inputs!$C$16/2 | T5: =F5-Inputs!$C$17/2 | U5: =F5+Inputs!$C$17/2 | V5: =ABS(P5) | W5: =ABS(Q5) | X5: =IF(OR(Inputs!$C$27=TRUE,Inputs!$C$27="TRUE",Inputs!$C$27=1),1,0)*(Inputs!$C$51*(115*EXP(-(((0)-25)^2)/(4.5^2))+70*EXP(-(((0)+38)^2)/(7^2))*(0.55+0.45*SIN(2*PI()*(A5)/45))+24*SIN(2*PI()*(0)/9+(A5)/18)*EXP(-(((0)+5)^2)/(22^2))+18*SIN(2*PI()*(A5)/70))+Inputs!$C$28*EXP(-(((A5)-Inputs!$C$29)^2)/(2*Inputs!$C$31^2))*EXP(-(((0)-Inputs!$C$30)^2)/(2*Inputs!$C$32^2))+-Inputs!$C$33*EXP(-(((((A5)-Inputs!$C$34)^2)+(((0)-Inputs!$C$35)^2))/(2*Inputs!$C$36^2)))+Inputs!$C$37*(0.55*SIN(2*PI()*(A5)/Inputs!$C$39)+0.35*COS(2*PI()*(0)/Inputs!$C$40)+0.2*SIN(2*PI()*((A5)+(0))/(0.5*(Inputs!$C$39+Inputs!$C$40))))+Inputs!$C$38*SIN(2*PI()*(A5)/Inputs!$C$39)*SIN(2*PI()*(0)/Inputs!$C$40)+-Inputs!$C$41*EXP(-(((0)-Inputs!$C$43)^2)/(2*Inputs!$C$44^2))*EXP(-(((A5)-Inputs!$C$42)^2)/(2*Inputs!$C$45^2))+Inputs!$C$48*(0.7*(0.45*SIN(2*PI()*(((A5)/Inputs!$C$49)+Inputs!$C$47*0.137))+0.35*COS(2*PI()*(((0)/Inputs!$C$50)+Inputs!$C$47*0.173))+0.2*SIN(2*PI()*(((A5)+(0))/(0.5*(Inputs!$C$49+Inputs!$C$50))+Inputs!$C$47*0.097)))+0.3*(2*((SIN(((A5)*12.9898+(0)*78.233+Inputs!$C$47*37.719))*43758.5453)-INT((SIN(((A5)*12.9898+(0)*78.233+Inputs!$C$47*37.719))*43758.5453)))-1))) | Y5: =IF(OR(Inputs!$C$27=TRUE,Inputs!$C$27="TRUE",Inputs!$C$27=1),1,0)*(Inputs!$C$51*(115*EXP(-(((Inputs!$C$6)-25)^2)/(4.5^2))+70*EXP(-(((Inputs!$C$6)+38)^2)/(7^2))*(0.55+0.45*SIN(2*PI()*(A5)/45))+24*SIN(2*PI()*(Inputs!$C$6)/9+(A5)/18)*EXP(-(((Inputs!$C$6)+5)^2)/(22^2))+18*SIN(2*PI()*(A5)/70))+Inputs!$C$28*EXP(-(((A5)-Inputs!$C$29)^2)/(2*Inputs!$C$31^2))*EXP(-(((Inputs!$C$6)-Inputs!$C$30)^2)/(2*Inputs!$C$32^2))+-Inputs!$C$33*EXP(-(((((A5)-Inputs!$C$34)^2)+(((Inputs!$C$6)-Inputs!$C$35)^2))/(2*Inputs!$C$36^2)))+Inputs!$C$37*(0.55*SIN(2*PI()*(A5)/Inputs!$C$39)+0.35*COS(2*PI()*(Inputs!$C$6)/Inputs!$C$40)+0.2*SIN(2*PI()*((A5)+(Inputs!$C$6))/(0.5*(Inputs!$C$39+Inputs!$C$40))))+Inputs!$C$38*SIN(2*PI()*(A5)/Inputs!$C$39)*SIN(2*PI()*(Inputs!$C$6)/Inputs!$C$40)+-Inputs!$C$41*EXP(-(((Inputs!$C$6)-Inputs!$C$43)^2)/(2*Inputs!$C$44^2))*EXP(-(((A5)-Inputs!$C$42)^2)/(2*Inputs!$C$45^2))+Inputs!$C$48*(0.7*(0.45*SIN(2*PI()*(((A5)/Inputs!$C$49)+Inputs!$C$47*0.137))+0.35*COS(2*PI()*(((Inputs!$C$6)/Inputs!$C$50)+Inputs!$C$47*0.173))+0.2*SIN(2*PI()*(((A5)+(Inputs!$C$6))/(0.5*(Inputs!$C$49+Inputs!$C$50))+Inputs!$C$47*0.097)))+0.3*(2*((SIN(((A5)*12.9898+(Inputs!$C$6)*78.233+Inputs!$C$47*37.719))*43758.5453)-INT((SIN(((A5)*12.9898+(Inputs!$C$6)*78.233+Inputs!$C$47*37.719))*43758.5453)))-1))) | Z5: =B5-X5/1000 | AA5: =SQRT((Inputs!$C$52+B5)^2+(Inputs!$C$52+Y5/1000)^2-2*(Inputs!$C$52+B5)*(Inputs!$C$52+Y5/1000)*COS(SQRT(A5^2+Inputs!$C$6^2)/Inputs!$C$52)) | AB5: =(AA5-Z5)*1000 | AC5: =AB5/Inputs!$C$12 | AD5: =2*AB5/Inputs!$C$21*1000000 | AE5: =DEGREES(ATAN(H5/(B5-Y5/1000))) | AF5: =DEGREES((2*PI()/Inputs!$C$13)*Inputs!$C$15*SIN(RADIANS(AE5))) | AG5: =(Z5/AA5)^4 | AH5: =10*LOG10(AG5) | AI5: =AC5-F5 | AJ5: =AD5-G5 | AK5: =Y5-X5 | AL5: =1000*(AA6-AA4)/(A6-A4)*Inputs!$C$11 | AM5: =-2*AL5/Inputs!$C$13 | AN5: =-2*AL5/Inputs!$C$14 | AO5: =ABS(AM5) | AP5: =ABS(AN5) | AQ5: =IF(OR(Inputs!$C$27=TRUE,Inputs!$C$27="TRUE",Inputs!$C$27=1),Inputs!$C$46/Inputs!$C$12,0) | AR5: =AC5-AQ5 | AS5: =AC5+AQ5
A6: =Inputs!$C$7+4*(Inputs!$C$8-Inputs!$C$7)/240 | B6: =Inputs!$C$5+Inputs!$C$9*(A6/Inputs!$C$10)^2 | C6: =B6 | D6: =SQRT((Inputs!$C$52+B6)^2+Inputs!$C$52^2-2*(Inputs!$C$52+B6)*Inputs!$C$52*COS(SQRT(A6^2+Inputs!$C$6^2)/Inputs!$C$52)) | E6: =(D6-C6)*1000 | F6: =E6/Inputs!$C$12 | G6: =2*E6/Inputs!$C$21*1000000 | H6: =SQRT(A6^2+Inputs!$C$6^2) | I6: =DEGREES(ATAN(H6/B6)) | J6: =DEGREES((2*PI()/Inputs!$C$13)*Inputs!$C$15*SIN(RADIANS(I6))) | K6: =(C6/D6)^4 | L6: =10*LOG10(K6) | M6: =2*(Inputs!$C$9/(Inputs!$C$10^2))*A6 | N6: =M6*Inputs!$C$11 | O6: =1000*(D7-D5)/(A7-A5)*Inputs!$C$11 | P6: =-2*O6/Inputs!$C$13 | Q6: =-2*O6/Inputs!$C$14 | R6: =F6-Inputs!$C$16/2 | S6: =F6+Inputs!$C$16/2 | T6: =F6-Inputs!$C$17/2 | U6: =F6+Inputs!$C$17/2 | V6: =ABS(P6) | W6: =ABS(Q6) | X6: =IF(OR(Inputs!$C$27=TRUE,Inputs!$C$27="TRUE",Inputs!$C$27=1),1,0)*(Inputs!$C$51*(115*EXP(-(((0)-25)^2)/(4.5^2))+70*EXP(-(((0)+38)^2)/(7^2))*(0.55+0.45*SIN(2*PI()*(A6)/45))+24*SIN(2*PI()*(0)/9+(A6)/18)*EXP(-(((0)+5)^2)/(22^2))+18*SIN(2*PI()*(A6)/70))+Inputs!$C$28*EXP(-(((A6)-Inputs!$C$29)^2)/(2*Inputs!$C$31^2))*EXP(-(((0)-Inputs!$C$30)^2)/(2*Inputs!$C$32^2))+-Inputs!$C$33*EXP(-(((((A6)-Inputs!$C$34)^2)+(((0)-Inputs!$C$35)^2))/(2*Inputs!$C$36^2)))+Inputs!$C$37*(0.55*SIN(2*PI()*(A6)/Inputs!$C$39)+0.35*COS(2*PI()*(0)/Inputs!$C$40)+0.2*SIN(2*PI()*((A6)+(0))/(0.5*(Inputs!$C$39+Inputs!$C$40))))+Inputs!$C$38*SIN(2*PI()*(A6)/Inputs!$C$39)*SIN(2*PI()*(0)/Inputs!$C$40)+-Inputs!$C$41*EXP(-(((0)-Inputs!$C$43)^2)/(2*Inputs!$C$44^2))*EXP(-(((A6)-Inputs!$C$42)^2)/(2*Inputs!$C$45^2))+Inputs!$C$48*(0.7*(0.45*SIN(2*PI()*(((A6)/Inputs!$C$49)+Inputs!$C$47*0.137))+0.35*COS(2*PI()*(((0)/Inputs!$C$50)+Inputs!$C$47*0.173))+0.2*SIN(2*PI()*(((A6)+(0))/(0.5*(Inputs!$C$49+Inputs!$C$50))+Inputs!$C$47*0.097)))+0.3*(2*((SIN(((A6)*12.9898+(0)*78.233+Inputs!$C$47*37.719))*43758.5453)-INT((SIN(((A6)*12.9898+(0)*78.233+Inputs!$C$47*37.719))*43758.5453)))-1))) | Y6: =IF(OR(Inputs!$C$27=TRUE,Inputs!$C$27="TRUE",Inputs!$C$27=1),1,0)*(Inputs!$C$51*(115*EXP(-(((Inputs!$C$6)-25)^2)/(4.5^2))+70*EXP(-(((Inputs!$C$6)+38)^2)/(7^2))*(0.55+0.45*SIN(2*PI()*(A6)/45))+24*SIN(2*PI()*(Inputs!$C$6)/9+(A6)/18)*EXP(-(((Inputs!$C$6)+5)^2)/(22^2))+18*SIN(2*PI()*(A6)/70))+Inputs!$C$28*EXP(-(((A6)-Inputs!$C$29)^2)/(2*Inputs!$C$31^2))*EXP(-(((Inputs!$C$6)-Inputs!$C$30)^2)/(2*Inputs!$C$32^2))+-Inputs!$C$33*EXP(-(((((A6)-Inputs!$C$34)^2)+(((Inputs!$C$6)-Inputs!$C$35)^2))/(2*Inputs!$C$36^2)))+Inputs!$C$37*(0.55*SIN(2*PI()*(A6)/Inputs!$C$39)+0.35*COS(2*PI()*(Inputs!$C$6)/Inputs!$C$40)+0.2*SIN(2*PI()*((A6)+(Inputs!$C$6))/(0.5*(Inputs!$C$39+Inputs!$C$40))))+Inputs!$C$38*SIN(2*PI()*(A6)/Inputs!$C$39)*SIN(2*PI()*(Inputs!$C$6)/Inputs!$C$40)+-Inputs!$C$41*EXP(-(((Inputs!$C$6)-Inputs!$C$43)^2)/(2*Inputs!$C$44^2))*EXP(-(((A6)-Inputs!$C$42)^2)/(2*Inputs!$C$45^2))+Inputs!$C$48*(0.7*(0.45*SIN(2*PI()*(((A6)/Inputs!$C$49)+Inputs!$C$47*0.137))+0.35*COS(2*PI()*(((Inputs!$C$6)/Inputs!$C$50)+Inputs!$C$47*0.173))+0.2*SIN(2*PI()*(((A6)+(Inputs!$C$6))/(0.5*(Inputs!$C$49+Inputs!$C$50))+Inputs!$C$47*0.097)))+0.3*(2*((SIN(((A6)*12.9898+(Inputs!$C$6)*78.233+Inputs!$C$47*37.719))*43758.5453)-INT((SIN(((A6)*12.9898+(Inputs!$C$6)*78.233+Inputs!$C$47*37.719))*43758.5453)))-1))) | Z6: =B6-X6/1000 | AA6: =SQRT((Inputs!$C$52+B6)^2+(Inputs!$C$52+Y6/1000)^2-2*(Inputs!$C$52+B6)*(Inputs!$C$52+Y6/1000)*COS(SQRT(A6^2+Inputs!$C$6^2)/Inputs!$C$52)) | AB6: =(AA6-Z6)*1000 | AC6: =AB6/Inputs!$C$12 | AD6: =2*AB6/Inputs!$C$21*1000000 | AE6: =DEGREES(ATAN(H6/(B6-Y6/1000))) | AF6: =DEGREES((2*PI()/Inputs!$C$13)*Inputs!$C$15*SIN(RADIANS(AE6))) | AG6: =(Z6/AA6)^4 | AH6: =10*LOG10(AG6) | AI6: =AC6-F6 | AJ6: =AD6-G6 | AK6: =Y6-X6 | AL6: =1000*(AA7-AA5)/(A7-A5)*Inputs!$C$11 | AM6: =-2*AL6/Inputs!$C$13 | AN6: =-2*AL6/Inputs!$C$14 | AO6: =ABS(AM6) | AP6: =ABS(AN6) | AQ6: =IF(OR(Inputs!$C$27=TRUE,Inputs!$C$27="TRUE",Inputs!$C$27=1),Inputs!$C$46/Inputs!$C$12,0) | AR6: =AC6-AQ6 | AS6: =AC6+AQ6
A7: =Inputs!$C$7+5*(Inputs!$C$8-Inputs!$C$7)/240 | B7: =Inputs!$C$5+Inputs!$C$9*(A7/Inputs!$C$10)^2 | C7: =B7 | D7: =SQRT((Inputs!$C$52+B7)^2+Inputs!$C$52^2-2*(Inputs!$C$52+B7)*Inputs!$C$52*COS(SQRT(A7^2+Inputs!$C$6^2)/Inputs!$C$52)) | E7: =(D7-C7)*1000 | F7: =E7/Inputs!$C$12 | G7: =2*E7/Inputs!$C$21*1000000 | H7: =SQRT(A7^2+Inputs!$C$6^2) | I7: =DEGREES(ATAN(H7/B7)) | J7: =DEGREES((2*PI()/Inputs!$C$13)*Inputs!$C$15*SIN(RADIANS(I7))) | K7: =(C7/D7)^4 | L7: =10*LOG10(K7) | M7: =2*(Inputs!$C$9/(Inputs!$C$10^2))*A7 | N7: =M7*Inputs!$C$11 | O7: =1000*(D8-D6)/(A8-A6)*Inputs!$C$11 | P7: =-2*O7/Inputs!$C$13 | Q7: =-2*O7/Inputs!$C$14 | R7: =F7-Inputs!$C$16/2 | S7: =F7+Inputs!$C$16/2 | T7: =F7-Inputs!$C$17/2 | U7: =F7+Inputs!$C$17/2 | V7: =ABS(P7) | W7: =ABS(Q7) | X7: =IF(OR(Inputs!$C$27=TRUE,Inputs!$C$27="TRUE",Inputs!$C$27=1),1,0)*(Inputs!$C$51*(115*EXP(-(((0)-25)^2)/(4.5^2))+70*EXP(-(((0)+38)^2)/(7^2))*(0.55+0.45*SIN(2*PI()*(A7)/45))+24*SIN(2*PI()*(0)/9+(A7)/18)*EXP(-(((0)+5)^2)/(22^2))+18*SIN(2*PI()*(A7)/70))+Inputs!$C$28*EXP(-(((A7)-Inputs!$C$29)^2)/(2*Inputs!$C$31^2))*EXP(-(((0)-Inputs!$C$30)^2)/(2*Inputs!$C$32^2))+-Inputs!$C$33*EXP(-(((((A7)-Inputs!$C$34)^2)+(((0)-Inputs!$C$35)^2))/(2*Inputs!$C$36^2)))+Inputs!$C$37*(0.55*SIN(2*PI()*(A7)/Inputs!$C$39)+0.35*COS(2*PI()*(0)/Inputs!$C$40)+0.2*SIN(2*PI()*((A7)+(0))/(0.5*(Inputs!$C$39+Inputs!$C$40))))+Inputs!$C$38*SIN(2*PI()*(A7)/Inputs!$C$39)*SIN(2*PI()*(0)/Inputs!$C$40)+-Inputs!$C$41*EXP(-(((0)-Inputs!$C$43)^2)/(2*Inputs!$C$44^2))*EXP(-(((A7)-Inputs!$C$42)^2)/(2*Inputs!$C$45^2))+Inputs!$C$48*(0.7*(0.45*SIN(2*PI()*(((A7)/Inputs!$C$49)+Inputs!$C$47*0.137))+0.35*COS(2*PI()*(((0)/Inputs!$C$50)+Inputs!$C$47*0.173))+0.2*SIN(2*PI()*(((A7)+(0))/(0.5*(Inputs!$C$49+Inputs!$C$50))+Inputs!$C$47*0.097)))+0.3*(2*((SIN(((A7)*12.9898+(0)*78.233+Inputs!$C$47*37.719))*43758.5453)-INT((SIN(((A7)*12.9898+(0)*78.233+Inputs!$C$47*37.719))*43758.5453)))-1))) | Y7: =IF(OR(Inputs!$C$27=TRUE,Inputs!$C$27="TRUE",Inputs!$C$27=1),1,0)*(Inputs!$C$51*(115*EXP(-(((Inputs!$C$6)-25)^2)/(4.5^2))+70*EXP(-(((Inputs!$C$6)+38)^2)/(7^2))*(0.55+0.45*SIN(2*PI()*(A7)/45))+24*SIN(2*PI()*(Inputs!$C$6)/9+(A7)/18)*EXP(-(((Inputs!$C$6)+5)^2)/(22^2))+18*SIN(2*PI()*(A7)/70))+Inputs!$C$28*EXP(-(((A7)-Inputs!$C$29)^2)/(2*Inputs!$C$31^2))*EXP(-(((Inputs!$C$6)-Inputs!$C$30)^2)/(2*Inputs!$C$32^2))+-Inputs!$C$33*EXP(-(((((A7)-Inputs!$C$34)^2)+(((Inputs!$C$6)-Inputs!$C$35)^2))/(2*Inputs!$C$36^2)))+Inputs!$C$37*(0.55*SIN(2*PI()*(A7)/Inputs!$C$39)+0.35*COS(2*PI()*(Inputs!$C$6)/Inputs!$C$40)+0.2*SIN(2*PI()*((A7)+(Inputs!$C$6))/(0.5*(Inputs!$C$39+Inputs!$C$40))))+Inputs!$C$38*SIN(2*PI()*(A7)/Inputs!$C$39)*SIN(2*PI()*(Inputs!$C$6)/Inputs!$C$40)+-Inputs!$C$41*EXP(-(((Inputs!$C$6)-Inputs!$C$43)^2)/(2*Inputs!$C$44^2))*EXP(-(((A7)-Inputs!$C$42)^2)/(2*Inputs!$C$45^2))+Inputs!$C$48*(0.7*(0.45*SIN(2*PI()*(((A7)/Inputs!$C$49)+Inputs!$C$47*0.137))+0.35*COS(2*PI()*(((Inputs!$C$6)/Inputs!$C$50)+Inputs!$C$47*0.173))+0.2*SIN(2*PI()*(((A7)+(Inputs!$C$6))/(0.5*(Inputs!$C$49+Inputs!$C$50))+Inputs!$C$47*0.097)))+0.3*(2*((SIN(((A7)*12.9898+(Inputs!$C$6)*78.233+Inputs!$C$47*37.719))*43758.5453)-INT((SIN(((A7)*12.9898+(Inputs!$C$6)*78.233+Inputs!$C$47*37.719))*43758.5453)))-1))) | Z7: =B7-X7/1000 | AA7: =SQRT((Inputs!$C$52+B7)^2+(Inputs!$C$52+Y7/1000)^2-2*(Inputs!$C$52+B7)*(Inputs!$C$52+Y7/1000)*COS(SQRT(A7^2+Inputs!$C$6^2)/Inputs!$C$52)) | AB7: =(AA7-Z7)*1000 | AC7: =AB7/Inputs!$C$12 | AD7: =2*AB7/Inputs!$C$21*1000000 | AE7: =DEGREES(ATAN(H7/(B7-Y7/1000))) | AF7: =DEGREES((2*PI()/Inputs!$C$13)*Inputs!$C$15*SIN(RADIANS(AE7))) | AG7: =(Z7/AA7)^4 | AH7: =10*LOG10(AG7) | AI7: =AC7-F7 | AJ7: =AD7-G7 | AK7: =Y7-X7 | AL7: =1000*(AA8-AA6)/(A8-A6)*Inputs!$C$11 | AM7: =-2*AL7/Inputs!$C$13 | AN7: =-2*AL7/Inputs!$C$14 | AO7: =ABS(AM7) | AP7: =ABS(AN7) | AQ7: =IF(OR(Inputs!$C$27=TRUE,Inputs!$C$27="TRUE",Inputs!$C$27=1),Inputs!$C$46/Inputs!$C$12,0) | AR7: =AC7-AQ7 | AS7: =AC7+AQ7
A8: =Inputs!$C$7+6*(Inputs!$C$8-Inputs!$C$7)/240 | B8: =Inputs!$C$5+Inputs!$C$9*(A8/Inputs!$C$10)^2 | C8: =B8 | D8: =SQRT((Inputs!$C$52+B8)^2+Inputs!$C$52^2-2*(Inputs!$C$52+B8)*Inputs!$C$52*COS(SQRT(A8^2+Inputs!$C$6^2)/Inputs!$C$52)) | E8: =(D8-C8)*1000 | F8: =E8/Inputs!$C$12 | G8: =2*E8/Inputs!$C$21*1000000 | H8: =SQRT(A8^2+Inputs!$C$6^2) | I8: =DEGREES(ATAN(H8/B8)) | J8: =DEGREES((2*PI()/Inputs!$C$13)*Inputs!$C$15*SIN(RADIANS(I8))) | K8: =(C8/D8)^4 | L8: =10*LOG10(K8) | M8: =2*(Inputs!$C$9/(Inputs!$C$10^2))*A8 | N8: =M8*Inputs!$C$11 | O8: =1000*(D9-D7)/(A9-A7)*Inputs!$C$11 | P8: =-2*O8/Inputs!$C$13 | Q8: =-2*O8/Inputs!$C$14 | R8: =F8-Inputs!$C$16/2 | S8: =F8+Inputs!$C$16/2 | T8: =F8-Inputs!$C$17/2 | U8: =F8+Inputs!$C$17/2 | V8: =ABS(P8) | W8: =ABS(Q8) | X8: =IF(OR(Inputs!$C$27=TRUE,Inputs!$C$27="TRUE",Inputs!$C$27=1),1,0)*(Inputs!$C$51*(115*EXP(-(((0)-25)^2)/(4.5^2))+70*EXP(-(((0)+38)^2)/(7^2))*(0.55+0.45*SIN(2*PI()*(A8)/45))+24*SIN(2*PI()*(0)/9+(A8)/18)*EXP(-(((0)+5)^2)/(22^2))+18*SIN(2*PI()*(A8)/70))+Inputs!$C$28*EXP(-(((A8)-Inputs!$C$29)^2)/(2*Inputs!$C$31^2))*EXP(-(((0)-Inputs!$C$30)^2)/(2*Inputs!$C$32^2))+-Inputs!$C$33*EXP(-(((((A8)-Inputs!$C$34)^2)+(((0)-Inputs!$C$35)^2))/(2*Inputs!$C$36^2)))+Inputs!$C$37*(0.55*SIN(2*PI()*(A8)/Inputs!$C$39)+0.35*COS(2*PI()*(0)/Inputs!$C$40)+0.2*SIN(2*PI()*((A8)+(0))/(0.5*(Inputs!$C$39+Inputs!$C$40))))+Inputs!$C$38*SIN(2*PI()*(A8)/Inputs!$C$39)*SIN(2*PI()*(0)/Inputs!$C$40)+-Inputs!$C$41*EXP(-(((0)-Inputs!$C$43)^2)/(2*Inputs!$C$44^2))*EXP(-(((A8)-Inputs!$C$42)^2)/(2*Inputs!$C$45^2))+Inputs!$C$48*(0.7*(0.45*SIN(2*PI()*(((A8)/Inputs!$C$49)+Inputs!$C$47*0.137))+0.35*COS(2*PI()*(((0)/Inputs!$C$50)+Inputs!$C$47*0.173))+0.2*SIN(2*PI()*(((A8)+(0))/(0.5*(Inputs!$C$49+Inputs!$C$50))+Inputs!$C$47*0.097)))+0.3*(2*((SIN(((A8)*12.9898+(0)*78.233+Inputs!$C$47*37.719))*43758.5453)-INT((SIN(((A8)*12.9898+(0)*78.233+Inputs!$C$47*37.719))*43758.5453)))-1))) | Y8: =IF(OR(Inputs!$C$27=TRUE,Inputs!$C$27="TRUE",Inputs!$C$27=1),1,0)*(Inputs!$C$51*(115*EXP(-(((Inputs!$C$6)-25)^2)/(4.5^2))+70*EXP(-(((Inputs!$C$6)+38)^2)/(7^2))*(0.55+0.45*SIN(2*PI()*(A8)/45))+24*SIN(2*PI()*(Inputs!$C$6)/9+(A8)/18)*EXP(-(((Inputs!$C$6)+5)^2)/(22^2))+18*SIN(2*PI()*(A8)/70))+Inputs!$C$28*EXP(-(((A8)-Inputs!$C$29)^2)/(2*Inputs!$C$31^2))*EXP(-(((Inputs!$C$6)-Inputs!$C$30)^2)/(2*Inputs!$C$32^2))+-Inputs!$C$33*EXP(-(((((A8)-Inputs!$C$34)^2)+(((Inputs!$C$6)-Inputs!$C$35)^2))/(2*Inputs!$C$36^2)))+Inputs!$C$37*(0.55*SIN(2*PI()*(A8)/Inputs!$C$39)+0.35*COS(2*PI()*(Inputs!$C$6)/Inputs!$C$40)+0.2*SIN(2*PI()*((A8)+(Inputs!$C$6))/(0.5*(Inputs!$C$39+Inputs!$C$40))))+Inputs!$C$38*SIN(2*PI()*(A8)/Inputs!$C$39)*SIN(2*PI()*(Inputs!$C$6)/Inputs!$C$40)+-Inputs!$C$41*EXP(-(((Inputs!$C$6)-Inputs!$C$43)^2)/(2*Inputs!$C$44^2))*EXP(-(((A8)-Inputs!$C$42)^2)/(2*Inputs!$C$45^2))+Inputs!$C$48*(0.7*(0.45*SIN(2*PI()*(((A8)/Inputs!$C$49)+Inputs!$C$47*0.137))+0.35*COS(2*PI()*(((Inputs!$C$6)/Inputs!$C$50)+Inputs!$C$47*0.173))+0.2*SIN(2*PI()*(((A8)+(Inputs!$C$6))/(0.5*(Inputs!$C$49+Inputs!$C$50))+Inputs!$C$47*0.097)))+0.3*(2*((SIN(((A8)*12.9898+(Inputs!$C$6)*78.233+Inputs!$C$47*37.719))*43758.5453)-INT((SIN(((A8)*12.9898+(Inputs!$C$6)*78.233+Inputs!$C$47*37.719))*43758.5453)))-1))) | Z8: =B8-X8/1000 | AA8: =SQRT((Inputs!$C$52+B8)^2+(Inputs!$C$52+Y8/1000)^2-2*(Inputs!$C$52+B8)*(Inputs!$C$52+Y8/1000)*COS(SQRT(A8^2+Inputs!$C$6^2)/Inputs!$C$52)) | AB8: =(AA8-Z8)*1000 | AC8: =AB8/Inputs!$C$12 | AD8: =2*AB8/Inputs!$C$21*1000000 | AE8: =DEGREES(ATAN(H8/(B8-Y8/1000))) | AF8: =DEGREES((2*PI()/Inputs!$C$13)*Inputs!$C$15*SIN(RADIANS(AE8))) | AG8: =(Z8/AA8)^4 | AH8: =10*LOG10(AG8) | AI8: =AC8-F8 | AJ8: =AD8-G8 | AK8: =Y8-X8 | AL8: =1000*(AA9-AA7)/(A9-A7)*Inputs!$C$11 | AM8: =-2*AL8/Inputs!$C$13 | AN8: =-2*AL8/Inputs!$C$14 | AO8: =ABS(AM8) | AP8: =ABS(AN8) | AQ8: =IF(OR(Inputs!$C$27=TRUE,Inputs!$C$27="TRUE",Inputs!$C$27=1),Inputs!$C$46/Inputs!$C$12,0) | AR8: =AC8-AQ8 | AS8: =AC8+AQ8
A9: =Inputs!$C$7+7*(Inputs!$C$8-Inputs!$C$7)/240 | B9: =Inputs!$C$5+Inputs!$C$9*(A9/Inputs!$C$10)^2 | C9: =B9 | D9: =SQRT((Inputs!$C$52+B9)^2+Inputs!$C$52^2-2*(Inputs!$C$52+B9)*Inputs!$C$52*COS(SQRT(A9^2+Inputs!$C$6^2)/Inputs!$C$52)) | E9: =(D9-C9)*1000 | F9: =E9/Inputs!$C$12 | G9: =2*E9/Inputs!$C$21*1000000 | H9: =SQRT(A9^2+Inputs!$C$6^2) | I9: =DEGREES(ATAN(H9/B9)) | J9: =DEGREES((2*PI()/Inputs!$C$13)*Inputs!$C$15*SIN(RADIANS(I9))) | K9: =(C9/D9)^4 | L9: =10*LOG10(K9) | M9: =2*(Inputs!$C$9/(Inputs!$C$10^2))*A9 | N9: =M9*Inputs!$C$11 | O9: =1000*(D10-D8)/(A10-A8)*Inputs!$C$11 | P9: =-2*O9/Inputs!$C$13 | Q9: =-2*O9/Inputs!$C$14 | R9: =F9-Inputs!$C$16/2 | S9: =F9+Inputs!$C$16/2 | T9: =F9-Inputs!$C$17/2 | U9: =F9+Inputs!$C$17/2 | V9: =ABS(P9) | W9: =ABS(Q9) | X9: =IF(OR(Inputs!$C$27=TRUE,Inputs!$C$27="TRUE",Inputs!$C$27=1),1,0)*(Inputs!$C$51*(115*EXP(-(((0)-25)^2)/(4.5^2))+70*EXP(-(((0)+38)^2)/(7^2))*(0.55+0.45*SIN(2*PI()*(A9)/45))+24*SIN(2*PI()*(0)/9+(A9)/18)*EXP(-(((0)+5)^2)/(22^2))+18*SIN(2*PI()*(A9)/70))+Inputs!$C$28*EXP(-(((A9)-Inputs!$C$29)^2)/(2*Inputs!$C$31^2))*EXP(-(((0)-Inputs!$C$30)^2)/(2*Inputs!$C$32^2))+-Inputs!$C$33*EXP(-(((((A9)-Inputs!$C$34)^2)+(((0)-Inputs!$C$35)^2))/(2*Inputs!$C$36^2)))+Inputs!$C$37*(0.55*SIN(2*PI()*(A9)/Inputs!$C$39)+0.35*COS(2*PI()*(0)/Inputs!$C$40)+0.2*SIN(2*PI()*((A9)+(0))/(0.5*(Inputs!$C$39+Inputs!$C$40))))+Inputs!$C$38*SIN(2*PI()*(A9)/Inputs!$C$39)*SIN(2*PI()*(0)/Inputs!$C$40)+-Inputs!$C$41*EXP(-(((0)-Inputs!$C$43)^2)/(2*Inputs!$C$44^2))*EXP(-(((A9)-Inputs!$C$42)^2)/(2*Inputs!$C$45^2))+Inputs!$C$48*(0.7*(0.45*SIN(2*PI()*(((A9)/Inputs!$C$49)+Inputs!$C$47*0.137))+0.35*COS(2*PI()*(((0)/Inputs!$C$50)+Inputs!$C$47*0.173))+0.2*SIN(2*PI()*(((A9)+(0))/(0.5*(Inputs!$C$49+Inputs!$C$50))+Inputs!$C$47*0.097)))+0.3*(2*((SIN(((A9)*12.9898+(0)*78.233+Inputs!$C$47*37.719))*43758.5453)-INT((SIN(((A9)*12.9898+(0)*78.233+Inputs!$C$47*37.719))*43758.5453)))-1))) | Y9: =IF(OR(Inputs!$C$27=TRUE,Inputs!$C$27="TRUE",Inputs!$C$27=1),1,0)*(Inputs!$C$51*(115*EXP(-(((Inputs!$C$6)-25)^2)/(4.5^2))+70*EXP(-(((Inputs!$C$6)+38)^2)/(7^2))*(0.55+0.45*SIN(2*PI()*(A9)/45))+24*SIN(2*PI()*(Inputs!$C$6)/9+(A9)/18)*EXP(-(((Inputs!$C$6)+5)^2)/(22^2))+18*SIN(2*PI()*(A9)/70))+Inputs!$C$28*EXP(-(((A9)-Inputs!$C$29)^2)/(2*Inputs!$C$31^2))*EXP(-(((Inputs!$C$6)-Inputs!$C$30)^2)/(2*Inputs!$C$32^2))+-Inputs!$C$33*EXP(-(((((A9)-Inputs!$C$34)^2)+(((Inputs!$C$6)-Inputs!$C$35)^2))/(2*Inputs!$C$36^2)))+Inputs!$C$37*(0.55*SIN(2*PI()*(A9)/Inputs!$C$39)+0.35*COS(2*PI()*(Inputs!$C$6)/Inputs!$C$40)+0.2*SIN(2*PI()*((A9)+(Inputs!$C$6))/(0.5*(Inputs!$C$39+Inputs!$C$40))))+Inputs!$C$38*SIN(2*PI()*(A9)/Inputs!$C$39)*SIN(2*PI()*(Inputs!$C$6)/Inputs!$C$40)+-Inputs!$C$41*EXP(-(((Inputs!$C$6)-Inputs!$C$43)^2)/(2*Inputs!$C$44^2))*EXP(-(((A9)-Inputs!$C$42)^2)/(2*Inputs!$C$45^2))+Inputs!$C$48*(0.7*(0.45*SIN(2*PI()*(((A9)/Inputs!$C$49)+Inputs!$C$47*0.137))+0.35*COS(2*PI()*(((Inputs!$C$6)/Inputs!$C$50)+Inputs!$C$47*0.173))+0.2*SIN(2*PI()*(((A9)+(Inputs!$C$6))/(0.5*(Inputs!$C$49+Inputs!$C$50))+Inputs!$C$47*0.097)))+0.3*(2*((SIN(((A9)*12.9898+(Inputs!$C$6)*78.233+Inputs!$C$47*37.719))*43758.5453)-INT((SIN(((A9)*12.9898+(Inputs!$C$6)*78.233+Inputs!$C$47*37.719))*43758.5453)))-1))) | Z9: =B9-X9/1000 | AA9: =SQRT((Inputs!$C$52+B9)^2+(Inputs!$C$52+Y9/1000)^2-2*(Inputs!$C$52+B9)*(Inputs!$C$52+Y9/1000)*COS(SQRT(A9^2+Inputs!$C$6^2)/Inputs!$C$52)) | AB9: =(AA9-Z9)*1000 | AC9: =AB9/Inputs!$C$12 | AD9: =2*AB9/Inputs!$C$21*1000000 | AE9: =DEGREES(ATAN(H9/(B9-Y9/1000))) | AF9: =DEGREES((2*PI()/Inputs!$C$13)*Inputs!$C$15*SIN(RADIANS(AE9))) | AG9: =(Z9/AA9)^4 | AH9: =10*LOG10(AG9) | AI9: =AC9-F9 | AJ9: =AD9-G9 | AK9: =Y9-X9 | AL9: =1000*(AA10-AA8)/(A10-A8)*Inputs!$C$11 | AM9: =-2*AL9/Inputs!$C$13 | AN9: =-2*AL9/Inputs!$C$14 | AO9: =ABS(AM9) | AP9: =ABS(AN9) | AQ9: =IF(OR(Inputs!$C$27=TRUE,Inputs!$C$27="TRUE",Inputs!$C$27=1),Inputs!$C$46/Inputs!$C$12,0) | AR9: =AC9-AQ9 | AS9: =AC9+AQ9
A10: =Inputs!$C$7+8*(Inputs!$C$8-Inputs!$C$7)/240 | B10: =Inputs!$C$5+Inputs!$C$9*(A10/Inputs!$C$10)^2 | C10: =B10 | D10: =SQRT((Inputs!$C$52+B10)^2+Inputs!$C$52^2-2*(Inputs!$C$52+B10)*Inputs!$C$52*COS(SQRT(A10^2+Inputs!$C$6^2)/Inputs!$C$52)) | E10: =(D10-C10)*1000 | F10: =E10/Inputs!$C$12 | G10: =2*E10/Inputs!$C$21*1000000 | H10: =SQRT(A10^2+Inputs!$C$6^2) | I10: =DEGREES(ATAN(H10/B10)) | J10: =DEGREES((2*PI()/Inputs!$C$13)*Inputs!$C$15*SIN(RADIANS(I10))) | K10: =(C10/D10)^4 | L10: =10*LOG10(K10) | M10: =2*(Inputs!$C$9/(Inputs!$C$10^2))*A10 | N10: =M10*Inputs!$C$11 | O10: =1000*(D11-D9)/(A11-A9)*Inputs!$C$11 | P10: =-2*O10/Inputs!$C$13 | Q10: =-2*O10/Inputs!$C$14 | R10: =F10-Inputs!$C$16/2 | S10: =F10+Inputs!$C$16/2 | T10: =F10-Inputs!$C$17/2 | U10: =F10+Inputs!$C$17/2 | V10: =ABS(P10) | W10: =ABS(Q10) | X10: =IF(OR(Inputs!$C$27=TRUE,Inputs!$C$27="TRUE",Inputs!$C$27=1),1,0)*(Inputs!$C$51*(115*EXP(-(((0)-25)^2)/(4.5^2))+70*EXP(-(((0)+38)^2)/(7^2))*(0.55+0.45*SIN(2*PI()*(A10)/45))+24*SIN(2*PI()*(0)/9+(A10)/18)*EXP(-(((0)+5)^2)/(22^2))+18*SIN(2*PI()*(A10)/70))+Inputs!$C$28*EXP(-(((A10)-Inputs!$C$29)^2)/(2*Inputs!$C$31^2))*EXP(-(((0)-Inputs!$C$30)^2)/(2*Inputs!$C$32^2))+-Inputs!$C$33*EXP(-(((((A10)-Inputs!$C$34)^2)+(((0)-Inputs!$C$35)^2))/(2*Inputs!$C$36^2)))+Inputs!$C$37*(0.55*SIN(2*PI()*(A10)/Inputs!$C$39)+0.35*COS(2*PI()*(0)/Inputs!$C$40)+0.2*SIN(2*PI()*((A10)+(0))/(0.5*(Inputs!$C$39+Inputs!$C$40))))+Inputs!$C$38*SIN(2*PI()*(A10)/Inputs!$C$39)*SIN(2*PI()*(0)/Inputs!$C$40)+-Inputs!$C$41*EXP(-(((0)-Inputs!$C$43)^2)/(2*Inputs!$C$44^2))*EXP(-(((A10)-Inputs!$C$42)^2)/(2*Inputs!$C$45^2))+Inputs!$C$48*(0.7*(0.45*SIN(2*PI()*(((A10)/Inputs!$C$49)+Inputs!$C$47*0.137))+0.35*COS(2*PI()*(((0)/Inputs!$C$50)+Inputs!$C$47*0.173))+0.2*SIN(2*PI()*(((A10)+(0))/(0.5*(Inputs!$C$49+Inputs!$C$50))+Inputs!$C$47*0.097)))+0.3*(2*((SIN(((A10)*12.9898+(0)*78.233+Inputs!$C$47*37.719))*43758.5453)-INT((SIN(((A10)*12.9898+(0)*78.233+Inputs!$C$47*37.719))*43758.5453)))-1))) | Y10: =IF(OR(Inputs!$C$27=TRUE,Inputs!$C$27="TRUE",Inputs!$C$27=1),1,0)*(Inputs!$C$51*(115*EXP(-(((Inputs!$C$6)-25)^2)/(4.5^2))+70*EXP(-(((Inputs!$C$6)+38)^2)/(7^2))*(0.55+0.45*SIN(2*PI()*(A10)/45))+24*SIN(2*PI()*(Inputs!$C$6)/9+(A10)/18)*EXP(-(((Inputs!$C$6)+5)^2)/(22^2))+18*SIN(2*PI()*(A10)/70))+Inputs!$C$28*EXP(-(((A10)-Inputs!$C$29)^2)/(2*Inputs!$C$31^2))*EXP(-(((Inputs!$C$6)-Inputs!$C$30)^2)/(2*Inputs!$C$32^2))+-Inputs!$C$33*EXP(-(((((A10)-Inputs!$C$34)^2)+(((Inputs!$C$6)-Inputs!$C$35)^2))/(2*Inputs!$C$36^2)))+Inputs!$C$37*(0.55*SIN(2*PI()*(A10)/Inputs!$C$39)+0.35*COS(2*PI()*(Inputs!$C$6)/Inputs!$C$40)+0.2*SIN(2*PI()*((A10)+(Inputs!$C$6))/(0.5*(Inputs!$C$39+Inputs!$C$40))))+Inputs!$C$38*SIN(2*PI()*(A10)/Inputs!$C$39)*SIN(2*PI()*(Inputs!$C$6)/Inputs!$C$40)+-Inputs!$C$41*EXP(-(((Inputs!$C$6)-Inputs!$C$43)^2)/(2*Inputs!$C$44^2))*EXP(-(((A10)-Inputs!$C$42)^2)/(2*Inputs!$C$45^2))+Inputs!$C$48*(0.7*(0.45*SIN(2*PI()*(((A10)/Inputs!$C$49)+Inputs!$C$47*0.137))+0.35*COS(2*PI()*(((Inputs!$C$6)/Inputs!$C$50)+Inputs!$C$47*0.173))+0.2*SIN(2*PI()*(((A10)+(Inputs!$C$6))/(0.5*(Inputs!$C$49+Inputs!$C$50))+Inputs!$C$47*0.097)))+0.3*(2*((SIN(((A10)*12.9898+(Inputs!$C$6)*78.233+Inputs!$C$47*37.719))*43758.5453)-INT((SIN(((A10)*12.9898+(Inputs!$C$6)*78.233+Inputs!$C$47*37.719))*43758.5453)))-1))) | Z10: =B10-X10/1000 | AA10: =SQRT((Inputs!$C$52+B10)^2+(Inputs!$C$52+Y10/1000)^2-2*(Inputs!$C$52+B10)*(Inputs!$C$52+Y10/1000)*COS(SQRT(A10^2+Inputs!$C$6^2)/Inputs!$C$52)) | AB10: =(AA10-Z10)*1000 | AC10: =AB10/Inputs!$C$12 | AD10: =2*AB10/Inputs!$C$21*1000000 | AE10: =DEGREES(ATAN(H10/(B10-Y10/1000))) | AF10: =DEGREES((2*PI()/Inputs!$C$13)*Inputs!$C$15*SIN(RADIANS(AE10))) | AG10: =(Z10/AA10)^4 | AH10: =10*LOG10(AG10) | AI10: =AC10-F10 | AJ10: =AD10-G10 | AK10: =Y10-X10 | AL10: =1000*(AA11-AA9)/(A11-A9)*Inputs!$C$11 | AM10: =-2*AL10/Inputs!$C$13 | AN10: =-2*AL10/Inputs!$C$14 | AO10: =ABS(AM10) | AP10: =ABS(AN10) | AQ10: =IF(OR(Inputs!$C$27=TRUE,Inputs!$C$27="TRUE",Inputs!$C$27=1),Inputs!$C$46/Inputs!$C$12,0) | AR10: =AC10-AQ10 | AS10: =AC10+AQ10
A11: =Inputs!$C$7+9*(Inputs!$C$8-Inputs!$C$7)/240 | B11: =Inputs!$C$5+Inputs!$C$9*(A11/Inputs!$C$10)^2 | C11: =B11 | D11: =SQRT((Inputs!$C$52+B11)^2+Inputs!$C$52^2-2*(Inputs!$C$52+B11)*Inputs!$C$52*COS(SQRT(A11^2+Inputs!$C$6^2)/Inputs!$C$52)) | E11: =(D11-C11)*1000 | F11: =E11/Inputs!$C$12 | G11: =2*E11/Inputs!$C$21*1000000 | H11: =SQRT(A11^2+Inputs!$C$6^2) | I11: =DEGREES(ATAN(H11/B11)) | J11: =DEGREES((2*PI()/Inputs!$C$13)*Inputs!$C$15*SIN(RADIANS(I11))) | K11: =(C11/D11)^4 | L11: =10*LOG10(K11) | M11: =2*(Inputs!$C$9/(Inputs!$C$10^2))*A11 | N11: =M11*Inputs!$C$11 | O11: =1000*(D12-D10)/(A12-A10)*Inputs!$C$11 | P11: =-2*O11/Inputs!$C$13 | Q11: =-2*O11/Inputs!$C$14 | R11: =F11-Inputs!$C$16/2 | S11: =F11+Inputs!$C$16/2 | T11: =F11-Inputs!$C$17/2 | U11: =F11+Inputs!$C$17/2 | V11: =ABS(P11) | W11: =ABS(Q11) | X11: =IF(OR(Inputs!$C$27=TRUE,Inputs!$C$27="TRUE",Inputs!$C$27=1),1,0)*(Inputs!$C$51*(115*EXP(-(((0)-25)^2)/(4.5^2))+70*EXP(-(((0)+38)^2)/(7^2))*(0.55+0.45*SIN(2*PI()*(A11)/45))+24*SIN(2*PI()*(0)/9+(A11)/18)*EXP(-(((0)+5)^2)/(22^2))+18*SIN(2*PI()*(A11)/70))+Inputs!$C$28*EXP(-(((A11)-Inputs!$C$29)^2)/(2*Inputs!$C$31^2))*EXP(-(((0)-Inputs!$C$30)^2)/(2*Inputs!$C$32^2))+-Inputs!$C$33*EXP(-(((((A11)-Inputs!$C$34)^2)+(((0)-Inputs!$C$35)^2))/(2*Inputs!$C$36^2)))+Inputs!$C$37*(0.55*SIN(2*PI()*(A11)/Inputs!$C$39)+0.35*COS(2*PI()*(0)/Inputs!$C$40)+0.2*SIN(2*PI()*((A11)+(0))/(0.5*(Inputs!$C$39+Inputs!$C$40))))+Inputs!$C$38*SIN(2*PI()*(A11)/Inputs!$C$39)*SIN(2*PI()*(0)/Inputs!$C$40)+-Inputs!$C$41*EXP(-(((0)-Inputs!$C$43)^2)/(2*Inputs!$C$44^2))*EXP(-(((A11)-Inputs!$C$42)^2)/(2*Inputs!$C$45^2))+Inputs!$C$48*(0.7*(0.45*SIN(2*PI()*(((A11)/Inputs!$C$49)+Inputs!$C$47*0.137))+0.35*COS(2*PI()*(((0)/Inputs!$C$50)+Inputs!$C$47*0.173))+0.2*SIN(2*PI()*(((A11)+(0))/(0.5*(Inputs!$C$49+Inputs!$C$50))+Inputs!$C$47*0.097)))+0.3*(2*((SIN(((A11)*12.9898+(0)*78.233+Inputs!$C$47*37.719))*43758.5453)-INT((SIN(((A11)*12.9898+(0)*78.233+Inputs!$C$47*37.719))*43758.5453)))-1))) | Y11: =IF(OR(Inputs!$C$27=TRUE,Inputs!$C$27="TRUE",Inputs!$C$27=1),1,0)*(Inputs!$C$51*(115*EXP(-(((Inputs!$C$6)-25)^2)/(4.5^2))+70*EXP(-(((Inputs!$C$6)+38)^2)/(7^2))*(0.55+0.45*SIN(2*PI()*(A11)/45))+24*SIN(2*PI()*(Inputs!$C$6)/9+(A11)/18)*EXP(-(((Inputs!$C$6)+5)^2)/(22^2))+18*SIN(2*PI()*(A11)/70))+Inputs!$C$28*EXP(-(((A11)-Inputs!$C$29)^2)/(2*Inputs!$C$31^2))*EXP(-(((Inputs!$C$6)-Inputs!$C$30)^2)/(2*Inputs!$C$32^2))+-Inputs!$C$33*EXP(-(((((A11)-Inputs!$C$34)^2)+(((Inputs!$C$6)-Inputs!$C$35)^2))/(2*Inputs!$C$36^2)))+Inputs!$C$37*(0.55*SIN(2*PI()*(A11)/Inputs!$C$39)+0.35*COS(2*PI()*(Inputs!$C$6)/Inputs!$C$40)+0.2*SIN(2*PI()*((A11)+(Inputs!$C$6))/(0.5*(Inputs!$C$39+Inputs!$C$40))))+Inputs!$C$38*SIN(2*PI()*(A11)/Inputs!$C$39)*SIN(2*PI()*(Inputs!$C$6)/Inputs!$C$40)+-Inputs!$C$41*EXP(-(((Inputs!$C$6)-Inputs!$C$43)^2)/(2*Inputs!$C$44^2))*EXP(-(((A11)-Inputs!$C$42)^2)/(2*Inputs!$C$45^2))+Inputs!$C$48*(0.7*(0.45*SIN(2*PI()*(((A11)/Inputs!$C$49)+Inputs!$C$47*0.137))+0.35*COS(2*PI()*(((Inputs!$C$6)/Inputs!$C$50)+Inputs!$C$47*0.173))+0.2*SIN(2*PI()*(((A11)+(Inputs!$C$6))/(0.5*(Inputs!$C$49+Inputs!$C$50))+Inputs!$C$47*0.097)))+0.3*(2*((SIN(((A11)*12.9898+(Inputs!$C$6)*78.233+Inputs!$C$47*37.719))*43758.5453)-INT((SIN(((A11)*12.9898+(Inputs!$C$6)*78.233+Inputs!$C$47*37.719))*43758.5453)))-1))) | Z11: =B11-X11/1000 | AA11: =SQRT((Inputs!$C$52+B11)^2+(Inputs!$C$52+Y11/1000)^2-2*(Inputs!$C$52+B11)*(Inputs!$C$52+Y11/1000)*COS(SQRT(A11^2+Inputs!$C$6^2)/Inputs!$C$52)) | AB11: =(AA11-Z11)*1000 | AC11: =AB11/Inputs!$C$12 | AD11: =2*AB11/Inputs!$C$21*1000000 | AE11: =DEGREES(ATAN(H11/(B11-Y11/1000))) | AF11: =DEGREES((2*PI()/Inputs!$C$13)*Inputs!$C$15*SIN(RADIANS(AE11))) | AG11: =(Z11/AA11)^4 | AH11: =10*LOG10(AG11) | AI11: =AC11-F11 | AJ11: =AD11-G11 | AK11: =Y11-X11 | AL11: =1000*(AA12-AA10)/(A12-A10)*Inputs!$C$11 | AM11: =-2*AL11/Inputs!$C$13 | AN11: =-2*AL11/Inputs!$C$14 | AO11: =ABS(AM11) | AP11: =ABS(AN11) | AQ11: =IF(OR(Inputs!$C$27=TRUE,Inputs!$C$27="TRUE",Inputs!$C$27=1),Inputs!$C$46/Inputs!$C$12,0) | AR11: =AC11-AQ11 | AS11: =AC11+AQ11
A12: =Inputs!$C$7+10*(Inputs!$C$8-Inputs!$C$7)/240 | B12: =Inputs!$C$5+Inputs!$C$9*(A12/Inputs!$C$10)^2 | C12: =B12 | D12: =SQRT((Inputs!$C$52+B12)^2+Inputs!$C$52^2-2*(Inputs!$C$52+B12)*Inputs!$C$52*COS(SQRT(A12^2+Inputs!$C$6^2)/Inputs!$C$52)) | E12: =(D12-C12)*1000 | F12: =E12/Inputs!$C$12 | G12: =2*E12/Inputs!$C$21*1000000 | H12: =SQRT(A12^2+Inputs!$C$6^2) | I12: =DEGREES(ATAN(H12/B12)) | J12: =DEGREES((2*PI()/Inputs!$C$13)*Inputs!$C$15*SIN(RADIANS(I12))) | K12: =(C12/D12)^4 | L12: =10*LOG10(K12) | M12: =2*(Inputs!$C$9/(Inputs!$C$10^2))*A12 | N12: =M12*Inputs!$C$11 | O12: =1000*(D13-D11)/(A13-A11)*Inputs!$C$11 | P12: =-2*O12/Inputs!$C$13 | Q12: =-2*O12/Inputs!$C$14 | R12: =F12-Inputs!$C$16/2 | S12: =F12+Inputs!$C$16/2 | T12: =F12-Inputs!$C$17/2 | U12: =F12+Inputs!$C$17/2 | V12: =ABS(P12) | W12: =ABS(Q12) | X12: =IF(OR(Inputs!$C$27=TRUE,Inputs!$C$27="TRUE",Inputs!$C$27=1),1,0)*(Inputs!$C$51*(115*EXP(-(((0)-25)^2)/(4.5^2))+70*EXP(-(((0)+38)^2)/(7^2))*(0.55+0.45*SIN(2*PI()*(A12)/45))+24*SIN(2*PI()*(0)/9+(A12)/18)*EXP(-(((0)+5)^2)/(22^2))+18*SIN(2*PI()*(A12)/70))+Inputs!$C$28*EXP(-(((A12)-Inputs!$C$29)^2)/(2*Inputs!$C$31^2))*EXP(-(((0)-Inputs!$C$30)^2)/(2*Inputs!$C$32^2))+-Inputs!$C$33*EXP(-(((((A12)-Inputs!$C$34)^2)+(((0)-Inputs!$C$35)^2))/(2*Inputs!$C$36^2)))+Inputs!$C$37*(0.55*SIN(2*PI()*(A12)/Inputs!$C$39)+0.35*COS(2*PI()*(0)/Inputs!$C$40)+0.2*SIN(2*PI()*((A12)+(0))/(0.5*(Inputs!$C$39+Inputs!$C$40))))+Inputs!$C$38*SIN(2*PI()*(A12)/Inputs!$C$39)*SIN(2*PI()*(0)/Inputs!$C$40)+-Inputs!$C$41*EXP(-(((0)-Inputs!$C$43)^2)/(2*Inputs!$C$44^2))*EXP(-(((A12)-Inputs!$C$42)^2)/(2*Inputs!$C$45^2))+Inputs!$C$48*(0.7*(0.45*SIN(2*PI()*(((A12)/Inputs!$C$49)+Inputs!$C$47*0.137))+0.35*COS(2*PI()*(((0)/Inputs!$C$50)+Inputs!$C$47*0.173))+0.2*SIN(2*PI()*(((A12)+(0))/(0.5*(Inputs!$C$49+Inputs!$C$50))+Inputs!$C$47*0.097)))+0.3*(2*((SIN(((A12)*12.9898+(0)*78.233+Inputs!$C$47*37.719))*43758.5453)-INT((SIN(((A12)*12.9898+(0)*78.233+Inputs!$C$47*37.719))*43758.5453)))-1))) | Y12: =IF(OR(Inputs!$C$27=TRUE,Inputs!$C$27="TRUE",Inputs!$C$27=1),1,0)*(Inputs!$C$51*(115*EXP(-(((Inputs!$C$6)-25)^2)/(4.5^2))+70*EXP(-(((Inputs!$C$6)+38)^2)/(7^2))*(0.55+0.45*SIN(2*PI()*(A12)/45))+24*SIN(2*PI()*(Inputs!$C$6)/9+(A12)/18)*EXP(-(((Inputs!$C$6)+5)^2)/(22^2))+18*SIN(2*PI()*(A12)/70))+Inputs!$C$28*EXP(-(((A12)-Inputs!$C$29)^2)/(2*Inputs!$C$31^2))*EXP(-(((Inputs!$C$6)-Inputs!$C$30)^2)/(2*Inputs!$C$32^2))+-Inputs!$C$33*EXP(-(((((A12)-Inputs!$C$34)^2)+(((Inputs!$C$6)-Inputs!$C$35)^2))/(2*Inputs!$C$36^2)))+Inputs!$C$37*(0.55*SIN(2*PI()*(A12)/Inputs!$C$39)+0.35*COS(2*PI()*(Inputs!$C$6)/Inputs!$C$40)+0.2*SIN(2*PI()*((A12)+(Inputs!$C$6))/(0.5*(Inputs!$C$39+Inputs!$C$40))))+Inputs!$C$38*SIN(2*PI()*(A12)/Inputs!$C$39)*SIN(2*PI()*(Inputs!$C$6)/Inputs!$C$40)+-Inputs!$C$41*EXP(-(((Inputs!$C$6)-Inputs!$C$43)^2)/(2*Inputs!$C$44^2))*EXP(-(((A12)-Inputs!$C$42)^2)/(2*Inputs!$C$45^2))+Inputs!$C$48*(0.7*(0.45*SIN(2*PI()*(((A12)/Inputs!$C$49)+Inputs!$C$47*0.137))+0.35*COS(2*PI()*(((Inputs!$C$6)/Inputs!$C$50)+Inputs!$C$47*0.173))+0.2*SIN(2*PI()*(((A12)+(Inputs!$C$6))/(0.5*(Inputs!$C$49+Inputs!$C$50))+Inputs!$C$47*0.097)))+0.3*(2*((SIN(((A12)*12.9898+(Inputs!$C$6)*78.233+Inputs!$C$47*37.719))*43758.5453)-INT((SIN(((A12)*12.9898+(Inputs!$C$6)*78.233+Inputs!$C$47*37.719))*43758.5453)))-1))) | Z12: =B12-X12/1000 | AA12: =SQRT((Inputs!$C$52+B12)^2+(Inputs!$C$52+Y12/1000)^2-2*(Inputs!$C$52+B12)*(Inputs!$C$52+Y12/1000)*COS(SQRT(A12^2+Inputs!$C$6^2)/Inputs!$C$52)) | AB12: =(AA12-Z12)*1000 | AC12: =AB12/Inputs!$C$12 | AD12: =2*AB12/Inputs!$C$21*1000000 | AE12: =DEGREES(ATAN(H12/(B12-Y12/1000))) | AF12: =DEGREES((2*PI()/Inputs!$C$13)*Inputs!$C$15*SIN(RADIANS(AE12))) | AG12: =(Z12/AA12)^4 | AH12: =10*LOG10(AG12) | AI12: =AC12-F12 | AJ12: =AD12-G12 | AK12: =Y12-X12 | AL12: =1000*(AA13-AA11)/(A13-A11)*Inputs!$C$11 | AM12: =-2*AL12/Inputs!$C$13 | AN12: =-2*AL12/Inputs!$C$14 | AO12: =ABS(AM12) | AP12: =ABS(AN12) | AQ12: =IF(OR(Inputs!$C$27=TRUE,Inputs!$C$27="TRUE",Inputs!$C$27=1),Inputs!$C$46/Inputs!$C$12,0) | AR12: =AC12-AQ12 | AS12: =AC12+AQ12
A13: =Inputs!$C$7+11*(Inputs!$C$8-Inputs!$C$7)/240 | B13: =Inputs!$C$5+Inputs!$C$9*(A13/Inputs!$C$10)^2 | C13: =B13 | D13: =SQRT((Inputs!$C$52+B13)^2+Inputs!$C$52^2-2*(Inputs!$C$52+B13)*Inputs!$C$52*COS(SQRT(A13^2+Inputs!$C$6^2)/Inputs!$C$52)) | E13: =(D13-C13)*1000 | F13: =E13/Inputs!$C$12 | G13: =2*E13/Inputs!$C$21*1000000 | H13: =SQRT(A13^2+Inputs!$C$6^2) | I13: =DEGREES(ATAN(H13/B13)) | J13: =DEGREES((2*PI()/Inputs!$C$13)*Inputs!$C$15*SIN(RADIANS(I13))) | K13: =(C13/D13)^4 | L13: =10*LOG10(K13) | M13: =2*(Inputs!$C$9/(Inputs!$C$10^2))*A13 | N13: =M13*Inputs!$C$11 | O13: =1000*(D14-D12)/(A14-A12)*Inputs!$C$11 | P13: =-2*O13/Inputs!$C$13 | Q13: =-2*O13/Inputs!$C$14 | R13: =F13-Inputs!$C$16/2 | S13: =F13+Inputs!$C$16/2 | T13: =F13-Inputs!$C$17/2 | U13: =F13+Inputs!$C$17/2 | V13: =ABS(P13) | W13: =ABS(Q13) | X13: =IF(OR(Inputs!$C$27=TRUE,Inputs!$C$27="TRUE",Inputs!$C$27=1),1,0)*(Inputs!$C$51*(115*EXP(-(((0)-25)^2)/(4.5^2))+70*EXP(-(((0)+38)^2)/(7^2))*(0.55+0.45*SIN(2*PI()*(A13)/45))+24*SIN(2*PI()*(0)/9+(A13)/18)*EXP(-(((0)+5)^2)/(22^2))+18*SIN(2*PI()*(A13)/70))+Inputs!$C$28*EXP(-(((A13)-Inputs!$C$29)^2)/(2*Inputs!$C$31^2))*EXP(-(((0)-Inputs!$C$30)^2)/(2*Inputs!$C$32^2))+-Inputs!$C$33*EXP(-(((((A13)-Inputs!$C$34)^2)+(((0)-Inputs!$C$35)^2))/(2*Inputs!$C$36^2)))+Inputs!$C$37*(0.55*SIN(2*PI()*(A13)/Inputs!$C$39)+0.35*COS(2*PI()*(0)/Inputs!$C$40)+0.2*SIN(2*PI()*((A13)+(0))/(0.5*(Inputs!$C$39+Inputs!$C$40))))+Inputs!$C$38*SIN(2*PI()*(A13)/Inputs!$C$39)*SIN(2*PI()*(0)/Inputs!$C$40)+-Inputs!$C$41*EXP(-(((0)-Inputs!$C$43)^2)/(2*Inputs!$C$44^2))*EXP(-(((A13)-Inputs!$C$42)^2)/(2*Inputs!$C$45^2))+Inputs!$C$48*(0.7*(0.45*SIN(2*PI()*(((A13)/Inputs!$C$49)+Inputs!$C$47*0.137))+0.35*COS(2*PI()*(((0)/Inputs!$C$50)+Inputs!$C$47*0.173))+0.2*SIN(2*PI()*(((A13)+(0))/(0.5*(Inputs!$C$49+Inputs!$C$50))+Inputs!$C$47*0.097)))+0.3*(2*((SIN(((A13)*12.9898+(0)*78.233+Inputs!$C$47*37.719))*43758.5453)-INT((SIN(((A13)*12.9898+(0)*78.233+Inputs!$C$47*37.719))*43758.5453)))-1))) | Y13: =IF(OR(Inputs!$C$27=TRUE,Inputs!$C$27="TRUE",Inputs!$C$27=1),1,0)*(Inputs!$C$51*(115*EXP(-(((Inputs!$C$6)-25)^2)/(4.5^2))+70*EXP(-(((Inputs!$C$6)+38)^2)/(7^2))*(0.55+0.45*SIN(2*PI()*(A13)/45))+24*SIN(2*PI()*(Inputs!$C$6)/9+(A13)/18)*EXP(-(((Inputs!$C$6)+5)^2)/(22^2))+18*SIN(2*PI()*(A13)/70))+Inputs!$C$28*EXP(-(((A13)-Inputs!$C$29)^2)/(2*Inputs!$C$31^2))*EXP(-(((Inputs!$C$6)-Inputs!$C$30)^2)/(2*Inputs!$C$32^2))+-Inputs!$C$33*EXP(-(((((A13)-Inputs!$C$34)^2)+(((Inputs!$C$6)-Inputs!$C$35)^2))/(2*Inputs!$C$36^2)))+Inputs!$C$37*(0.55*SIN(2*PI()*(A13)/Inputs!$C$39)+0.35*COS(2*PI()*(Inputs!$C$6)/Inputs!$C$40)+0.2*SIN(2*PI()*((A13)+(Inputs!$C$6))/(0.5*(Inputs!$C$39+Inputs!$C$40))))+Inputs!$C$38*SIN(2*PI()*(A13)/Inputs!$C$39)*SIN(2*PI()*(Inputs!$C$6)/Inputs!$C$40)+-Inputs!$C$41*EXP(-(((Inputs!$C$6)-Inputs!$C$43)^2)/(2*Inputs!$C$44^2))*EXP(-(((A13)-Inputs!$C$42)^2)/(2*Inputs!$C$45^2))+Inputs!$C$48*(0.7*(0.45*SIN(2*PI()*(((A13)/Inputs!$C$49)+Inputs!$C$47*0.137))+0.35*COS(2*PI()*(((Inputs!$C$6)/Inputs!$C$50)+Inputs!$C$47*0.173))+0.2*SIN(2*PI()*(((A13)+(Inputs!$C$6))/(0.5*(Inputs!$C$49+Inputs!$C$50))+Inputs!$C$47*0.097)))+0.3*(2*((SIN(((A13)*12.9898+(Inputs!$C$6)*78.233+Inputs!$C$47*37.719))*43758.5453)-INT((SIN(((A13)*12.9898+(Inputs!$C$6)*78.233+Inputs!$C$47*37.719))*43758.5453)))-1))) | Z13: =B13-X13/1000 | AA13: =SQRT((Inputs!$C$52+B13)^2+(Inputs!$C$52+Y13/1000)^2-2*(Inputs!$C$52+B13)*(Inputs!$C$52+Y13/1000)*COS(SQRT(A13^2+Inputs!$C$6^2)/Inputs!$C$52)) | AB13: =(AA13-Z13)*1000 | AC13: =AB13/Inputs!$C$12 | AD13: =2*AB13/Inputs!$C$21*1000000 | AE13: =DEGREES(ATAN(H13/(B13-Y13/1000))) | AF13: =DEGREES((2*PI()/Inputs!$C$13)*Inputs!$C$15*SIN(RADIANS(AE13))) | AG13: =(Z13/AA13)^4 | AH13: =10*LOG10(AG13) | AI13: =AC13-F13 | AJ13: =AD13-G13 | AK13: =Y13-X13 | AL13: =1000*(AA14-AA12)/(A14-A12)*Inputs!$C$11 | AM13: =-2*AL13/Inputs!$C$13 | AN13: =-2*AL13/Inputs!$C$14 | AO13: =ABS(AM13) | AP13: =ABS(AN13) | AQ13: =IF(OR(Inputs!$C$27=TRUE,Inputs!$C$27="TRUE",Inputs!$C$27=1),Inputs!$C$46/Inputs!$C$12,0) | AR13: =AC13-AQ13 | AS13: =AC13+AQ13
