Workbook

Sheet Dashboard
A1: Parabolic Motion Radar + Topography Parameter Model
A2: Use Inputs!C27 to apply/remove topography from the main outputs and charts. Inputs!C47 changes the terrain seed. Long-pass scenario ranges use Europa spherical curvature instead of flat Cartesian range. Off-nadir means the side-looking target at Inputs!C6, while nadir means straight below the spacecraft.
A4: Key Output Results
A5: Output | B5: Value | C5: Unit | D5: What it means
A6: Topography toggle | B6: =IF(OR(Inputs!$C$27=TRUE,Inputs!$C$27="TRUE",Inputs!$C$27=1),"Topography ON","Topography OFF") -> Topography ON | D6: Set Inputs!C27 to TRUE to include terrain, or FALSE to return to a flat surface. Change Inputs!C47 to test a new terrain case.
A7: Flat apparent depth at mid-pass | B7: =Model_Data!F122 -> 550.69986 | C7: m | D7: Original flat-surface result.
A8: Topo apparent depth at mid-pass | B8: =Model_Data!AC122 -> 278.83553 | C8: m | D8: Apparent depth after terrain height changes the range geometry.
A9: Depth change from topography | B9: =Model_Data!AI122 -> -271.86433 | C9: m | D9: Topo apparent depth minus flat apparent depth.
A10: Topo extra two-way delay | B10: =Model_Data!AD122 -> 3.311139 | C10: us | D10: Two-way delay after topography is included.
A11: Topo VHF interferometric phase | B11: =Model_Data!AF122 -> 22.483083 | C11: deg | D11: VHF phase after topography changes the look geometry.
A12: Max target terrain height | B12: =MAX(Model_Data!Y2:Y242) -> 568.64364 | C12: m | D12: Highest modeled terrain at the side-offset target path.
A13: Min target terrain height | B13: =MIN(Model_Data!Y2:Y242) -> 107.75271 | C13: m | D13: Lowest modeled terrain at the side-offset target path.
A14: Max absolute topo depth change | B14: =MAX(MAX(Model_Data!AI2:AI242),-MIN(Model_Data!AI2:AI242)) -> 302.98887 | C14: m | D14: Largest magnitude of topography-driven apparent-depth change.
A15: Max topo VHF Doppler magnitude | B15: =MAX(Model_Data!AO2:AO242) -> 534.06021 | C15: Hz | D15: Largest VHF Doppler after topography is included.
A16: Simple minimum PRF with topo | B16: =2*B15 -> 1068.1204 | C16: Hz | D16: Twice max topo VHF Doppler, a simple no-alias floor.
A17: Topo depth uncertainty band | B17: =Model_Data!AQ122 -> 42.134831 | C17: m | D17: Representative vertical uncertainty converted to apparent-depth uncertainty.
A19: PRF Choices
A20: PRF (Hz) | B20: Pulse interval (ms) | C20: Along-track spacing (m) | D20: Unambiguous range (km) | E20: Pulses in air at z0 | F20: Status
A21: =PRF_Results!A4 -> 50 | B21: =PRF_Results!B4 -> 20 | C21: =PRF_Results!C4 -> 80 | D21: =PRF_Results!D4 -> 2997.9246 | E21: =PRF_Results!E4 -> 0.13342564 | F21: =PRF_Results!F4 -> Below simple Doppler floor
A22: =PRF_Results!A5 -> 500 | B22: =PRF_Results!B5 -> 2 | C22: =PRF_Results!C5 -> 8 | D22: =PRF_Results!D5 -> 299.79246 | E22: =PRF_Results!E5 -> 1.3342564 | F22: =PRF_Results!F5 -> Below simple Doppler floor
A23: =PRF_Results!A6 -> 3000 | B23: =PRF_Results!B6 -> 0.33333333 | C23: =PRF_Results!C6 -> 1.3333333 | D23: =PRF_Results!D6 -> 49.96541 | E23: =PRF_Results!E6 -> 8.0055383 | F23: =PRF_Results!F6 -> OK for modeled topo VHF Doppler
A25: How to read this model
A26: The chain is: parabolic motion changes z(x); topography adds h(x,y); the radar then turns that real surface pattern into an apparent range/depth shift. The off-nadir target is the side-looking point at y = Inputs!C6; nadir is the straight-down reference. Flat means flat surface, not straight spacecraft motion.
A114: Paper Pass Scenario Comparison
A115: Scenario | B115: Show | C115: z0 (km) | D115: Length (km) | E115: Edge alt (km) | F115: Mid depth (m) | G115: Max VHF (Hz) | H115: PRF floor (Hz) | I115: Basis
A116: =Inputs!G6 -> Current custom inputs | B116: =Inputs!F6 -> TRUE | C116: =Inputs!H6 -> 400 | D116: =Inputs!J6-Inputs!I6 -> 120 | E116: =Inputs!M6 -> 404 | F116: =Scenario_Data!AF122 -> 550.69986 | G116: =MAX(MAX(Scenario_Data!AL2:AL242),-MIN(Scenario_Data!AL2:AL242)) -> 504.93234 | H116: =2*G116 -> 1009.8647 | I116: Current editable
A117: =Inputs!G7 -> Paper low-altitude 800-km pass | B117: =Inputs!F7 -> TRUE | C117: =Inputs!H7 -> 35 | D117: =Inputs!J7-Inputs!I7 -> 800 | E117: =Inputs!M7 -> 400 | F117: =Scenario_Data!AG122 -> 4592.1824 | G117: =MAX(MAX(Scenario_Data!AM2:AM242),-MIN(Scenario_Data!AM2:AM242)) -> 3517.7285 | H117: =2*G117 -> 7035.4571 | I117: 800 km below 400
A118: =Inputs!G8 -> Paper ice-ocean 1600-km pass | B118: =Inputs!F8 -> TRUE | C118: =Inputs!H8 -> 35 | D118: =Inputs!J8-Inputs!I8 -> 1600 | E118: =Inputs!M8 -> 1000 | F118: =Scenario_Data!AH122 -> 4592.1824 | G118: =MAX(MAX(Scenario_Data!AN2:AN242),-MIN(Scenario_Data!AN2:AN242)) -> 4665.3413 | H118: =2*G118 -> 9330.6826 | I118: 1600 km below 1000
A119: =Inputs!G9 -> Paper operating 25-to-1000-km pass | B119: =Inputs!F9 -> TRUE | C119: =Inputs!H9 -> 25 | D119: =Inputs!J9-Inputs!I9 -> 1600 | E119: =Inputs!M9 -> 1000 | F119: =Scenario_Data!AI122 -> 5896.8769 | G119: =MAX(MAX(Scenario_Data!AO2:AO242),-MIN(Scenario_Data!AO2:AO242)) -> 4699.0668 | H119: =2*G119 -> 9398.1336 | I119: 25-1000 km range
A120: Scenario note | B120: Paper numbers are converted into this workbook's simplified parabola so the outcomes can be compared. The paper states altitude ranges and groundtrack requirements, not an exact parabolic spacecraft trajectory.
A122: Quick Graph Guide
A123: Graph | B123: What it is trying to show | F123: How to read the baseline
A124: Apparent depth | B124: Motion and topography change the apparent radar depth relative to the nadir reference. | F124: Grey zero line is a reference, not a plotted terrain/run result.
A125: Surface height | B125: Shows the generated topography used as the reference floor, plus the off-nadir target and nadir terrain heights. The satellite path is curved/parabolic, not flat. | F125: Grey floor now follows the generated topography instead of 0 m; colored lines show target and nadir terrain.
A126: Doppler | B126: Range-rate-driven VHF/HF Doppler, with flat geometry compared against topography-adjusted geometry. | F126: Crossing 0 Hz means the radial motion changes sign near closest approach.
A127: Motion-only / scenarios | B127: The motion-only chart is a radar reading from flat ground. It is not ground height; the curve comes from satellite path and slant-range geometry. | F127: Scenario baselines are grey reference floors; they are intentionally not orange model lines.
A128: Detailed notes | B128: See the Graph_Guide tab for every chart, source range, formula basis, and audit status. | F128: Checks!B4:B23 remains the formula-health checklist.

Sheet Subsurface_Dashboard
A1: Europa Ice Subsurface Interface
A2: Live subsurface outputs from Subsurface_Inputs. The model is synthetic: it helps test what radar might see below icy topography, but it does not prove real Europa layers by itself.
A4: Key Subsurface Results | F4: Realism / Proof Strength
A5: Output | B5: Value | C5: Unit | D5: What it means | F5: Score | G5: Value | H5: Meaning | I5: Improve by
A6: Average bottom depth | B6: =AVERAGE(Subsurface_Live_Data!K2:K242) -> 15077.385 | C6: m | D6: Mean proposed ice-ocean boundary depth. | F6: Concept realism | G6: 0.7 | H6: Good for showing layered-ice radar behavior. | I6: Compare more scenarios.
A7: Boundary uncertainty band | B7: =Subsurface_Inputs!$C$44 -> 1500 | C7: m | D7: Plus/minus range around bottom reflector. | F7: Europa prediction realism | G7: =MIN(0.75,0.25+Subsurface_Materials_Evidence!D14/100*0.45) -> 0.4615 | H7: Plausible, but synthetic and not measured. | I7: Use published constraints or real mission data.
A8: Best ocean echo margin | B8: =MAX(Subsurface_Live_Data!Y2:Y242) -> 11.938394 | C8: dB | D8: How far deep reflector rises above/below threshold. | F8: Proof strength | G8: =MIN(0.6,0.15+Subsurface_Materials_Evidence!D14/100*0.35) -> 0.3145 | H8: Supports a hypothesis; does not prove a real layer. | I8: Validate with radar, thermal, composition, and magnetic/plasma data.
A9: Best lens echo margin | B9: =MAX(Subsurface_Live_Data!X2:X242) -> 21.49132 | C9: dB | D9: How far internal lens return rises above/below threshold.
A10: Likely visible ocean samples | B10: =COUNTIF(Subsurface_Live_Data!V2:V242,"Likely visible") -> 241 | C10: count | D10: Pass samples clearing the detection threshold.
A11: Total evidence support | B11: =Subsurface_Materials_Evidence!D14 -> 47 | C11: % | D11: Radar + thermal + composition + magnetic/plasma support.
A13: Subsurface Graph Guide
A14: Graph | B14: What it shows | C14: How to read it | F14: Graph | G14: What it shows | H14: How to read it
A15: Icy layers | B15: Top surface, internal ice, lens, and possible ocean boundary. | C15: Lower lines are deeper. | F15: Scenarios | G15: Thin / medium / thick ice shell cases. | H15: Different assumptions change boundary depth.
A16: Uncertainty | B16: Mean bottom boundary with lower/upper bounds. | C16: Band width comes from Subsurface_Inputs. | F16: Control | G16: Ocean model compared with no-ocean control. | H16: Positive margin clears threshold.
A17: Radargram timing | B17: Return delay with surface clutter and jitter. | C17: Later delay means deeper reflector. | F17: Detectability | G17: Lens/ocean echo margin above threshold. | H17: Above 0 dB is easier to detect.
A18: Materials | B18: Reflector strength by material/interface. | C18: Less negative is stronger. | F18: Evidence | G18: Radar, thermal, composition, magnetic/plasma support. | H18: Higher percent means stronger support.

Sheet Doppler_Depth_Inversion
A1: Doppler-Angle Depth Inversion
A2: Main view only: charts plus key live results. The detailed row-by-row numbers that feed the graphs were moved to the Doppler_Depth_Data tab.
A5: Main result | F5: Live inputs | K5: Sample depth point | P5: Simplified method
A6: Mean raw slant error | B6: =SUMPRODUCT(ABS(Doppler_Depth_Data!N4:N244))/ROWS(Doppler_Depth_Data!N4:N244) -> 261.4472 | C6: m | F6: VHF wavelength | G6: =Inputs!$C$13 -> 5 | H6: m | K6: x position | L6: =Doppler_Depth_Data!A4 -> -60 | M6: km | P6: 1 | Q6: Doppler shift gives line-of-sight velocity
A7: Mean corrected error | B7: =SUMPRODUCT(ABS(Doppler_Depth_Data!O4:O244))/ROWS(Doppler_Depth_Data!O4:O244) -> 0 | C7: m | F7: Spacecraft speed | G7: =Inputs!$C$11*1000 -> 4000 | H7: m/s | K7: True ocean depth | L7: =Doppler_Depth_Data!H4 -> 14538.343 | M7: m | P7: 2 | Q7: Velocity gives look angle
A8: Max Doppler angle | B8: =MAX(Doppler_Depth_Data!D4:D244) -> 18.319248 | C8: deg | F8: Ice refractive index | G8: =Inputs!$C$12 -> 1.78 | H8: n | K8: Raw slant depth | L8: =Doppler_Depth_Data!L4 -> 15314.482 | M8: m | P8: 3 | Q8: Echo delay gives slant depth
A9: Depth correction status | B9: =IF(SUMPRODUCT(ABS(Doppler_Depth_Data!O4:O244))/ROWS(Doppler_Depth_Data!O4:O244)<0.000001,"PASS","CHECK") -> PASS | F9: Speed of light | G9: =Inputs!$C$21 -> 299792458 | H9: m/s | K9: Corrected ocean depth | L9: =Doppler_Depth_Data!M4 -> 14538.343 | M9: m | P9: 4 | Q9: Angle correction gives actual depth
A11: NASA context source | B11: https://science.nasa.gov/mission/europa-clipper/spacecraft-instruments/

Sheet Doppler_Depth_Data
A1: Detailed Doppler Depth Data - feeds the Doppler dashboard charts
A3: x_km | B3: vhf_doppler_hz | C3: radial_velocity_m_s | D3: doppler_angle_deg | E3: geometry_look_angle_deg | F3: true_upper_depth_m | G3: true_lens_depth_m | H3: true_ocean_depth_m | I3: upper_slant_delay_us | J3: lens_slant_delay_us | K3: ocean_slant_delay_us | L3: raw_ocean_slant_depth_m | M3: doppler_corrected_ocean_depth_m | N3: uncorrected_ocean_error_m | O3: corrected_ocean_error_m | P3: correction_removed_m | Q3: raw_lens_slant_depth_m | R3: doppler_corrected_lens_depth_m | S3: doppler_corrected_upper_depth_m
A4: =Subsurface_Live_Data!A2 -> -60 | B4: =Model_Data!P2 -> 502.89823 | C4: =ABS(B4)*Inputs!$C$13/2 -> 1257.2456 | D4: =DEGREES(ASIN(MIN(1,C4/(Inputs!$C$11*1000)))) -> 18.319248 | E4: =Model_Data!I2 -> 9.1400512 | F4: =Subsurface_Live_Data!F2 -> 946.6775 | G4: =Subsurface_Live_Data!I2 -> 5589.0431 | H4: =Subsurface_Live_Data!K2 -> 14538.343 | I4: =Subsurface_Live_Data!M2/COS(RADIANS(D4)) -> 11.841828 | J4: =Subsurface_Live_Data!N2/COS(RADIANS(D4)) -> 69.912391 | K4: =Subsurface_Live_Data!O2/COS(RADIANS(D4)) -> 181.85767 | L4: =Inputs!$C$21*K4/(2*Inputs!$C$12*1000000) -> 15314.482 | M4: =L4*COS(RADIANS(D4)) -> 14538.343 | N4: =L4-H4 -> 776.1389 | O4: =M4-H4 -> 0 | P4: =N4-O4 -> 776.1389 | Q4: =Inputs!$C$21*J4/(2*Inputs!$C$12*1000000) -> 5887.4178 | R4: =Q4*COS(RADIANS(D4)) -> 5589.0431 | S4: =Inputs!$C$21*I4/(2*Inputs!$C$12*1000000)*COS(RADIANS(D4)) -> 946.6775
A5: =Subsurface_Live_Data!A3 -> -59.5 | B5: =Model_Data!P3 -> 500.86301 | C5: =ABS(B5)*Inputs!$C$13/2 -> 1252.1575 | D5: =DEGREES(ASIN(MIN(1,C5/(Inputs!$C$11*1000)))) -> 18.242494 | E5: =Model_Data!I3 -> 9.077742 | F5: =Subsurface_Live_Data!F3 -> 946.39058 | G5: =Subsurface_Live_Data!I3 -> 5595.348 | H5: =Subsurface_Live_Data!K3 -> 14548.766 | I5: =Subsurface_Live_Data!M3/COS(RADIANS(D5)) -> 11.833001 | J5: =Subsurface_Live_Data!N3/COS(RADIANS(D5)) -> 69.96029 | K5: =Subsurface_Live_Data!O3/COS(RADIANS(D5)) -> 181.90753 | L5: =Inputs!$C$21*K5/(2*Inputs!$C$12*1000000) -> 15318.681 | M5: =L5*COS(RADIANS(D5)) -> 14548.766 | N5: =L5-H5 -> 769.91468 | O5: =M5-H5 -> 0 | P5: =N5-O5 -> 769.91468 | Q5: =Inputs!$C$21*J5/(2*Inputs!$C$12*1000000) -> 5891.4515 | R5: =Q5*COS(RADIANS(D5)) -> 5595.348 | S5: =Inputs!$C$21*I5/(2*Inputs!$C$12*1000000)*COS(RADIANS(D5)) -> 946.39058
A6: =Subsurface_Live_Data!A4 -> -59 | B6: =Model_Data!P4 -> 496.79091 | C6: =ABS(B6)*Inputs!$C$13/2 -> 1241.9773 | D6: =DEGREES(ASIN(MIN(1,C6/(Inputs!$C$11*1000)))) -> 18.089023 | E6: =Model_Data!I4 -> 9.0154589 | F6: =Subsurface_Live_Data!F4 -> 948.30586 | G6: =Subsurface_Live_Data!I4 -> 5600.9131 | H6: =Subsurface_Live_Data!K4 -> 14557.338 | I6: =Subsurface_Live_Data!M4/COS(RADIANS(D6)) -> 11.846532 | J6: =Subsurface_Live_Data!N4/COS(RADIANS(D6)) -> 69.96835 | K6: =Subsurface_Live_Data!O4/COS(RADIANS(D6)) -> 181.8548 | L6: =Inputs!$C$21*K6/(2*Inputs!$C$12*1000000) -> 15314.241 | M6: =L6*COS(RADIANS(D6)) -> 14557.338 | N6: =L6-H6 -> 756.90276 | O6: =M6-H6 -> 0 | P6: =N6-O6 -> 756.90276 | Q6: =Inputs!$C$21*J6/(2*Inputs!$C$12*1000000) -> 5892.1302 | R6: =Q6*COS(RADIANS(D6)) -> 5600.9131 | S6: =Inputs!$C$21*I6/(2*Inputs!$C$12*1000000)*COS(RADIANS(D6)) -> 948.30586
A7: =Subsurface_Live_Data!A5 -> -58.5 | B7: =Model_Data!P5 -> 492.7155 | C7: =ABS(B7)*Inputs!$C$13/2 -> 1231.7887 | D7: =DEGREES(ASIN(MIN(1,C7/(Inputs!$C$11*1000)))) -> 17.935562 | E7: =Model_Data!I5 -> 8.9532041 | F7: =Subsurface_Live_Data!F5 -> 952.78511 | G7: =Subsurface_Live_Data!I5 -> 5605.7282 | H7: =Subsurface_Live_Data!K5 -> 14562.907 | I7: =Subsurface_Live_Data!M5/COS(RADIANS(D7)) -> 11.892127 | J7: =Subsurface_Live_Data!N5/COS(RADIANS(D7)) -> 69.967541 | K7: =Subsurface_Live_Data!O5/COS(RADIANS(D7)) -> 181.766 | L7: =Inputs!$C$21*K7/(2*Inputs!$C$12*1000000) -> 15306.763 | M7: =L7*COS(RADIANS(D7)) -> 14562.907 | N7: =L7-H7 -> 743.85582 | O7: =M7-H7 -> 0 | P7: =N7-O7 -> 743.85582 | Q7: =Inputs!$C$21*J7/(2*Inputs!$C$12*1000000) -> 5892.0621 | R7: =Q7*COS(RADIANS(D7)) -> 5605.7282 | S7: =Inputs!$C$21*I7/(2*Inputs!$C$12*1000000)*COS(RADIANS(D7)) -> 952.78511
A8: =Subsurface_Live_Data!A6 -> -58 | B8: =Model_Data!P6 -> 488.63679 | C8: =ABS(B8)*Inputs!$C$13/2 -> 1221.592 | D8: =DEGREES(ASIN(MIN(1,C8/(Inputs!$C$11*1000)))) -> 17.78211 | E8: =Model_Data!I6 -> 8.8909798 | F8: =Subsurface_Live_Data!F6 -> 957.6515 | G8: =Subsurface_Live_Data!I6 -> 5609.7841 | H8: =Subsurface_Live_Data!K6 -> 14573.126 | I8: =Subsurface_Live_Data!M6/COS(RADIANS(D8)) -> 11.942556 | J8: =Subsurface_Live_Data!N6/COS(RADIANS(D8)) -> 69.95777 | K8: =Subsurface_Live_Data!O6/COS(RADIANS(D8)) -> 181.73665 | L8: =Inputs!$C$21*K8/(2*Inputs!$C$12*1000000) -> 15304.291 | M8: =L8*COS(RADIANS(D8)) -> 14573.126 | N8: =L8-H8 -> 731.16562 | O8: =M8-H8 -> 0 | P8: =N8-O8 -> 731.16562 | Q8: =Inputs!$C$21*J8/(2*Inputs!$C$12*1000000) -> 5891.2392 | R8: =Q8*COS(RADIANS(D8)) -> 5609.7841 | S8: =Inputs!$C$21*I8/(2*Inputs!$C$12*1000000)*COS(RADIANS(D8)) -> 957.6515
A9: =Subsurface_Live_Data!A7 -> -57.5 | B9: =Model_Data!P7 -> 484.55482 | C9: =ABS(B9)*Inputs!$C$13/2 -> 1211.3871 | D9: =DEGREES(ASIN(MIN(1,C9/(Inputs!$C$11*1000)))) -> 17.628667 | E9: =Model_Data!I7 -> 8.8287885 | F9: =Subsurface_Live_Data!F7 -> 965.65068 | G9: =Subsurface_Live_Data!I7 -> 5613.0721 | H9: =Subsurface_Live_Data!K7 -> 14578.335 | I9: =Subsurface_Live_Data!M7/COS(RADIANS(D9)) -> 12.03202 | J9: =Subsurface_Live_Data!N7/COS(RADIANS(D9)) -> 69.938953 | K9: =Subsurface_Live_Data!O7/COS(RADIANS(D9)) -> 181.64625 | L9: =Inputs!$C$21*K9/(2*Inputs!$C$12*1000000) -> 15296.678 | M9: =L9*COS(RADIANS(D9)) -> 14578.335 | N9: =L9-H9 -> 718.34329 | O9: =M9-H9 -> 0 | P9: =N9-O9 -> 718.34329 | Q9: =Inputs!$C$21*J9/(2*Inputs!$C$12*1000000) -> 5889.6547 | R9: =Q9*COS(RADIANS(D9)) -> 5613.0721 | S9: =Inputs!$C$21*I9/(2*Inputs!$C$12*1000000)*COS(RADIANS(D9)) -> 965.65068
A10: =Subsurface_Live_Data!A8 -> -57 | B10: =Model_Data!P8 -> 480.46961 | C10: =ABS(B10)*Inputs!$C$13/2 -> 1201.174 | D10: =DEGREES(ASIN(MIN(1,C10/(Inputs!$C$11*1000)))) -> 17.475232 | E10: =Model_Data!I8 -> 8.7666324 | F10: =Subsurface_Live_Data!F8 -> 974.61276 | G10: =Subsurface_Live_Data!I8 -> 5615.5846 | H10: =Subsurface_Live_Data!K8 -> 14585.997 | I10: =Subsurface_Live_Data!M8/COS(RADIANS(D10)) -> 12.133406 | J10: =Subsurface_Live_Data!N8/COS(RADIANS(D10)) -> 69.911017 | K10: =Subsurface_Live_Data!O8/COS(RADIANS(D10)) -> 181.58784 | L10: =Inputs!$C$21*K10/(2*Inputs!$C$12*1000000) -> 15291.76 | M10: =L10*COS(RADIANS(D10)) -> 14585.997 | N10: =L10-H10 -> 705.7629 | O10: =M10-H10 -> 0 | P10: =N10-O10 -> 705.7629 | Q10: =Inputs!$C$21*J10/(2*Inputs!$C$12*1000000) -> 5887.3022 | R10: =Q10*COS(RADIANS(D10)) -> 5615.5846 | S10: =Inputs!$C$21*I10/(2*Inputs!$C$12*1000000)*COS(RADIANS(D10)) -> 974.61276
A11: =Subsurface_Live_Data!A9 -> -56.5 | B11: =Model_Data!P9 -> 476.38117 | C11: =ABS(B11)*Inputs!$C$13/2 -> 1190.9529 | D11: =DEGREES(ASIN(MIN(1,C11/(Inputs!$C$11*1000)))) -> 17.321806 | E11: =Model_Data!I9 -> 8.704514 | F11: =Subsurface_Live_Data!F9 -> 985.50774 | G11: =Subsurface_Live_Data!I9 -> 5617.3146 | H11: =Subsurface_Live_Data!K9 -> 14592.499 | I11: =Subsurface_Live_Data!M9/COS(RADIANS(D11)) -> 12.258752 | J11: =Subsurface_Live_Data!N9/COS(RADIANS(D11)) -> 69.873899 | K11: =Subsurface_Live_Data!O9/COS(RADIANS(D11)) -> 181.51642 | L11: =Inputs!$C$21*K11/(2*Inputs!$C$12*1000000) -> 15285.745 | M11: =L11*COS(RADIANS(D11)) -> 14592.499 | N11: =L11-H11 -> 693.24598 | O11: =M11-H11 -> 0 | P11: =N11-O11 -> 693.24598 | Q11: =Inputs!$C$21*J11/(2*Inputs!$C$12*1000000) -> 5884.1764 | R11: =Q11*COS(RADIANS(D11)) -> 5617.3146 | S11: =Inputs!$C$21*I11/(2*Inputs!$C$12*1000000)*COS(RADIANS(D11)) -> 985.50774
A12: =Subsurface_Live_Data!A10 -> -56 | B12: =Model_Data!P10 -> 472.28953 | C12: =ABS(B12)*Inputs!$C$13/2 -> 1180.7238 | D12: =DEGREES(ASIN(MIN(1,C12/(Inputs!$C$11*1000)))) -> 17.168389 | E12: =Model_Data!I10 -> 8.6424357 | F12: =Subsurface_Live_Data!F10 -> 998.90364 | G12: =Subsurface_Live_Data!I10 -> 5618.2559 | H12: =Subsurface_Live_Data!K10 -> 14595.555 | I12: =Subsurface_Live_Data!M10/COS(RADIANS(D12)) -> 12.415061 | J12: =Subsurface_Live_Data!N10/COS(RADIANS(D12)) -> 69.827544 | K12: =Subsurface_Live_Data!O10/COS(RADIANS(D12)) -> 181.40358 | L12: =Inputs!$C$21*K12/(2*Inputs!$C$12*1000000) -> 15276.243 | M12: =L12*COS(RADIANS(D12)) -> 14595.555 | N12: =L12-H12 -> 680.68853 | O12: =M12-H12 -> 0 | P12: =N12-O12 -> 680.68853 | Q12: =Inputs!$C$21*J12/(2*Inputs!$C$12*1000000) -> 5880.2728 | R12: =Q12*COS(RADIANS(D12)) -> 5618.2559 | S12: =Inputs!$C$21*I12/(2*Inputs!$C$12*1000000)*COS(RADIANS(D12)) -> 998.90364
A13: =Subsurface_Live_Data!A11 -> -55.5 | B13: =Model_Data!P11 -> 468.19471 | C13: =ABS(B13)*Inputs!$C$13/2 -> 1170.4868 | D13: =DEGREES(ASIN(MIN(1,C13/(Inputs!$C$11*1000)))) -> 17.014978 | E13: =Model_Data!I11 -> 8.5804002 | F13: =Subsurface_Live_Data!F11 -> 1012.5409 | G13: =Subsurface_Live_Data!I11 -> 5618.403 | H13: =Subsurface_Live_Data!K11 -> 14602.693 | I13: =Subsurface_Live_Data!M11/COS(RADIANS(D13)) -> 12.574198 | J13: =Subsurface_Live_Data!N11/COS(RADIANS(D13)) -> 69.771908 | K13: =Subsurface_Live_Data!O11/COS(RADIANS(D13)) -> 181.34294 | L13: =Inputs!$C$21*K13/(2*Inputs!$C$12*1000000) -> 15271.137 | M13: =L13*COS(RADIANS(D13)) -> 14602.693 | N13: =L13-H13 -> 668.44375 | O13: =M13-H13 -> 0 | P13: =N13-O13 -> 668.44375 | Q13: =Inputs!$C$21*J13/(2*Inputs!$C$12*1000000) -> 5875.5876 | R13: =Q13*COS(RADIANS(D13)) -> 5618.403 | S13: =Inputs!$C$21*I13/(2*Inputs!$C$12*1000000)*COS(RADIANS(D13)) -> 1012.5409
A14: =Subsurface_Live_Data!A12 -> -55 | B14: =Model_Data!P12 -> 464.09674 | C14: =ABS(B14)*Inputs!$C$13/2 -> 1160.2418 | D14: =DEGREES(ASIN(MIN(1,C14/(Inputs!$C$11*1000)))) -> 16.861576 | E14: =Model_Data!I12 -> 8.5184101 | F14: =Subsurface_Live_Data!F12 -> 1028.4632 | G14: =Subsurface_Live_Data!I12 -> 5617.7514 | H14: =Subsurface_Live_Data!K12 -> 14606.308 | I14: =Subsurface_Live_Data!M12/COS(RADIANS(D14)) -> 12.761518 | J14: =Subsurface_Live_Data!N12/COS(RADIANS(D14)) -> 69.706952 | K14: =Subsurface_Live_Data!O12/COS(RADIANS(D14)) -> 181.23999 | L14: =Inputs!$C$21*K14/(2*Inputs!$C$12*1000000) -> 15262.467 | M14: =L14*COS(RADIANS(D14)) -> 14606.308 | N14: =L14-H14 -> 656.15906 | O14: =M14-H14 -> 0 | P14: =N14-O14 -> 656.15906 | Q14: =Inputs!$C$21*J14/(2*Inputs!$C$12*1000000) -> 5870.1176 | R14: =Q14*COS(RADIANS(D14)) -> 5617.7514 | S14: =Inputs!$C$21*I14/(2*Inputs!$C$12*1000000)*COS(RADIANS(D14)) -> 1028.4632
A15: =Subsurface_Live_Data!A13 -> -54.5 | B15: =Model_Data!P13 -> 459.99563 | C15: =ABS(B15)*Inputs!$C$13/2 -> 1149.9891 | D15: =DEGREES(ASIN(MIN(1,C15/(Inputs!$C$11*1000)))) -> 16.70818 | E15: =Model_Data!I13 -> 8.456468 | F15: =Subsurface_Live_Data!F13 -> 1045.7515 | G15: =Subsurface_Live_Data!I13 -> 5616.2969 | H15: =Subsurface_Live_Data!K13 -> 14609.094 | I15: =Subsurface_Live_Data!M13/COS(RADIANS(D15)) -> 12.965563 | J15: =Subsurface_Live_Data!N13/COS(RADIANS(D15)) -> 69.632651 | K15: =Subsurface_Live_Data!O13/COS(RADIANS(D15)) -> 181.12824 | L15: =Inputs!$C$21*K15/(2*Inputs!$C$12*1000000) -> 15253.056 | M15: =L15*COS(RADIANS(D15)) -> 14609.094 | N15: =L15-H15 -> 643.96179 | O15: =M15-H15 -> 0 | P15: =N15-O15 -> 643.96179 | Q15: =Inputs!$C$21*J15/(2*Inputs!$C$12*1000000) -> 5863.8605 | R15: =Q15*COS(RADIANS(D15)) -> 5616.2969 | S15: =Inputs!$C$21*I15/(2*Inputs!$C$12*1000000)*COS(RADIANS(D15)) -> 1045.7515
... A244: =Subsurface_Live_Data!A242 -> 60 | B244: =Model_Data!P242 -> -502.89823 | C244: =ABS(B244)*Inputs!$C$13/2 -> 1257.2456 | D244: =DEGREES(ASIN(MIN(1,C244/(Inputs!$C$11*1000)))) -> 18.319248 | E244: =Model_Data!I242 -> 9.1400512 | F244: =Subsurface_Live_Data!F242 -> 959.45014 | G244: =Subsurface_Live_Data!I242 -> 4663.3815 | H244: =Subsurface_Live_Data!K242 -> 14617.139 | I244: =Subsurface_Live_Data!M242/COS(RADIANS(D244)) -> 12.001599 | J244: =Subsurface_Live_Data!N242/COS(RADIANS(D244)) -> 58.333447 | K244: =Subsurface_Live_Data!O242/COS(RADIANS(D244)) -> 182.8433 | L244: =Inputs!$C$21*K244/(2*Inputs!$C$12*1000000) -> 15397.484 | M244: =L244*COS(RADIANS(D244)) -> 14617.139 | N244: =L244-H244 -> 780.34544 | O244: =M244-H244 -> 0 | P244: =N244-O244 -> 780.34544 | Q244: =Inputs!$C$21*J244/(2*Inputs!$C$12*1000000) -> 4912.3391 | R244: =Q244*COS(RADIANS(D244)) -> 4663.3815 | S244: =Inputs!$C$21*I244/(2*Inputs!$C$12*1000000)*COS(RADIANS(D244)) -> 959.45014

Sheet Inputs
A1: Parabolic Motion Radar Model - Editable Inputs
A2: Change the yellow cells in column C for the custom model. Use the TRUE/FALSE scenario toggles at the right to overlay paper-derived pass cases on the Dashboard charts.
A4: Parameter | B4: Symbol | C4: Value | D4: Unit | E4: Notes | F4: Paper-Derived Pass Scenario Overlays
A5: Closest altitude | B5: z0 | C5: 400 | D5: km | E5: Altitude at closest approach. Change this to test other flyby heights. | F5: Show | G5: Scenario | H5: z0 | I5: x_min | J5: x_max | K5: x_edge | L5: Delta_z_edge | M5: Edge altitude | N5: Paper basis / meaning
A6: Side/cross-track offset | B6: y | C6: 25 | D6: km | E6: Horizontal offset of the modeled target from nadir. | F6: TRUE | G6: Current custom inputs | H6: =C5 -> 400 | I6: =C7 -> -60 | J6: =C8 -> 60 | K6: =C10 -> 60 | L6: =C9 -> 4 | M6: =C5+C9 -> 404 | N6: Your editable custom case from the left table. It remains the main model used by the topography dashboard.
A7: Along-track minimum | B7: x_min | C7: -60 | D7: km | E7: Left/start side of the modeled pass. | F7: TRUE | G7: Paper low-altitude 800-km pass | H7: 35 | I7: -400 | J7: 400 | K7: 400 | L7: 365 | M7: 400 | N7: Paper coverage requirement: groundtrack segments at least 800 km long below 400 km for most REASON datasets. This model makes that a parabola.
A8: Along-track maximum | B8: x_max | C8: 60 | D8: km | E8: Right/end side of the modeled pass. | F8: TRUE | G8: Paper ice-ocean 1600-km pass | H8: 35 | I8: -800 | J8: 800 | K8: 800 | L8: 965 | M8: 1000 | N8: Paper ice-ocean interface requirement: at least 1600 km below 1000 km. This model makes that a parabola.
A9: Altitude rise at edge | B9: Delta_z_edge | C9: 4 | D9: km | E9: How much altitude rises at +/- x_edge. | F9: TRUE | G9: Paper operating 25-to-1000-km pass | H9: 25 | I9: -800 | J9: 800 | K9: 800 | L9: 975 | M9: 1000 | N9: Paper instrument table lists operational altitudes of 25 km to 1000 km. This shows the lower-bound closest-approach case.
A10: Parabola edge location | B10: x_edge | C10: 60 | D10: km | E10: Controls curvature together with Delta_z_edge.
A11: Along-track speed | B11: v | C11: 4 | D11: km/s | E11: Used for range rate, Doppler, and pulse spacing. | F11: Scenario note | G11: The paper gives altitude ranges and required groundtrack lengths, not exact parabolic equations. These rows convert those paper values into the same simplified parabola equation so outcomes can be compared on one dashboard.
A12: Ice refractive index | B12: n | C12: 1.78 | E12: Used to convert extra slant path into apparent depth.
A13: VHF wavelength | B13: lambda_vhf | C13: 5 | D13: m | E13: REASON-like VHF wavelength.
A14: HF wavelength | B14: lambda_hf | C14: 33.3 | D14: m | E14: REASON-like HF wavelength.
A15: Interferometer baseline | B15: b | C15: 5 | D15: m | E15: Used for VHF phase estimate.
A16: VHF range resolution | B16: res_vhf | C16: 30 | D16: m | E16: Used for VHF apparent-depth uncertainty band.
A17: HF range resolution | B17: res_hf | C17: 300 | D17: m | E17: Used for HF apparent-depth uncertainty band.
A18: PRF choice 1 | B18: PRF_1 | C18: 50 | D18: Hz | E18: Example low PRF.
A19: PRF choice 2 | B19: PRF_2 | C19: 500 | D19: Hz | E19: Example medium PRF.
A20: PRF choice 3 | B20: PRF_3 | C20: 3000 | D20: Hz | E20: Example high PRF.
A21: Speed of light | B21: c | C21: 299792458 | D21: m/s | E21: Physical constant used for delay and timing.
A23: Model note | B23: The parabola is a simplified local path, not a real mission trajectory. Use it to see how geometry changes radar outputs.
A25: Representative Europa Topography Controls
A26: Parameter | B26: Symbol | C26: Value | D26: Unit | E26: Notes
A27: Topography enabled | B27: topography_on | C27: TRUE | E27: Dropdown-style toggle. TRUE adds terrain height to the radar geometry; FALSE returns to flat surface.
A28: Ridge height | B28: A_ridge | C28: 350 | D28: m | E28: Positive height for a representative double-ridge / raised band.
A29: Ridge center x | B29: ridge_x0 | C29: 0 | D29: km | E29: Along-track center of the ridge.
A30: Ridge center y | B30: ridge_y0 | C30: 25 | D30: km | E30: Cross-track center of the ridge.
A31: Ridge length sigma | B31: ridge_sigma_x | C31: 24 | D31: km | E31: Long direction of the ridge feature.
A32: Ridge width sigma | B32: ridge_sigma_y | C32: 3.5 | D32: km | E32: Narrow cross-track width of the ridge.
A33: Crater/depression depth | B33: D_crater | C33: 180 | D33: m | E33: Positive number becomes a negative depression in the surface model.
A34: Crater center x | B34: crater_x0 | C34: -18 | D34: km | E34: Along-track center of depression.
A35: Crater center y | B35: crater_y0 | C35: 8 | D35: km | E35: Cross-track center of depression.
A36: Crater width sigma | B36: crater_sigma | C36: 8 | D36: km | E36: Controls how broad the depression is.
A37: Chaos amplitude | B37: A_chaos | C37: 65 | D37: m | E37: Mixed sinusoidal terrain term for irregular chaos-like height variation.
A38: Fine roughness amplitude | B38: A_rough | C38: 35 | D38: m | E38: Smaller surface roughness term.
A39: Roughness wavelength x | B39: Lx | C39: 18 | D39: km | E39: Along-track roughness wavelength.
... A46: Terrain vertical uncertainty | B46: sigma_h | C46: 75 | D46: m | E46: Representative uncertainty band for the topographic height model.
A47: Terrain seed | B47: terrain_seed | C47: 7 | E47: Change this number to generate a different repeatable random-looking surface. Same seed gives the same graphs.
A48: Seeded random amplitude | B48: A_seeded | C48: 45 | D48: m | E48: Strength of the generated terrain added on top of the DEM-style surface.
A49: Seeded random scale x | B49: L_seed_x | C49: 12 | D49: km | E49: Along-track scale for seeded terrain waves.
...

Sheet Subsurface_Inputs
A1: Europa Ice Subsurface Editable Inputs
A2: Change the yellow values in column C. Subsurface_Live_Data and Subsurface_Dashboard update from these formulas. | E2: All editable values live on this tab. Subsurface_Dashboard is output-only.
A3: Section | B3: Parameter | C3: Value | D3: Unit | E3: Notes
A4: Surface | B4: Use generated icy topography | C4: TRUE | E4: Surface/topography is modeled as icy terrain, not rock.
A5: Shallow ice | B5: Upper ice layer mean depth | C5: 1150 | D5: m | E5: Depth below the local icy surface.
A6: Shallow ice | B6: Upper ice sine amplitude | C6: 160 | D6: m | E6: Smooth undulation in shallow internal ice.
A7: Shallow ice | B7: Upper ice phase shift | C7: 10 | D7: km | E7: Moves the shallow layer pattern left/right.
A8: Shallow ice | B8: Upper ice sine wavelength | C8: 42 | D8: km | E8: Longer number means smoother/larger features.
A9: Shallow ice | B9: Upper ice cosine amplitude | C9: 60 | D9: m | E9: Secondary shallow-layer variation.
A10: Shallow ice | B10: Upper ice cosine wavelength | C10: 23 | D10: km | E10: Secondary shallow-layer spacing.
A11: Shallow ice | B11: Surface coupling factor | C11: 0.04 | E11: How much surface relief carries into shallow ice.
A13: Warm/briny lens | B13: Lens A strength | C13: 0.95 | D13: 0-1 | E13: Local possible warm/briny contrast, not proven.
A14: Warm/briny lens | B14: Lens A center | C14: -24 | D14: km | E14: Along-track center of first possible lens.
A15: Warm/briny lens | B15: Lens A width | C15: 10 | D15: km | E15: Controls how broad lens A is.
A16: Warm/briny lens | B16: Lens B strength | C16: 0.7 | D16: 0-1 | E16: Second possible lens.
A17: Warm/briny lens | B17: Lens B center | C17: 30 | D17: km | E17: Along-track center of second possible lens.
A18: Warm/briny lens | B18: Lens B width | C18: 8 | D18: km | E18: Controls how broad lens B is.
A19: Warm/briny lens | B19: Lens mean depth | C19: 5100 | D19: m | E19: Depth below local surface.
A20: Warm/briny lens | B20: Lens depth wave amplitude | C20: 520 | D20: m | E20: Broad depth variation.
A21: Warm/briny lens | B21: Lens depth phase shift | C21: 6 | D21: km | E21: Moves lens-depth wave left/right.
A22: Warm/briny lens | B22: Lens depth wavelength | C22: 82 | D22: km | E22: Lens-depth wave spacing.
A23: Warm/briny lens | B23: Lens uplift when strong | C23: 240 | D23: m | E23: Strong lens sits slightly shallower.
A25: Ice-ocean boundary | B25: Nominal ice shell thickness | C25: 15000 | D25: m | E25: Possible bottom reflector depth.
... A31: Ice-ocean boundary | B31: Ocean boundary cosine wavelength | C31: 62 | D31: km | E31: Secondary basal spacing.
A32: Ice-ocean boundary | B32: Surface anti-coupling factor | C32: 0.14 | E32: Surface highs slightly reduce thickness.
A34: Radar | B34: Ice refractive index | C34: =Inputs!$C$12 -> 1.78 | E34: Uses workbook ice index by default.
A35: Radar | B35: Speed of light | C35: 299792458 | D35: m/s | E35: Used for two-way delay.
A36: Radar | B36: One-way ice attenuation | C36: 0.9 | D36: dB/km | E36: Simple signal loss through ice.
A37: Radar | B37: Shallow layer base echo | C37: -10 | D37: dB | E37: Relative reflector strength before attenuation.
A38: Radar | B38: Lens base echo | C38: -24 | D38: dB | E38: Relative lens strength before lens multiplier and attenuation.
A39: Radar | B39: Lens strength echo bonus | C39: 9 | D39: dB | E39: A stronger lens creates a stronger reflector.
A40: Radar | B40: Ocean boundary base echo | C40: -6 | D40: dB | E40: Large material contrast from ice to possible ocean.
A41: Radar | B41: Basal roughness penalty | C41: 0.004 | D41: dB/m | E41: Rougher boundary weakens coherent echo.
A42: Radar | B42: Lens display threshold | C42: 0.18 | D42: 0-1 | E42: Below this, lens is treated as too weak for chart focus.
A43: Radar | B43: Detection threshold | C43: -45 | D43: dB | E43: Simple threshold for treating a return as easier to see.
A44: Uncertainty | B44: Boundary uncertainty band | C44: 1500 | D44: m | E44: Plus/minus range around the possible ice-ocean boundary.
A45: Scenario | B45: Thin shell multiplier | C45: 0.55 | E45: Creates a thinner-shell scenario from the live depth.
A46: Scenario | B46: Thick shell multiplier | C46: 1.75 | E46: Creates a thicker-shell scenario from the live depth.
A47: Scenario | B47: No-ocean control echo | C47: -60 | D47: dB | E47: Weak baseline return for a no-bottom-reflector control case.
A48: Evidence | B48: Radar support score | C48: 55 | D48: % | E48: How strongly radar outputs support the proposed subsurface.
...

Sheet Model_Data
A1: x_km | B1: z_km | C1: R_nadir_km | D1: R_off_km | E1: Delta_R_m | F1: apparent_depth_m | G1: extra_delay_us | H1: horizontal_offset_km | I1: look_angle_deg | J1: vhf_phase_deg | K1: relative_power | L1: power_dB | M1: dz_dx | N1: dz_dt_km_s | O1: range_rate_m_s | P1: vhf_doppler_hz | Q1: hf_doppler_hz | R1: vhf_band_low_m | S1: vhf_band_high_m | T1: hf_band_low_m | U1: hf_band_high_m | V1: abs_vhf_doppler_hz | W1: abs_hf_doppler_hz | X1: h_nadir_m | Y1: h_target_m | Z1: R_nadir_topo_km | AA1: R_off_topo_km | AB1: Delta_R_topo_m | AC1: apparent_depth_topo_m | AD1: extra_delay_topo_us | AE1: look_angle_topo_deg | AF1: vhf_phase_topo_deg | AG1: relative_power_topo | AH1: power_dB_topo | AI1: depth_change_topo_minus_flat_m | AJ1: delay_change_topo_minus_flat_us | AK1: target_minus_nadir_height_m | AL1: range_rate_topo_m_s | AM1: vhf_doppler_topo_hz | AN1: hf_doppler_topo_hz | AO1: abs_vhf_doppler_topo_hz | AP1: abs_hf_doppler_topo_hz | AQ1: topo_depth_uncertainty_m | AR1: topo_depth_low_m | AS1: topo_depth_high_m
A2: =Inputs!$C$7+0*(Inputs!$C$8-Inputs!$C$7)/240 -> -60 | B2: =Inputs!$C$5+Inputs!$C$9*(A2/Inputs!$C$10)^2 -> 404 | C2: =B2 -> 404 | D2: =SQRT((Inputs!$C$52+B2)^2+Inputs!$C$52^2-2*(Inputs!$C$52+B2)*Inputs!$C$52*COS(SQRT(A2^2+Inputs!$C$6^2)/Inputs!$C$52)) -> 410.52873 | E2: =(D2-C2)*1000 -> 6528.7288 | F2: =E2/Inputs!$C$12 -> 3667.8252 | G2: =2*E2/Inputs!$C$21*1000000 -> 43.554991 | H2: =SQRT(A2^2+Inputs!$C$6^2) -> 65 | I2: =DEGREES(ATAN(H2/B2)) -> 9.1400512 | J2: =DEGREES((2*PI()/Inputs!$C$13)*Inputs!$C$15*SIN(RADIANS(I2))) -> 57.185372 | K2: =(C2/D2)^4 -> 0.93788857 | L2: =10*LOG10(K2) -> -0.27848758 | M2: =2*(Inputs!$C$9/(Inputs!$C$10^2))*A2 -> -0.13333333 | N2: =M2*Inputs!$C$11 -> -0.53333333 | O2: =1000*(D3-D2)/(A3-A2)*Inputs!$C$11 -> -1257.2456 | P2: =-2*O2/Inputs!$C$13 -> 502.89823 | Q2: =-2*O2/Inputs!$C$14 -> 75.510245 | R2: =F2-Inputs!$C$16/2 -> 3652.8252 | S2: =F2+Inputs!$C$16/2 -> 3682.8252 | T2: =F2-Inputs!$C$17/2 -> 3517.8252 | U2: =F2+Inputs!$C$17/2 -> 3817.8252 | V2: =ABS(P2) -> 502.89823 | W2: =ABS(Q2) -> 75.510245 | X2: =IF(OR(Inputs!$C$27=TRUE,Inputs!$C$27="TRUE",Inputs!$C$27=1),1,0)*(Inputs!$C$51*(115*EXP(-(((0)-25)^2)/(4.5^2))+70*EXP(-(((0)+38)^2)/(7^2))*(0.55+0.45*SIN(2*PI()*(A2)/45))+24*SIN(2*PI()*(0)/9+(A2)/18)*EXP(-(((0)+5)^2)/(22^2))+18*SIN(2*PI()*(A2)/70))+Inputs!$C$28*EXP(-(((A2)-Inputs!$C$29)^2)/(2*Inputs!$C$31^2))*EXP(-(((0)-Inputs!$C$30)^2)/(2*Inputs!$C$32^2))+-Inputs!$C$33*EXP(-(((((A2)-Inputs!$C$34)^2)+(((0)-Inputs!$C$35)^2))/(2*Inputs!$C$36^2)))+Inputs!$C$37*(0.55*SIN(2*PI()*(A2)/Inputs!$C$39)+0.35*COS(2*PI()*(0)/Inputs!$C$40)+0.2*SIN(2*PI()*((A2)+(0))/(0.5*(Inputs!$C$39+Inputs!$C$40))))+Inputs!$C$38*SIN(2*PI()*(A2)/Inputs!$C$39)*SIN(2*PI()*(0)/Inputs!$C$40)+-Inputs!$C$41*EXP(-(((0)-Inputs!$C$43)^2)/(2*Inputs!$C$44^2))*EXP(-(((A2)-Inputs!$C$42)^2)/(2*Inputs!$C$45^2))+Inputs!$C$48*(0.7*(0.45*SIN(2*PI()*(((A2)/Inputs!$C$49)+Inputs!$C$47*0.137))+0.35*COS(2*PI()*(((0)/Inputs!$C$50)+Inputs!$C$47*0.173))+0.2*SIN(2*PI()*(((A2)+(0))/(0.5*(Inputs!$C$49+Inputs!$C$50))+Inputs!$C$47*0.097)))+0.3*(2*((SIN(((A2)*12.9898+(0)*78.233+Inputs!$C$47*37.719))*43758.5453)-INT((SIN(((A2)*12.9898+(0)*78.233+Inputs!$C$47*37.719))*43758.5453)))-1))) -> 2.764279 | Y2: =IF(OR(Inputs!$C$27=TRUE,Inputs!$C$27="TRUE",Inputs!$C$27=1),1,0)*(Inputs!$C$51*(115*EXP(-(((Inputs!$C$6)-25)^2)/(4.5^2))+70*EXP(-(((Inputs!$C$6)+38)^2)/(7^2))*(0.55+0.45*SIN(2*PI()*(A2)/45))+24*SIN(2*PI()*(Inputs!$C$6)/9+(A2)/18)*EXP(-(((Inputs!$C$6)+5)^2)/(22^2))+18*SIN(2*PI()*(A2)/70))+Inputs!$C$28*EXP(-(((A2)-Inputs!$C$29)^2)/(2*Inputs!$C$31^2))*EXP(-(((Inputs!$C$6)-Inputs!$C$30)^2)/(2*Inputs!$C$32^2))+-Inputs!$C$33*EXP(-(((((A2)-Inputs!$C$34)^2)+(((Inputs!$C$6)-Inputs!$C$35)^2))/(2*Inputs!$C$36^2)))+Inputs!$C$37*(0.55*SIN(2*PI()*(A2)/Inputs!$C$39)+0.35*COS(2*PI()*(Inputs!$C$6)/Inputs!$C$40)+0.2*SIN(2*PI()*((A2)+(Inputs!$C$6))/(0.5*(Inputs!$C$39+Inputs!$C$40))))+Inputs!$C$38*SIN(2*PI()*(A2)/Inputs!$C$39)*SIN(2*PI()*(Inputs!$C$6)/Inputs!$C$40)+-Inputs!$C$41*EXP(-(((Inputs!$C$6)-Inputs!$C$43)^2)/(2*Inputs!$C$44^2))*EXP(-(((A2)-Inputs!$C$42)^2)/(2*Inputs!$C$45^2))+Inputs!$C$48*(0.7*(0.45*SIN(2*PI()*(((A2)/Inputs!$C$49)+Inputs!$C$47*0.137))+0.35*COS(2*PI()*(((Inputs!$C$6)/Inputs!$C$50)+Inputs!$C$47*0.173))+0.2*SIN(2*PI()*(((A2)+(Inputs!$C$6))/(0.5*(Inputs!$C$49+Inputs!$C$50))+Inputs!$C$47*0.097)))+0.3*(2*((SIN(((A2)*12.9898+(Inputs!$C$6)*78.233+Inputs!$C$47*37.719))*43758.5453)-INT((SIN(((A2)*12.9898+(Inputs!$C$6)*78.233+Inputs!$C$47*37.719))*43758.5453)))-1))) -> 119.42639 | Z2: =B2-X2/1000 -> 403.99724 | AA2: =SQRT((Inputs!$C$52+B2)^2+(Inputs!$C$52+Y2/1000)^2-2*(Inputs!$C$52+B2)*(Inputs!$C$52+Y2/1000)*COS(SQRT(A2^2+Inputs!$C$6^2)/Inputs!$C$52)) -> 410.4117 | AB2: =(AA2-Z2)*1000 -> 6414.4623 | AC2: =AB2/Inputs!$C$12 -> 3603.6305 | AD2: =2*AB2/Inputs!$C$21*1000000 -> 42.792686 | AE2: =DEGREES(ATAN(H2/(B2-Y2/1000))) -> 9.1427083 | AF2: =DEGREES((2*PI()/Inputs!$C$13)*Inputs!$C$15*SIN(RADIANS(AE2))) -> 57.201855 | AG2: =(Z2/AA2)^4 -> 0.9389331 | AH2: =10*LOG10(AG2) -> -0.2736535 | AI2: =AC2-F2 -> -64.194703 | AJ2: =AD2-G2 -> -0.76230451 | AK2: =Y2-X2 -> 116.66211 | AL2: =1000*(AA3-AA2)/(A3-A2)*Inputs!$C$11 -> -1189.0456 | AM2: =-2*AL2/Inputs!$C$13 -> 475.61823 | AN2: =-2*AL2/Inputs!$C$14 -> 71.414149 | AO2: =ABS(AM2) -> 475.61823 | AP2: =ABS(AN2) -> 71.414149 | AQ2: =IF(OR(Inputs!$C$27=TRUE,Inputs!$C$27="TRUE",Inputs!$C$27=1),Inputs!$C$46/Inputs!$C$12,0) -> 42.134831 | AR2: =AC2-AQ2 -> 3561.4957 | AS2: =AC2+AQ2 -> 3645.7653
A3: =Inputs!$C$7+1*(Inputs!$C$8-Inputs!$C$7)/240 -> -59.5 | B3: =Inputs!$C$5+Inputs!$C$9*(A3/Inputs!$C$10)^2 -> 403.93361 | C3: =B3 -> 403.93361 | D3: =SQRT((Inputs!$C$52+B3)^2+Inputs!$C$52^2-2*(Inputs!$C$52+B3)*Inputs!$C$52*COS(SQRT(A3^2+Inputs!$C$6^2)/Inputs!$C$52)) -> 410.37157 | E3: =(D3-C3)*1000 -> 6437.962 | F3: =E3/Inputs!$C$12 -> 3616.8326 | G3: =2*E3/Inputs!$C$21*1000000 -> 42.94946 | H3: =SQRT(A3^2+Inputs!$C$6^2) -> 64.538748 | I3: =DEGREES(ATAN(H3/B3)) -> 9.077742 | J3: =DEGREES((2*PI()/Inputs!$C$13)*Inputs!$C$15*SIN(RADIANS(I3))) -> 56.798809 | K3: =(C3/D3)^4 -> 0.93870881 | L3: =10*LOG10(K3) -> -0.27469108 | M3: =2*(Inputs!$C$9/(Inputs!$C$10^2))*A3 -> -0.13222222 | N3: =M3*Inputs!$C$11 -> -0.52888889 | O3: =1000*(D4-D2)/(A4-A2)*Inputs!$C$11 -> -1252.1575 | P3: =-2*O3/Inputs!$C$13 -> 500.86301 | Q3: =-2*O3/Inputs!$C$14 -> 75.204657 | R3: =F3-Inputs!$C$16/2 -> 3601.8326 | S3: =F3+Inputs!$C$16/2 -> 3631.8326 | T3: =F3-Inputs!$C$17/2 -> 3466.8326 | U3: =F3+Inputs!$C$17/2 -> 3766.8326 | V3: =ABS(P3) -> 500.86301 | W3: =ABS(Q3) -> 75.204657 | X3: =IF(OR(Inputs!$C$27=TRUE,Inputs!$C$27="TRUE",Inputs!$C$27=1),1,0)*(Inputs!$C$51*(115*EXP(-(((0)-25)^2)/(4.5^2))+70*EXP(-(((0)+38)^2)/(7^2))*(0.55+0.45*SIN(2*PI()*(A3)/45))+24*SIN(2*PI()*(0)/9+(A3)/18)*EXP(-(((0)+5)^2)/(22^2))+18*SIN(2*PI()*(A3)/70))+Inputs!$C$28*EXP(-(((A3)-Inputs!$C$29)^2)/(2*Inputs!$C$31^2))*EXP(-(((0)-Inputs!$C$30)^2)/(2*Inputs!$C$32^2))+-Inputs!$C$33*EXP(-(((((A3)-Inputs!$C$34)^2)+(((0)-Inputs!$C$35)^2))/(2*Inputs!$C$36^2)))+Inputs!$C$37*(0.55*SIN(2*PI()*(A3)/Inputs!$C$39)+0.35*COS(2*PI()*(0)/Inputs!$C$40)+0.2*SIN(2*PI()*((A3)+(0))/(0.5*(Inputs!$C$39+Inputs!$C$40))))+Inputs!$C$38*SIN(2*PI()*(A3)/Inputs!$C$39)*SIN(2*PI()*(0)/Inputs!$C$40)+-Inputs!$C$41*EXP(-(((0)-Inputs!$C$43)^2)/(2*Inputs!$C$44^2))*EXP(-(((A3)-Inputs!$C$42)^2)/(2*Inputs!$C$45^2))+Inputs!$C$48*(0.7*(0.45*SIN(2*PI()*(((A3)/Inputs!$C$49)+Inputs!$C$47*0.137))+0.35*COS(2*PI()*(((0)/Inputs!$C$50)+Inputs!$C$47*0.173))+0.2*SIN(2*PI()*(((A3)+(0))/(0.5*(Inputs!$C$49+Inputs!$C$50))+Inputs!$C$47*0.097)))+0.3*(2*((SIN(((A3)*12.9898+(0)*78.233+Inputs!$C$47*37.719))*43758.5453)-INT((SIN(((A3)*12.9898+(0)*78.233+Inputs!$C$47*37.719))*43758.5453)))-1))) -> 19.645117 | Y3: =IF(OR(Inputs!$C$27=TRUE,Inputs!$C$27="TRUE",Inputs!$C$27=1),1,0)*(Inputs!$C$51*(115*EXP(-(((Inputs!$C$6)-25)^2)/(4.5^2))+70*EXP(-(((Inputs!$C$6)+38)^2)/(7^2))*(0.55+0.45*SIN(2*PI()*(A3)/45))+24*SIN(2*PI()*(Inputs!$C$6)/9+(A3)/18)*EXP(-(((Inputs!$C$6)+5)^2)/(22^2))+18*SIN(2*PI()*(A3)/70))+Inputs!$C$28*EXP(-(((A3)-Inputs!$C$29)^2)/(2*Inputs!$C$31^2))*EXP(-(((Inputs!$C$6)-Inputs!$C$30)^2)/(2*Inputs!$C$32^2))+-Inputs!$C$33*EXP(-(((((A3)-Inputs!$C$34)^2)+(((Inputs!$C$6)-Inputs!$C$35)^2))/(2*Inputs!$C$36^2)))+Inputs!$C$37*(0.55*SIN(2*PI()*(A3)/Inputs!$C$39)+0.35*COS(2*PI()*(Inputs!$C$6)/Inputs!$C$40)+0.2*SIN(2*PI()*((A3)+(Inputs!$C$6))/(0.5*(Inputs!$C$39+Inputs!$C$40))))+Inputs!$C$38*SIN(2*PI()*(A3)/Inputs!$C$39)*SIN(2*PI()*(Inputs!$C$6)/Inputs!$C$40)+-Inputs!$C$41*EXP(-(((Inputs!$C$6)-Inputs!$C$43)^2)/(2*Inputs!$C$44^2))*EXP(-(((A3)-Inputs!$C$42)^2)/(2*Inputs!$C$45^2))+Inputs!$C$48*(0.7*(0.45*SIN(2*PI()*(((A3)/Inputs!$C$49)+Inputs!$C$47*0.137))+0.35*COS(2*PI()*(((Inputs!$C$6)/Inputs!$C$50)+Inputs!$C$47*0.173))+0.2*SIN(2*PI()*(((A3)+(Inputs!$C$6))/(0.5*(Inputs!$C$49+Inputs!$C$50))+Inputs!$C$47*0.097)))+0.3*(2*((SIN(((A3)*12.9898+(Inputs!$C$6)*78.233+Inputs!$C$47*37.719))*43758.5453)-INT((SIN(((A3)*12.9898+(Inputs!$C$6)*78.233+Inputs!$C$47*37.719))*43758.5453)))-1))) -> 110.69606 | Z3: =B3-X3/1000 -> 403.91397 | AA3: =SQRT((Inputs!$C$52+B3)^2+(Inputs!$C$52+Y3/1000)^2-2*(Inputs!$C$52+B3)*(Inputs!$C$52+Y3/1000)*COS(SQRT(A3^2+Inputs!$C$6^2)/Inputs!$C$52)) -> 410.26307 | AB3: =(AA3-Z3)*1000 -> 6349.1013 | AC3: =AB3/Inputs!$C$12 -> 3566.9108 | AD3: =2*AB3/Inputs!$C$21*1000000 -> 42.356645 | AE3: =DEGREES(ATAN(H3/(B3-Y3/1000))) -> 9.080189 | AF3: =DEGREES((2*PI()/Inputs!$C$13)*Inputs!$C$15*SIN(RADIANS(AE3))) -> 56.813991 | AG3: =(Z3/AA3)^4 -> 0.93951948 | AH3: =10*LOG10(AG3) -> -0.27094211 | AI3: =AC3-F3 -> -49.92176 | AJ3: =AD3-G3 -> -0.592815 | AK3: =Y3-X3 -> 91.050948 | AL3: =1000*(AA4-AA2)/(A4-A2)*Inputs!$C$11 -> -1227.1825 | AM3: =-2*AL3/Inputs!$C$13 -> 490.873 | AN3: =-2*AL3/Inputs!$C$14 -> 73.704655 | AO3: =ABS(AM3) -> 490.873 | AP3: =ABS(AN3) -> 73.704655 | AQ3: =IF(OR(Inputs!$C$27=TRUE,Inputs!$C$27="TRUE",Inputs!$C$27=1),Inputs!$C$46/Inputs!$C$12,0) -> 42.134831 | AR3: =AC3-AQ3 -> 3524.776 | AS3: =AC3+AQ3 -> 3609.0457
A4: =Inputs!$C$7+2*(Inputs!$C$8-Inputs!$C$7)/240 -> -59 | B4: =Inputs!$C$5+Inputs!$C$9*(A4/Inputs!$C$10)^2 -> 403.86778 | C4: =B4 -> 403.86778 | D4: =SQRT((Inputs!$C$52+B4)^2+Inputs!$C$52^2-2*(Inputs!$C$52+B4)*Inputs!$C$52*COS(SQRT(A4^2+Inputs!$C$6^2)/Inputs!$C$52)) -> 410.21569 | E4: =(D4-C4)*1000 -> 6347.9117 | F4: =E4/Inputs!$C$12 -> 3566.2425 | G4: =2*E4/Inputs!$C$21*1000000 -> 42.348708 | H4: =SQRT(A4^2+Inputs!$C$6^2) -> 64.078077 | I4: =DEGREES(ATAN(H4/B4)) -> 9.0154589 | J4: =DEGREES((2*PI()/Inputs!$C$13)*Inputs!$C$15*SIN(RADIANS(I4))) -> 56.412341 | K4: =(C4/D4)^4 -> 0.93952373 | L4: =10*LOG10(K4) -> -0.27092248 | M4: =2*(Inputs!$C$9/(Inputs!$C$10^2))*A4 -> -0.13111111 | N4: =M4*Inputs!$C$11 -> -0.52444444 | O4: =1000*(D5-D3)/(A5-A3)*Inputs!$C$11 -> -1241.9773 | P4: =-2*O4/Inputs!$C$13 -> 496.79091 | Q4: =-2*O4/Inputs!$C$14 -> 74.59323 | R4: =F4-Inputs!$C$16/2 -> 3551.2425 | S4: =F4+Inputs!$C$16/2 -> 3581.2425 | T4: =F4-Inputs!$C$17/2 -> 3416.2425 | U4: =F4+Inputs!$C$17/2 -> 3716.2425 | V4: =ABS(P4) -> 496.79091 | W4: =ABS(Q4) -> 74.59323 | X4: =IF(OR(Inputs!$C$27=TRUE,Inputs!$C$27="TRUE",Inputs!$C$27=1),1,0)*(Inputs!$C$51*(115*EXP(-(((0)-25)^2)/(4.5^2))+70*EXP(-(((0)+38)^2)/(7^2))*(0.55+0.45*SIN(2*PI()*(A4)/45))+24*SIN(2*PI()*(0)/9+(A4)/18)*EXP(-(((0)+5)^2)/(22^2))+18*SIN(2*PI()*(A4)/70))+Inputs!$C$28*EXP(-(((A4)-Inputs!$C$29)^2)/(2*Inputs!$C$31^2))*EXP(-(((0)-Inputs!$C$30)^2)/(2*Inputs!$C$32^2))+-Inputs!$C$33*EXP(-(((((A4)-Inputs!$C$34)^2)+(((0)-Inputs!$C$35)^2))/(2*Inputs!$C$36^2)))+Inputs!$C$37*(0.55*SIN(2*PI()*(A4)/Inputs!$C$39)+0.35*COS(2*PI()*(0)/Inputs!$C$40)+0.2*SIN(2*PI()*((A4)+(0))/(0.5*(Inputs!$C$39+Inputs!$C$40))))+Inputs!$C$38*SIN(2*PI()*(A4)/Inputs!$C$39)*SIN(2*PI()*(0)/Inputs!$C$40)+-Inputs!$C$41*EXP(-(((0)-Inputs!$C$43)^2)/(2*Inputs!$C$44^2))*EXP(-(((A4)-Inputs!$C$42)^2)/(2*Inputs!$C$45^2))+Inputs!$C$48*(0.7*(0.45*SIN(2*PI()*(((A4)/Inputs!$C$49)+Inputs!$C$47*0.137))+0.35*COS(2*PI()*(((0)/Inputs!$C$50)+Inputs!$C$47*0.173))+0.2*SIN(2*PI()*(((A4)+(0))/(0.5*(Inputs!$C$49+Inputs!$C$50))+Inputs!$C$47*0.097)))+0.3*(2*((SIN(((A4)*12.9898+(0)*78.233+Inputs!$C$47*37.719))*43758.5453)-INT((SIN(((A4)*12.9898+(0)*78.233+Inputs!$C$47*37.719))*43758.5453)))-1))) -> 7.9704484 | Y4: =IF(OR(Inputs!$C$27=TRUE,Inputs!$C$27="TRUE",Inputs!$C$27=1),1,0)*(Inputs!$C$51*(115*EXP(-(((Inputs!$C$6)-25)^2)/(4.5^2))+70*EXP(-(((Inputs!$C$6)+38)^2)/(7^2))*(0.55+0.45*SIN(2*PI()*(A4)/45))+24*SIN(2*PI()*(Inputs!$C$6)/9+(A4)/18)*EXP(-(((Inputs!$C$6)+5)^2)/(22^2))+18*SIN(2*PI()*(A4)/70))+Inputs!$C$28*EXP(-(((A4)-Inputs!$C$29)^2)/(2*Inputs!$C$31^2))*EXP(-(((Inputs!$C$6)-Inputs!$C$30)^2)/(2*Inputs!$C$32^2))+-Inputs!$C$33*EXP(-(((((A4)-Inputs!$C$34)^2)+(((Inputs!$C$6)-Inputs!$C$35)^2))/(2*Inputs!$C$36^2)))+Inputs!$C$37*(0.55*SIN(2*PI()*(A4)/Inputs!$C$39)+0.35*COS(2*PI()*(Inputs!$C$6)/Inputs!$C$40)+0.2*SIN(2*PI()*((A4)+(Inputs!$C$6))/(0.5*(Inputs!$C$39+Inputs!$C$40))))+Inputs!$C$38*SIN(2*PI()*(A4)/Inputs!$C$39)*SIN(2*PI()*(Inputs!$C$6)/Inputs!$C$40)+-Inputs!$C$41*EXP(-(((Inputs!$C$6)-Inputs!$C$43)^2)/(2*Inputs!$C$44^2))*EXP(-(((A4)-Inputs!$C$42)^2)/(2*Inputs!$C$45^2))+Inputs!$C$48*(0.7*(0.45*SIN(2*PI()*(((A4)/Inputs!$C$49)+Inputs!$C$47*0.137))+0.35*COS(2*PI()*(((Inputs!$C$6)/Inputs!$C$50)+Inputs!$C$47*0.173))+0.2*SIN(2*PI()*(((A4)+(Inputs!$C$6))/(0.5*(Inputs!$C$49+Inputs!$C$50))+Inputs!$C$47*0.097)))+0.3*(2*((SIN(((A4)*12.9898+(Inputs!$C$6)*78.233+Inputs!$C$47*37.719))*43758.5453)-INT((SIN(((A4)*12.9898+(Inputs!$C$6)*78.233+Inputs!$C$47*37.719))*43758.5453)))-1))) -> 112.99219 | Z4: =B4-X4/1000 -> 403.85981 | AA4: =SQRT((Inputs!$C$52+B4)^2+(Inputs!$C$52+Y4/1000)^2-2*(Inputs!$C$52+B4)*(Inputs!$C$52+Y4/1000)*COS(SQRT(A4^2+Inputs!$C$6^2)/Inputs!$C$52)) -> 410.1049 | AB4: =(AA4-Z4)*1000 -> 6245.095 | AC4: =AB4/Inputs!$C$12 -> 3508.4804 | AD4: =2*AB4/Inputs!$C$21*1000000 -> 41.662789 | AE4: =DEGREES(ATAN(H4/(B4-Y4/1000))) -> 9.0179405 | AF4: =DEGREES((2*PI()/Inputs!$C$13)*Inputs!$C$15*SIN(RADIANS(AE4))) -> 56.42774 | AG4: =(Z4/AA4)^4 -> 0.94046512 | AH4: =10*LOG10(AG4) -> -0.26657308 | AI4: =AC4-F4 -> -57.76216 | AJ4: =AD4-G4 -> -0.68591882 | AK4: =Y4-X4 -> 105.02175 | AL4: =1000*(AA5-AA3)/(A5-A3)*Inputs!$C$11 -> -1335.1505 | AM4: =-2*AL4/Inputs!$C$13 -> 534.06021 | AN4: =-2*AL4/Inputs!$C$14 -> 80.189221 | AO4: =ABS(AM4) -> 534.06021 | AP4: =ABS(AN4) -> 80.189221 | AQ4: =IF(OR(Inputs!$C$27=TRUE,Inputs!$C$27="TRUE",Inputs!$C$27=1),Inputs!$C$46/Inputs!$C$12,0) -> 42.134831 | AR4: =AC4-AQ4 -> 3466.3455 | AS4: =AC4+AQ4 -> 3550.6152
A5: =Inputs!$C$7+3*(Inputs!$C$8-Inputs!$C$7)/240 -> -58.5 | B5: =Inputs!$C$5+Inputs!$C$9*(A5/Inputs!$C$10)^2 -> 403.8025 | C5: =B5 -> 403.8025 | D5: =SQRT((Inputs!$C$52+B5)^2+Inputs!$C$52^2-2*(Inputs!$C$52+B5)*Inputs!$C$52*COS(SQRT(A5^2+Inputs!$C$6^2)/Inputs!$C$52)) -> 410.06108 | E5: =(D5-C5)*1000 -> 6258.5788 | F5: =E5/Inputs!$C$12 -> 3516.0555 | G5: =2*E5/Inputs!$C$21*1000000 -> 41.752744 | H5: =SQRT(A5^2+Inputs!$C$6^2) -> 63.618001 | I5: =DEGREES(ATAN(H5/B5)) -> 8.9532041 | J5: =DEGREES((2*PI()/Inputs!$C$13)*Inputs!$C$15*SIN(RADIANS(I5))) -> 56.025981 | K5: =(C5/D5)^4 -> 0.9403333 | L5: =10*LOG10(K5) -> -0.26718186 | M5: =2*(Inputs!$C$9/(Inputs!$C$10^2))*A5 -> -0.13 | N5: =M5*Inputs!$C$11 -> -0.52 | O5: =1000*(D6-D4)/(A6-A4)*Inputs!$C$11 -> -1231.7887 | P5: =-2*O5/Inputs!$C$13 -> 492.7155 | Q5: =-2*O5/Inputs!$C$14 -> 73.981306 | R5: =F5-Inputs!$C$16/2 -> 3501.0555 | S5: =F5+Inputs!$C$16/2 -> 3531.0555 | T5: =F5-Inputs!$C$17/2 -> 3366.0555 | U5: =F5+Inputs!$C$17/2 -> 3666.0555 | V5: =ABS(P5) -> 492.7155 | W5: =ABS(Q5) -> 73.981306 | X5: =IF(OR(Inputs!$C$27=TRUE,Inputs!$C$27="TRUE",Inputs!$C$27=1),1,0)*(Inputs!$C$51*(115*EXP(-(((0)-25)^2)/(4.5^2))+70*EXP(-(((0)+38)^2)/(7^2))*(0.55+0.45*SIN(2*PI()*(A5)/45))+24*SIN(2*PI()*(0)/9+(A5)/18)*EXP(-(((0)+5)^2)/(22^2))+18*SIN(2*PI()*(A5)/70))+Inputs!$C$28*EXP(-(((A5)-Inputs!$C$29)^2)/(2*Inputs!$C$31^2))*EXP(-(((0)-Inputs!$C$30)^2)/(2*Inputs!$C$32^2))+-Inputs!$C$33*EXP(-(((((A5)-Inputs!$C$34)^2)+(((0)-Inputs!$C$35)^2))/(2*Inputs!$C$36^2)))+Inputs!$C$37*(0.55*SIN(2*PI()*(A5)/Inputs!$C$39)+0.35*COS(2*PI()*(0)/Inputs!$C$40)+0.2*SIN(2*PI()*((A5)+(0))/(0.5*(Inputs!$C$39+Inputs!$C$40))))+Inputs!$C$38*SIN(2*PI()*(A5)/Inputs!$C$39)*SIN(2*PI()*(0)/Inputs!$C$40)+-Inputs!$C$41*EXP(-(((0)-Inputs!$C$43)^2)/(2*Inputs!$C$44^2))*EXP(-(((A5)-Inputs!$C$42)^2)/(2*Inputs!$C$45^2))+Inputs!$C$48*(0.7*(0.45*SIN(2*PI()*(((A5)/Inputs!$C$49)+Inputs!$C$47*0.137))+0.35*COS(2*PI()*(((0)/Inputs!$C$50)+Inputs!$C$47*0.173))+0.2*SIN(2*PI()*(((A5)+(0))/(0.5*(Inputs!$C$49+Inputs!$C$50))+Inputs!$C$47*0.097)))+0.3*(2*((SIN(((A5)*12.9898+(0)*78.233+Inputs!$C$47*37.719))*43758.5453)-INT((SIN(((A5)*12.9898+(0)*78.233+Inputs!$C$47*37.719))*43758.5453)))-1))) -> 21.747314 | Y5: =IF(OR(Inputs!$C$27=TRUE,Inputs!$C$27="TRUE",Inputs!$C$27=1),1,0)*(Inputs!$C$51*(115*EXP(-(((Inputs!$C$6)-25)^2)/(4.5^2))+70*EXP(-(((Inputs!$C$6)+38)^2)/(7^2))*(0.55+0.45*SIN(2*PI()*(A5)/45))+24*SIN(2*PI()*(Inputs!$C$6)/9+(A5)/18)*EXP(-(((Inputs!$C$6)+5)^2)/(22^2))+18*SIN(2*PI()*(A5)/70))+Inputs!$C$28*EXP(-(((A5)-Inputs!$C$29)^2)/(2*Inputs!$C$31^2))*EXP(-(((Inputs!$C$6)-Inputs!$C$30)^2)/(2*Inputs!$C$32^2))+-Inputs!$C$33*EXP(-(((((A5)-Inputs!$C$34)^2)+(((Inputs!$C$6)-Inputs!$C$35)^2))/(2*Inputs!$C$36^2)))+Inputs!$C$37*(0.55*SIN(2*PI()*(A5)/Inputs!$C$39)+0.35*COS(2*PI()*(Inputs!$C$6)/Inputs!$C$40)+0.2*SIN(2*PI()*((A5)+(Inputs!$C$6))/(0.5*(Inputs!$C$39+Inputs!$C$40))))+Inputs!$C$38*SIN(2*PI()*(A5)/Inputs!$C$39)*SIN(2*PI()*(Inputs!$C$6)/Inputs!$C$40)+-Inputs!$C$41*EXP(-(((Inputs!$C$6)-Inputs!$C$43)^2)/(2*Inputs!$C$44^2))*EXP(-(((A5)-Inputs!$C$42)^2)/(2*Inputs!$C$45^2))+Inputs!$C$48*(0.7*(0.45*SIN(2*PI()*(((A5)/Inputs!$C$49)+Inputs!$C$47*0.137))+0.35*COS(2*PI()*(((Inputs!$C$6)/Inputs!$C$50)+Inputs!$C$47*0.173))+0.2*SIN(2*PI()*(((A5)+(Inputs!$C$6))/(0.5*(Inputs!$C$49+Inputs!$C$50))+Inputs!$C$47*0.097)))+0.3*(2*((SIN(((A5)*12.9898+(Inputs!$C$6)*78.233+Inputs!$C$47*37.719))*43758.5453)-INT((SIN(((A5)*12.9898+(Inputs!$C$6)*78.233+Inputs!$C$47*37.719))*43758.5453)))-1))) -> 134.38583 | Z5: =B5-X5/1000 -> 403.78075 | AA5: =SQRT((Inputs!$C$52+B5)^2+(Inputs!$C$52+Y5/1000)^2-2*(Inputs!$C$52+B5)*(Inputs!$C$52+Y5/1000)*COS(SQRT(A5^2+Inputs!$C$6^2)/Inputs!$C$52)) -> 409.92928 | AB5: =(AA5-Z5)*1000 -> 6148.527 | AC5: =AB5/Inputs!$C$12 -> 3454.2286 | AD5: =2*AB5/Inputs!$C$21*1000000 -> 41.018557 | AE5: =DEGREES(ATAN(H5/(B5-Y5/1000))) -> 8.9561364 | AF5: =DEGREES((2*PI()/Inputs!$C$13)*Inputs!$C$15*SIN(RADIANS(AE5))) -> 56.044181 | AG5: =(Z5/AA5)^4 -> 0.94134039 | AH5: =10*LOG10(AG5) -> -0.26253305 | AI5: =AC5-F5 -> -61.826883 | AJ5: =AD5-G5 -> -0.73418693 | AK5: =Y5-X5 -> 112.63852 | AL5: =1000*(AA6-AA4)/(A6-A4)*Inputs!$C$11 -> -1259.8024 | AM5: =-2*AL5/Inputs!$C$13 -> 503.92095 | AN5: =-2*AL5/Inputs!$C$14 -> 75.663806 | AO5: =ABS(AM5) -> 503.92095 | AP5: =ABS(AN5) -> 75.663806 | AQ5: =IF(OR(Inputs!$C$27=TRUE,Inputs!$C$27="TRUE",Inputs!$C$27=1),Inputs!$C$46/Inputs!$C$12,0) -> 42.134831 | AR5: =AC5-AQ5 -> 3412.0938 | AS5: =AC5+AQ5 -> 3496.3635
A6: =Inputs!$C$7+4*(Inputs!$C$8-Inputs!$C$7)/240 -> -58 | B6: =Inputs!$C$5+Inputs!$C$9*(A6/Inputs!$C$10)^2 -> 403.73778 | C6: =B6 -> 403.73778 | D6: =SQRT((Inputs!$C$52+B6)^2+Inputs!$C$52^2-2*(Inputs!$C$52+B6)*Inputs!$C$52*COS(SQRT(A6^2+Inputs!$C$6^2)/Inputs!$C$52)) -> 409.90774 | E6: =(D6-C6)*1000 -> 6169.9645 | F6: =E6/Inputs!$C$12 -> 3466.2722 | G6: =2*E6/Inputs!$C$21*1000000 -> 41.161572 | H6: =SQRT(A6^2+Inputs!$C$6^2) -> 63.158531 | I6: =DEGREES(ATAN(H6/B6)) -> 8.8909798 | J6: =DEGREES((2*PI()/Inputs!$C$13)*Inputs!$C$15*SIN(RADIANS(I6))) -> 55.639745 | K6: =(C6/D6)^4 -> 0.94113748 | L6: =10*LOG10(K6) -> -0.26346932 | M6: =2*(Inputs!$C$9/(Inputs!$C$10^2))*A6 -> -0.12888889 | N6: =M6*Inputs!$C$11 -> -0.51555556 | O6: =1000*(D7-D5)/(A7-A5)*Inputs!$C$11 -> -1221.592 | P6: =-2*O6/Inputs!$C$13 -> 488.63679 | Q6: =-2*O6/Inputs!$C$14 -> 73.368888 | R6: =F6-Inputs!$C$16/2 -> 3451.2722 | S6: =F6+Inputs!$C$16/2 -> 3481.2722 | T6: =F6-Inputs!$C$17/2 -> 3316.2722 | U6: =F6+Inputs!$C$17/2 -> 3616.2722 | V6: =ABS(P6) -> 488.63679 | W6: =ABS(Q6) -> 73.368888 | X6: =IF(OR(Inputs!$C$27=TRUE,Inputs!$C$27="TRUE",Inputs!$C$27=1),1,0)*(Inputs!$C$51*(115*EXP(-(((0)-25)^2)/(4.5^2))+70*EXP(-(((0)+38)^2)/(7^2))*(0.55+0.45*SIN(2*PI()*(A6)/45))+24*SIN(2*PI()*(0)/9+(A6)/18)*EXP(-(((0)+5)^2)/(22^2))+18*SIN(2*PI()*(A6)/70))+Inputs!$C$28*EXP(-(((A6)-Inputs!$C$29)^2)/(2*Inputs!$C$31^2))*EXP(-(((0)-Inputs!$C$30)^2)/(2*Inputs!$C$32^2))+-Inputs!$C$33*EXP(-(((((A6)-Inputs!$C$34)^2)+(((0)-Inputs!$C$35)^2))/(2*Inputs!$C$36^2)))+Inputs!$C$37*(0.55*SIN(2*PI()*(A6)/Inputs!$C$39)+0.35*COS(2*PI()*(0)/Inputs!$C$40)+0.2*SIN(2*PI()*((A6)+(0))/(0.5*(Inputs!$C$39+Inputs!$C$40))))+Inputs!$C$38*SIN(2*PI()*(A6)/Inputs!$C$39)*SIN(2*PI()*(0)/Inputs!$C$40)+-Inputs!$C$41*EXP(-(((0)-Inputs!$C$43)^2)/(2*Inputs!$C$44^2))*EXP(-(((A6)-Inputs!$C$42)^2)/(2*Inputs!$C$45^2))+Inputs!$C$48*(0.7*(0.45*SIN(2*PI()*(((A6)/Inputs!$C$49)+Inputs!$C$47*0.137))+0.35*COS(2*PI()*(((0)/Inputs!$C$50)+Inputs!$C$47*0.173))+0.2*SIN(2*PI()*(((A6)+(0))/(0.5*(Inputs!$C$49+Inputs!$C$50))+Inputs!$C$47*0.097)))+0.3*(2*((SIN(((A6)*12.9898+(0)*78.233+Inputs!$C$47*37.719))*43758.5453)-INT((SIN(((A6)*12.9898+(0)*78.233+Inputs!$C$47*37.719))*43758.5453)))-1))) -> 31.866914 | Y6: =IF(OR(Inputs!$C$27=TRUE,Inputs!$C$27="TRUE",Inputs!$C$27=1),1,0)*(Inputs!$C$51*(115*EXP(-(((Inputs!$C$6)-25)^2)/(4.5^2))+70*EXP(-(((Inputs!$C$6)+38)^2)/(7^2))*(0.55+0.45*SIN(2*PI()*(A6)/45))+24*SIN(2*PI()*(Inputs!$C$6)/9+(A6)/18)*EXP(-(((Inputs!$C$6)+5)^2)/(22^2))+18*SIN(2*PI()*(A6)/70))+Inputs!$C$28*EXP(-(((A6)-Inputs!$C$29)^2)/(2*Inputs!$C$31^2))*EXP(-(((Inputs!$C$6)-Inputs!$C$30)^2)/(2*Inputs!$C$32^2))+-Inputs!$C$33*EXP(-(((((A6)-Inputs!$C$34)^2)+(((Inputs!$C$6)-Inputs!$C$35)^2))/(2*Inputs!$C$36^2)))+Inputs!$C$37*(0.55*SIN(2*PI()*(A6)/Inputs!$C$39)+0.35*COS(2*PI()*(Inputs!$C$6)/Inputs!$C$40)+0.2*SIN(2*PI()*((A6)+(Inputs!$C$6))/(0.5*(Inputs!$C$39+Inputs!$C$40))))+Inputs!$C$38*SIN(2*PI()*(A6)/Inputs!$C$39)*SIN(2*PI()*(Inputs!$C$6)/Inputs!$C$40)+-Inputs!$C$41*EXP(-(((Inputs!$C$6)-Inputs!$C$43)^2)/(2*Inputs!$C$44^2))*EXP(-(((A6)-Inputs!$C$42)^2)/(2*Inputs!$C$45^2))+Inputs!$C$48*(0.7*(0.45*SIN(2*PI()*(((A6)/Inputs!$C$49)+Inputs!$C$47*0.137))+0.35*COS(2*PI()*(((Inputs!$C$6)/Inputs!$C$50)+Inputs!$C$47*0.173))+0.2*SIN(2*PI()*(((A6)+(Inputs!$C$6))/(0.5*(Inputs!$C$49+Inputs!$C$50))+Inputs!$C$47*0.097)))+0.3*(2*((SIN(((A6)*12.9898+(Inputs!$C$6)*78.233+Inputs!$C$47*37.719))*43758.5453)-INT((SIN(((A6)*12.9898+(Inputs!$C$6)*78.233+Inputs!$C$47*37.719))*43758.5453)))-1))) -> 120.06953 | Z6: =B6-X6/1000 -> 403.70591 | AA6: =SQRT((Inputs!$C$52+B6)^2+(Inputs!$C$52+Y6/1000)^2-2*(Inputs!$C$52+B6)*(Inputs!$C$52+Y6/1000)*COS(SQRT(A6^2+Inputs!$C$6^2)/Inputs!$C$52)) -> 409.78995 | AB6: =(AA6-Z6)*1000 -> 6084.0409 | AC6: =AB6/Inputs!$C$12 -> 3418.0005 | AD6: =2*AB6/Inputs!$C$21*1000000 -> 40.588352 | AE6: =DEGREES(ATAN(H6/(B6-Y6/1000))) -> 8.8935825 | AF6: =DEGREES((2*PI()/Inputs!$C$13)*Inputs!$C$15*SIN(RADIANS(AE6))) -> 55.655902 | AG6: =(Z6/AA6)^4 -> 0.94192259 | AH6: =10*LOG10(AG6) -> -0.25984788 | AI6: =AC6-F6 -> -48.271678 | AJ6: =AD6-G6 -> -0.57322046 | AK6: =Y6-X6 -> 88.202616 | AL6: =1000*(AA7-AA5)/(A7-A5)*Inputs!$C$11 -> -1239.6019 | AM6: =-2*AL6/Inputs!$C$13 -> 495.84078 | AN6: =-2*AL6/Inputs!$C$14 -> 74.450567 | AO6: =ABS(AM6) -> 495.84078 | AP6: =ABS(AN6) -> 74.450567 | AQ6: =IF(OR(Inputs!$C$27=TRUE,Inputs!$C$27="TRUE",Inputs!$C$27=1),Inputs!$C$46/Inputs!$C$12,0) -> 42.134831 | AR6: =AC6-AQ6 -> 3375.8657 | AS6: =AC6+AQ6 -> 3460.1353
