Workbook

Sheet Dashboard
A1: Parabolic Motion Radar + Topography Parameter Model
A2: Use Inputs!C27 to apply/remove topography from the main outputs. The chart previews keep the same modeled surface visible so turning topography off does not erase the comparison. Inputs!C47 changes the terrain seed.
A4: Key Output Results
A5: Output | B5: Value | C5: Unit | D5: What it means
A6: Topography toggle | B6: =IF(OR(Inputs!$C$27=TRUE,Inputs!$C$27="TRUE",Inputs!$C$27=1),"Topography ON","Topography OFF") -> Topography OFF | D6: Set Inputs!C27 to TRUE to include terrain, or FALSE to return to a flat surface. Change Inputs!C47 to test a new terrain case.
A7: Flat apparent depth at mid-pass | B7: =Model_Data!F122 -> 438.47671 | C7: m | D7: Original flat-surface result.
A8: Topo apparent depth at mid-pass | B8: =Model_Data!AC122 -> 438.47671 | C8: m | D8: Apparent depth after terrain height changes the range geometry.
A9: Depth change from topography | B9: =Model_Data!AI122 -> 0 | C9: m | D9: Topo apparent depth minus flat apparent depth.
A10: Topo extra two-way delay | B10: =Model_Data!AD122 -> 5.2068591 | C10: us | D10: Two-way delay after topography is included.
A11: Topo VHF interferometric phase | B11: =Model_Data!AF122 -> 22.456183 | C11: deg | D11: VHF phase after topography changes the look geometry.
A12: Max target terrain height | B12: =MAX(Model_Data!Y2:Y242) -> 0 | C12: m | D12: Highest modeled terrain at the side-offset target path.
A13: Min target terrain height | B13: =MIN(Model_Data!Y2:Y242) -> 0 | C13: m | D13: Lowest modeled terrain at the side-offset target path.
A14: Max absolute topo depth change | B14: =MAX(MAX(Model_Data!AI2:AI242),-MIN(Model_Data!AI2:AI242)) -> 0 | C14: m | D14: Largest magnitude of topography-driven apparent-depth change.
A15: Max topo VHF Doppler magnitude | B15: =MAX(Model_Data!AO2:AO242) -> 443.43402 | C15: Hz | D15: Largest VHF Doppler after topography is included.
A16: Simple minimum PRF with topo | B16: =2*B15 -> 886.86803 | C16: Hz | D16: Twice max topo VHF Doppler, a simple no-alias floor.
A17: Topo depth uncertainty band | B17: =Model_Data!AQ122 -> 0 | C17: m | D17: Representative vertical uncertainty converted to apparent-depth uncertainty.
A19: PRF Choices
A20: PRF (Hz) | B20: Pulse interval (ms) | C20: Along-track spacing (m) | D20: Unambiguous range (km) | E20: Pulses in air at z0 | F20: Status
A21: =PRF_Results!A4 -> 50 | B21: =PRF_Results!B4 -> 20 | C21: =PRF_Results!C4 -> 80 | D21: =PRF_Results!D4 -> 2997.9246 | E21: =PRF_Results!E4 -> 0.13342564 | F21: =PRF_Results!F4 -> Below simple Doppler floor
A22: =PRF_Results!A5 -> 500 | B22: =PRF_Results!B5 -> 2 | C22: =PRF_Results!C5 -> 8 | D22: =PRF_Results!D5 -> 299.79246 | E22: =PRF_Results!E5 -> 1.3342564 | F22: =PRF_Results!F5 -> Below simple Doppler floor
A23: =PRF_Results!A6 -> 3000 | B23: =PRF_Results!B6 -> 0.33333333 | C23: =PRF_Results!C6 -> 1.3333333 | D23: =PRF_Results!D6 -> 49.96541 | E23: =PRF_Results!E6 -> 8.0055383 | F23: =PRF_Results!F6 -> OK for modeled topo VHF Doppler
A25: How to read this model
A26: The chain is: parabolic motion changes z(x); topography adds h(x,y); the radar then turns that real surface pattern into an apparent range/depth shift. Flat means flat surface, not straight spacecraft motion.
A57: Paper Pass Scenario Comparison
A58: Scenario | B58: Show | C58: z0 (km) | D58: Length (km) | E58: Edge alt (km) | F58: Mid depth (m) | G58: Max VHF (Hz) | H58: PRF floor (Hz) | I58: Basis
A59: =Inputs!G6 -> Current custom inputs | B59: TRUE | C59: =Inputs!H6 -> 400 | D59: =Inputs!J6-Inputs!I6 -> 120 | E59: =Inputs!M6 -> 404 | F59: =Scenario_Data!AF122 -> 438.47671 | G59: =MAX(MAX(Scenario_Data!AL2:AL242),-MIN(Scenario_Data!AL2:AL242)) -> 445.2313 | H59: =2*G59 -> 890.46259 | I59: Current editable
A60: =Inputs!G7 -> Paper low-altitude 800-km pass | B60: TRUE | C60: =Inputs!H7 -> 35 | D60: =Inputs!J7-Inputs!I7 -> 800 | E60: =Inputs!M7 -> 400 | F60: =Scenario_Data!AG122 -> 4500.9137 | G60: =MAX(MAX(Scenario_Data!AM2:AM242),-MIN(Scenario_Data!AM2:AM242)) -> 3193.006 | H60: =2*G60 -> 6386.012 | I60: 800 km below 400
A61: =Inputs!G8 -> Paper ice-ocean 1600-km pass | B61: TRUE | C61: =Inputs!H8 -> 35 | D61: =Inputs!J8-Inputs!I8 -> 1600 | E61: =Inputs!M8 -> 1000 | F61: =Scenario_Data!AH122 -> 4500.9137 | G61: =MAX(MAX(Scenario_Data!AN2:AN242),-MIN(Scenario_Data!AN2:AN242)) -> 4012.9011 | H61: =2*G61 -> 8025.8022 | I61: 1600 km below 1000
A62: =Inputs!G9 -> Paper operating 25-to-1000-km pass | B62: TRUE | C62: =Inputs!H9 -> 25 | D62: =Inputs!J9-Inputs!I9 -> 1600 | E62: =Inputs!M9 -> 1000 | F62: =Scenario_Data!AI122 -> 5817.6062 | G62: =MAX(MAX(Scenario_Data!AO2:AO242),-MIN(Scenario_Data!AO2:AO242)) -> 4044.1299 | H62: =2*G62 -> 8088.2598 | I62: 25-1000 km range
A63: Scenario note | B63: Paper numbers are converted into this workbook's simplified parabola so the outcomes can be compared. The paper states altitude ranges and groundtrack requirements, not an exact parabolic spacecraft trajectory.

Sheet Inputs
A1: Parabolic Motion Radar Model - Editable Inputs
A2: Change the yellow cells in column C for the custom model. Use the TRUE/FALSE scenario toggles at the right to overlay paper-derived pass cases on the Dashboard charts.
A4: Parameter | B4: Symbol | C4: Value | D4: Unit | E4: Notes | F4: Paper-Derived Pass Scenario Overlays
A5: Closest altitude | B5: z0 | C5: 400 | D5: km | E5: Altitude at closest approach. Change this to test other flyby heights. | F5: Show | G5: Scenario | H5: z0 | I5: x_min | J5: x_max | K5: x_edge | L5: Delta_z_edge | M5: Edge altitude | N5: Paper basis / meaning
A6: Side/cross-track offset | B6: y | C6: 25 | D6: km | E6: Horizontal offset of the modeled target from nadir. | F6: =Dashboard!B59 -> TRUE | G6: Current custom inputs | H6: =C5 -> 400 | I6: =C7 -> -60 | J6: =C8 -> 60 | K6: =C10 -> 60 | L6: =C9 -> 4 | M6: =C5+C9 -> 404 | N6: Your editable custom case from the left table. It remains the main model used by the topography dashboard.
A7: Along-track minimum | B7: x_min | C7: -60 | D7: km | E7: Left/start side of the modeled pass. | F7: =Dashboard!B60 -> TRUE | G7: Paper low-altitude 800-km pass | H7: 35 | I7: -400 | J7: 400 | K7: 400 | L7: 365 | M7: 400 | N7: Paper coverage requirement: groundtrack segments at least 800 km long below 400 km for most REASON datasets. This model makes that a parabola.
A8: Along-track maximum | B8: x_max | C8: 60 | D8: km | E8: Right/end side of the modeled pass. | F8: =Dashboard!B61 -> TRUE | G8: Paper ice-ocean 1600-km pass | H8: 35 | I8: -800 | J8: 800 | K8: 800 | L8: 965 | M8: 1000 | N8: Paper ice-ocean interface requirement: at least 1600 km below 1000 km. This model makes that a parabola.
A9: Altitude rise at edge | B9: Delta_z_edge | C9: 4 | D9: km | E9: How much altitude rises at +/- x_edge. | F9: =Dashboard!B62 -> TRUE | G9: Paper operating 25-to-1000-km pass | H9: 25 | I9: -800 | J9: 800 | K9: 800 | L9: 975 | M9: 1000 | N9: Paper instrument table lists operational altitudes of 25 km to 1000 km. This shows the lower-bound closest-approach case.
A10: Parabola edge location | B10: x_edge | C10: 60 | D10: km | E10: Controls curvature together with Delta_z_edge.
A11: Along-track speed | B11: v | C11: 4 | D11: km/s | E11: Used for range rate, Doppler, and pulse spacing. | F11: Scenario note | G11: The paper gives altitude ranges and required groundtrack lengths, not exact parabolic equations. These rows convert those paper values into the same simplified parabola equation so outcomes can be compared on one dashboard.
A12: Ice refractive index | B12: n | C12: 1.78 | E12: Used to convert extra slant path into apparent depth.
A13: VHF wavelength | B13: lambda_vhf | C13: 5 | D13: m | E13: REASON-like VHF wavelength.
A14: HF wavelength | B14: lambda_hf | C14: 33.3 | D14: m | E14: REASON-like HF wavelength.
A15: Interferometer baseline | B15: b | C15: 5 | D15: m | E15: Used for VHF phase estimate.
A16: VHF range resolution | B16: res_vhf | C16: 30 | D16: m | E16: Used for VHF apparent-depth uncertainty band.
A17: HF range resolution | B17: res_hf | C17: 300 | D17: m | E17: Used for HF apparent-depth uncertainty band.
A18: PRF choice 1 | B18: PRF_1 | C18: 50 | D18: Hz | E18: Example low PRF.
A19: PRF choice 2 | B19: PRF_2 | C19: 500 | D19: Hz | E19: Example medium PRF.
A20: PRF choice 3 | B20: PRF_3 | C20: 3000 | D20: Hz | E20: Example high PRF.
A21: Speed of light | B21: c | C21: 299792458 | D21: m/s | E21: Physical constant used for delay and timing.
A23: Model note | B23: The parabola is a simplified local path, not a real mission trajectory. Use it to see how geometry changes radar outputs.
A25: Representative Europa Topography Controls
A26: Parameter | B26: Symbol | C26: Value | D26: Unit | E26: Notes
A27: Topography enabled | B27: topography_on | C27: FALSE | E27: Dropdown-style toggle. TRUE adds terrain height to the radar geometry; FALSE returns to flat surface.
A28: Ridge height | B28: A_ridge | C28: 350 | D28: m | E28: Positive height for a representative double-ridge / raised band.
A29: Ridge center x | B29: ridge_x0 | C29: 0 | D29: km | E29: Along-track center of the ridge.
A30: Ridge center y | B30: ridge_y0 | C30: 25 | D30: km | E30: Cross-track center of the ridge.
A31: Ridge length sigma | B31: ridge_sigma_x | C31: 24 | D31: km | E31: Long direction of the ridge feature.
A32: Ridge width sigma | B32: ridge_sigma_y | C32: 3.5 | D32: km | E32: Narrow cross-track width of the ridge.
A33: Crater/depression depth | B33: D_crater | C33: 180 | D33: m | E33: Positive number becomes a negative depression in the surface model.
A34: Crater center x | B34: crater_x0 | C34: -18 | D34: km | E34: Along-track center of depression.
A35: Crater center y | B35: crater_y0 | C35: 8 | D35: km | E35: Cross-track center of depression.
A36: Crater width sigma | B36: crater_sigma | C36: 8 | D36: km | E36: Controls how broad the depression is.
A37: Chaos amplitude | B37: A_chaos | C37: 65 | D37: m | E37: Mixed sinusoidal terrain term for irregular chaos-like height variation.
A38: Fine roughness amplitude | B38: A_rough | C38: 35 | D38: m | E38: Smaller surface roughness term.
A39: Roughness wavelength x | B39: Lx | C39: 18 | D39: km | E39: Along-track roughness wavelength.
... A46: Terrain vertical uncertainty | B46: sigma_h | C46: 75 | D46: m | E46: Representative uncertainty band for the topographic height model.
A47: Terrain seed | B47: terrain_seed | C47: 7 | E47: Change this number to generate a different repeatable random-looking surface. Same seed gives the same graphs.
A48: Seeded random amplitude | B48: A_seeded | C48: 45 | D48: m | E48: Strength of the generated terrain added on top of the DEM-style surface.
A49: Seeded random scale x | B49: L_seed_x | C49: 12 | D49: km | E49: Along-track scale for seeded terrain waves.
...

Sheet Model_Data
A1: x_km | B1: z_km | C1: R_nadir_km | D1: R_off_km | E1: Delta_R_m | F1: apparent_depth_m | G1: extra_delay_us | H1: horizontal_offset_km | I1: look_angle_deg | J1: vhf_phase_deg | K1: relative_power | L1: power_dB | M1: dz_dx | N1: dz_dt_km_s | O1: range_rate_m_s | P1: vhf_doppler_hz | Q1: hf_doppler_hz | R1: vhf_band_low_m | S1: vhf_band_high_m | T1: hf_band_low_m | U1: hf_band_high_m | V1: abs_vhf_doppler_hz | W1: abs_hf_doppler_hz | X1: h_nadir_m | Y1: h_target_m | Z1: R_nadir_topo_km | AA1: R_off_topo_km | AB1: Delta_R_topo_m | AC1: apparent_depth_topo_m | AD1: extra_delay_topo_us | AE1: look_angle_topo_deg | AF1: vhf_phase_topo_deg | AG1: relative_power_topo | AH1: power_dB_topo | AI1: depth_change_topo_minus_flat_m | AJ1: delay_change_topo_minus_flat_us | AK1: target_minus_nadir_height_m | AL1: range_rate_topo_m_s | AM1: vhf_doppler_topo_hz | AN1: hf_doppler_topo_hz | AO1: abs_vhf_doppler_topo_hz | AP1: abs_hf_doppler_topo_hz | AQ1: topo_depth_uncertainty_m | AR1: topo_depth_low_m | AS1: topo_depth_high_m
A2: =Inputs!$C$7+0*(Inputs!$C$8-Inputs!$C$7)/240 -> -60 | B2: =Inputs!$C$5+Inputs!$C$9*(A2/Inputs!$C$10)^2 -> 404 | C2: =B2 -> 404 | D2: =SQRT(A2^2+Inputs!$C$6^2+B2^2) -> 409.19555 | E2: =(D2-C2)*1000 -> 5195.5523 | F2: =E2/Inputs!$C$12 -> 2918.8496 | G2: =2*E2/Inputs!$C$21*1000000 -> 34.660994 | H2: =SQRT(A2^2+Inputs!$C$6^2) -> 65 | I2: =DEGREES(ATAN(H2/B2)) -> 9.1400512 | J2: =DEGREES((2*PI()/Inputs!$C$13)*Inputs!$C$15*SIN(RADIANS(I2))) -> 57.185372 | K2: =(C2/D2)^4 -> 0.95017116 | L2: =10*LOG10(K2) -> -0.22198158 | M2: =2*(Inputs!$C$9/(Inputs!$C$10^2))*A2 -> -0.13333333 | N2: =M2*Inputs!$C$11 -> -0.53333333 | O2: =1000*((A2*Inputs!$C$11)+(B2*N2))/D2 -> -1113.0782 | P2: =-2*O2/Inputs!$C$13 -> 445.2313 | Q2: =-2*O2/Inputs!$C$14 -> 66.851546 | R2: =F2-Inputs!$C$16/2 -> 2903.8496 | S2: =F2+Inputs!$C$16/2 -> 2933.8496 | T2: =F2-Inputs!$C$17/2 -> 2768.8496 | U2: =F2+Inputs!$C$17/2 -> 3068.8496 | V2: =ABS(P2) -> 445.2313 | W2: =ABS(Q2) -> 66.851546 | X2: =IF(OR(Inputs!$C$27=TRUE,Inputs!$C$27="TRUE",Inputs!$C$27=1),1,0)*(Inputs!$C$51*(115*EXP(-(((0)-25)^2)/(4.5^2))+70*EXP(-(((0)+38)^2)/(7^2))*(0.55+0.45*SIN(2*PI()*(A2)/45))+24*SIN(2*PI()*(0)/9+(A2)/18)*EXP(-(((0)+5)^2)/(22^2))+18*SIN(2*PI()*(A2)/70))+Inputs!$C$28*EXP(-(((A2)-Inputs!$C$29)^2)/(2*Inputs!$C$31^2))*EXP(-(((0)-Inputs!$C$30)^2)/(2*Inputs!$C$32^2))+-Inputs!$C$33*EXP(-(((((A2)-Inputs!$C$34)^2)+(((0)-Inputs!$C$35)^2))/(2*Inputs!$C$36^2)))+Inputs!$C$37*(0.55*SIN(2*PI()*(A2)/Inputs!$C$39)+0.35*COS(2*PI()*(0)/Inputs!$C$40)+0.2*SIN(2*PI()*((A2)+(0))/(0.5*(Inputs!$C$39+Inputs!$C$40))))+Inputs!$C$38*SIN(2*PI()*(A2)/Inputs!$C$39)*SIN(2*PI()*(0)/Inputs!$C$40)+-Inputs!$C$41*EXP(-(((0)-Inputs!$C$43)^2)/(2*Inputs!$C$44^2))*EXP(-(((A2)-Inputs!$C$42)^2)/(2*Inputs!$C$45^2))+Inputs!$C$48*(0.7*(0.45*SIN(2*PI()*(((A2)/Inputs!$C$49)+Inputs!$C$47*0.137))+0.35*COS(2*PI()*(((0)/Inputs!$C$50)+Inputs!$C$47*0.173))+0.2*SIN(2*PI()*(((A2)+(0))/(0.5*(Inputs!$C$49+Inputs!$C$50))+Inputs!$C$47*0.097)))+0.3*(2*((SIN(((A2)*12.9898+(0)*78.233+Inputs!$C$47*37.719))*43758.5453)-INT((SIN(((A2)*12.9898+(0)*78.233+Inputs!$C$47*37.719))*43758.5453)))-1))) -> 0 | Y2: =IF(OR(Inputs!$C$27=TRUE,Inputs!$C$27="TRUE",Inputs!$C$27=1),1,0)*(Inputs!$C$51*(115*EXP(-(((Inputs!$C$6)-25)^2)/(4.5^2))+70*EXP(-(((Inputs!$C$6)+38)^2)/(7^2))*(0.55+0.45*SIN(2*PI()*(A2)/45))+24*SIN(2*PI()*(Inputs!$C$6)/9+(A2)/18)*EXP(-(((Inputs!$C$6)+5)^2)/(22^2))+18*SIN(2*PI()*(A2)/70))+Inputs!$C$28*EXP(-(((A2)-Inputs!$C$29)^2)/(2*Inputs!$C$31^2))*EXP(-(((Inputs!$C$6)-Inputs!$C$30)^2)/(2*Inputs!$C$32^2))+-Inputs!$C$33*EXP(-(((((A2)-Inputs!$C$34)^2)+(((Inputs!$C$6)-Inputs!$C$35)^2))/(2*Inputs!$C$36^2)))+Inputs!$C$37*(0.55*SIN(2*PI()*(A2)/Inputs!$C$39)+0.35*COS(2*PI()*(Inputs!$C$6)/Inputs!$C$40)+0.2*SIN(2*PI()*((A2)+(Inputs!$C$6))/(0.5*(Inputs!$C$39+Inputs!$C$40))))+Inputs!$C$38*SIN(2*PI()*(A2)/Inputs!$C$39)*SIN(2*PI()*(Inputs!$C$6)/Inputs!$C$40)+-Inputs!$C$41*EXP(-(((Inputs!$C$6)-Inputs!$C$43)^2)/(2*Inputs!$C$44^2))*EXP(-(((A2)-Inputs!$C$42)^2)/(2*Inputs!$C$45^2))+Inputs!$C$48*(0.7*(0.45*SIN(2*PI()*(((A2)/Inputs!$C$49)+Inputs!$C$47*0.137))+0.35*COS(2*PI()*(((Inputs!$C$6)/Inputs!$C$50)+Inputs!$C$47*0.173))+0.2*SIN(2*PI()*(((A2)+(Inputs!$C$6))/(0.5*(Inputs!$C$49+Inputs!$C$50))+Inputs!$C$47*0.097)))+0.3*(2*((SIN(((A2)*12.9898+(Inputs!$C$6)*78.233+Inputs!$C$47*37.719))*43758.5453)-INT((SIN(((A2)*12.9898+(Inputs!$C$6)*78.233+Inputs!$C$47*37.719))*43758.5453)))-1))) -> 0 | Z2: =B2-X2/1000 -> 404 | AA2: =SQRT(A2^2+Inputs!$C$6^2+(B2-Y2/1000)^2) -> 409.19555 | AB2: =(AA2-Z2)*1000 -> 5195.5523 | AC2: =AB2/Inputs!$C$12 -> 2918.8496 | AD2: =2*AB2/Inputs!$C$21*1000000 -> 34.660994 | AE2: =DEGREES(ATAN(H2/(B2-Y2/1000))) -> 9.1400512 | AF2: =DEGREES((2*PI()/Inputs!$C$13)*Inputs!$C$15*SIN(RADIANS(AE2))) -> 57.185372 | AG2: =(Z2/AA2)^4 -> 0.95017116 | AH2: =10*LOG10(AG2) -> -0.22198158 | AI2: =AC2-F2 -> 0 | AJ2: =AD2-G2 -> 0 | AK2: =Y2-X2 -> 0 | AL2: =1000*(AA3-AA2)/(A3-A2)*Inputs!$C$11 -> -1108.585 | AM2: =-2*AL2/Inputs!$C$13 -> 443.43402 | AN2: =-2*AL2/Inputs!$C$14 -> 66.581684 | AO2: =ABS(AM2) -> 443.43402 | AP2: =ABS(AN2) -> 66.581684 | AQ2: =IF(OR(Inputs!$C$27=TRUE,Inputs!$C$27="TRUE",Inputs!$C$27=1),Inputs!$C$46/Inputs!$C$12,0) -> 0 | AR2: =AC2-AQ2 -> 2918.8496 | AS2: =AC2+AQ2 -> 2918.8496
A3: =Inputs!$C$7+1*(Inputs!$C$8-Inputs!$C$7)/240 -> -59.5 | B3: =Inputs!$C$5+Inputs!$C$9*(A3/Inputs!$C$10)^2 -> 403.93361 | C3: =B3 -> 403.93361 | D3: =SQRT(A3^2+Inputs!$C$6^2+B3^2) -> 409.05698 | E3: =(D3-C3)*1000 -> 5123.368 | F3: =E3/Inputs!$C$12 -> 2878.2966 | G3: =2*E3/Inputs!$C$21*1000000 -> 34.179432 | H3: =SQRT(A3^2+Inputs!$C$6^2) -> 64.538748 | I3: =DEGREES(ATAN(H3/B3)) -> 9.077742 | J3: =DEGREES((2*PI()/Inputs!$C$13)*Inputs!$C$15*SIN(RADIANS(I3))) -> 56.798809 | K3: =(C3/D3)^4 -> 0.95083408 | L3: =10*LOG10(K3) -> -0.21895259 | M3: =2*(Inputs!$C$9/(Inputs!$C$10^2))*A3 -> -0.13222222 | N3: =M3*Inputs!$C$11 -> -0.52888889 | O3: =1000*((A3*Inputs!$C$11)+(B3*N3))/D3 -> -1104.0907 | P3: =-2*O3/Inputs!$C$13 -> 441.63627 | Q3: =-2*O3/Inputs!$C$14 -> 66.311753 | R3: =F3-Inputs!$C$16/2 -> 2863.2966 | S3: =F3+Inputs!$C$16/2 -> 2893.2966 | T3: =F3-Inputs!$C$17/2 -> 2728.2966 | U3: =F3+Inputs!$C$17/2 -> 3028.2966 | V3: =ABS(P3) -> 441.63627 | W3: =ABS(Q3) -> 66.311753 | X3: =IF(OR(Inputs!$C$27=TRUE,Inputs!$C$27="TRUE",Inputs!$C$27=1),1,0)*(Inputs!$C$51*(115*EXP(-(((0)-25)^2)/(4.5^2))+70*EXP(-(((0)+38)^2)/(7^2))*(0.55+0.45*SIN(2*PI()*(A3)/45))+24*SIN(2*PI()*(0)/9+(A3)/18)*EXP(-(((0)+5)^2)/(22^2))+18*SIN(2*PI()*(A3)/70))+Inputs!$C$28*EXP(-(((A3)-Inputs!$C$29)^2)/(2*Inputs!$C$31^2))*EXP(-(((0)-Inputs!$C$30)^2)/(2*Inputs!$C$32^2))+-Inputs!$C$33*EXP(-(((((A3)-Inputs!$C$34)^2)+(((0)-Inputs!$C$35)^2))/(2*Inputs!$C$36^2)))+Inputs!$C$37*(0.55*SIN(2*PI()*(A3)/Inputs!$C$39)+0.35*COS(2*PI()*(0)/Inputs!$C$40)+0.2*SIN(2*PI()*((A3)+(0))/(0.5*(Inputs!$C$39+Inputs!$C$40))))+Inputs!$C$38*SIN(2*PI()*(A3)/Inputs!$C$39)*SIN(2*PI()*(0)/Inputs!$C$40)+-Inputs!$C$41*EXP(-(((0)-Inputs!$C$43)^2)/(2*Inputs!$C$44^2))*EXP(-(((A3)-Inputs!$C$42)^2)/(2*Inputs!$C$45^2))+Inputs!$C$48*(0.7*(0.45*SIN(2*PI()*(((A3)/Inputs!$C$49)+Inputs!$C$47*0.137))+0.35*COS(2*PI()*(((0)/Inputs!$C$50)+Inputs!$C$47*0.173))+0.2*SIN(2*PI()*(((A3)+(0))/(0.5*(Inputs!$C$49+Inputs!$C$50))+Inputs!$C$47*0.097)))+0.3*(2*((SIN(((A3)*12.9898+(0)*78.233+Inputs!$C$47*37.719))*43758.5453)-INT((SIN(((A3)*12.9898+(0)*78.233+Inputs!$C$47*37.719))*43758.5453)))-1))) -> 0 | Y3: =IF(OR(Inputs!$C$27=TRUE,Inputs!$C$27="TRUE",Inputs!$C$27=1),1,0)*(Inputs!$C$51*(115*EXP(-(((Inputs!$C$6)-25)^2)/(4.5^2))+70*EXP(-(((Inputs!$C$6)+38)^2)/(7^2))*(0.55+0.45*SIN(2*PI()*(A3)/45))+24*SIN(2*PI()*(Inputs!$C$6)/9+(A3)/18)*EXP(-(((Inputs!$C$6)+5)^2)/(22^2))+18*SIN(2*PI()*(A3)/70))+Inputs!$C$28*EXP(-(((A3)-Inputs!$C$29)^2)/(2*Inputs!$C$31^2))*EXP(-(((Inputs!$C$6)-Inputs!$C$30)^2)/(2*Inputs!$C$32^2))+-Inputs!$C$33*EXP(-(((((A3)-Inputs!$C$34)^2)+(((Inputs!$C$6)-Inputs!$C$35)^2))/(2*Inputs!$C$36^2)))+Inputs!$C$37*(0.55*SIN(2*PI()*(A3)/Inputs!$C$39)+0.35*COS(2*PI()*(Inputs!$C$6)/Inputs!$C$40)+0.2*SIN(2*PI()*((A3)+(Inputs!$C$6))/(0.5*(Inputs!$C$39+Inputs!$C$40))))+Inputs!$C$38*SIN(2*PI()*(A3)/Inputs!$C$39)*SIN(2*PI()*(Inputs!$C$6)/Inputs!$C$40)+-Inputs!$C$41*EXP(-(((Inputs!$C$6)-Inputs!$C$43)^2)/(2*Inputs!$C$44^2))*EXP(-(((A3)-Inputs!$C$42)^2)/(2*Inputs!$C$45^2))+Inputs!$C$48*(0.7*(0.45*SIN(2*PI()*(((A3)/Inputs!$C$49)+Inputs!$C$47*0.137))+0.35*COS(2*PI()*(((Inputs!$C$6)/Inputs!$C$50)+Inputs!$C$47*0.173))+0.2*SIN(2*PI()*(((A3)+(Inputs!$C$6))/(0.5*(Inputs!$C$49+Inputs!$C$50))+Inputs!$C$47*0.097)))+0.3*(2*((SIN(((A3)*12.9898+(Inputs!$C$6)*78.233+Inputs!$C$47*37.719))*43758.5453)-INT((SIN(((A3)*12.9898+(Inputs!$C$6)*78.233+Inputs!$C$47*37.719))*43758.5453)))-1))) -> 0 | Z3: =B3-X3/1000 -> 403.93361 | AA3: =SQRT(A3^2+Inputs!$C$6^2+(B3-Y3/1000)^2) -> 409.05698 | AB3: =(AA3-Z3)*1000 -> 5123.368 | AC3: =AB3/Inputs!$C$12 -> 2878.2966 | AD3: =2*AB3/Inputs!$C$21*1000000 -> 34.179432 | AE3: =DEGREES(ATAN(H3/(B3-Y3/1000))) -> 9.077742 | AF3: =DEGREES((2*PI()/Inputs!$C$13)*Inputs!$C$15*SIN(RADIANS(AE3))) -> 56.798809 | AG3: =(Z3/AA3)^4 -> 0.95083408 | AH3: =10*LOG10(AG3) -> -0.21895259 | AI3: =AC3-F3 -> 0 | AJ3: =AD3-G3 -> 0 | AK3: =Y3-X3 -> 0 | AL3: =1000*(AA4-AA2)/(A4-A2)*Inputs!$C$11 -> -1104.0895 | AM3: =-2*AL3/Inputs!$C$13 -> 441.63581 | AN3: =-2*AL3/Inputs!$C$14 -> 66.311683 | AO3: =ABS(AM3) -> 441.63581 | AP3: =ABS(AN3) -> 66.311683 | AQ3: =IF(OR(Inputs!$C$27=TRUE,Inputs!$C$27="TRUE",Inputs!$C$27=1),Inputs!$C$46/Inputs!$C$12,0) -> 0 | AR3: =AC3-AQ3 -> 2878.2966 | AS3: =AC3+AQ3 -> 2878.2966
A4: =Inputs!$C$7+2*(Inputs!$C$8-Inputs!$C$7)/240 -> -59 | B4: =Inputs!$C$5+Inputs!$C$9*(A4/Inputs!$C$10)^2 -> 403.86778 | C4: =B4 -> 403.86778 | D4: =SQRT(A4^2+Inputs!$C$6^2+B4^2) -> 408.91953 | E4: =(D4-C4)*1000 -> 5051.7521 | F4: =E4/Inputs!$C$12 -> 2838.063 | G4: =2*E4/Inputs!$C$21*1000000 -> 33.701662 | H4: =SQRT(A4^2+Inputs!$C$6^2) -> 64.078077 | I4: =DEGREES(ATAN(H4/B4)) -> 9.0154589 | J4: =DEGREES((2*PI()/Inputs!$C$13)*Inputs!$C$15*SIN(RADIANS(I4))) -> 56.412341 | K4: =(C4/D4)^4 -> 0.95149258 | L4: =10*LOG10(K4) -> -0.21594592 | M4: =2*(Inputs!$C$9/(Inputs!$C$10^2))*A4 -> -0.13111111 | N4: =M4*Inputs!$C$11 -> -0.52444444 | O4: =1000*((A4*Inputs!$C$11)+(B4*N4))/D4 -> -1095.0962 | P4: =-2*O4/Inputs!$C$13 -> 438.03847 | Q4: =-2*O4/Inputs!$C$14 -> 65.771542 | R4: =F4-Inputs!$C$16/2 -> 2823.063 | S4: =F4+Inputs!$C$16/2 -> 2853.063 | T4: =F4-Inputs!$C$17/2 -> 2688.063 | U4: =F4+Inputs!$C$17/2 -> 2988.063 | V4: =ABS(P4) -> 438.03847 | W4: =ABS(Q4) -> 65.771542 | X4: =IF(OR(Inputs!$C$27=TRUE,Inputs!$C$27="TRUE",Inputs!$C$27=1),1,0)*(Inputs!$C$51*(115*EXP(-(((0)-25)^2)/(4.5^2))+70*EXP(-(((0)+38)^2)/(7^2))*(0.55+0.45*SIN(2*PI()*(A4)/45))+24*SIN(2*PI()*(0)/9+(A4)/18)*EXP(-(((0)+5)^2)/(22^2))+18*SIN(2*PI()*(A4)/70))+Inputs!$C$28*EXP(-(((A4)-Inputs!$C$29)^2)/(2*Inputs!$C$31^2))*EXP(-(((0)-Inputs!$C$30)^2)/(2*Inputs!$C$32^2))+-Inputs!$C$33*EXP(-(((((A4)-Inputs!$C$34)^2)+(((0)-Inputs!$C$35)^2))/(2*Inputs!$C$36^2)))+Inputs!$C$37*(0.55*SIN(2*PI()*(A4)/Inputs!$C$39)+0.35*COS(2*PI()*(0)/Inputs!$C$40)+0.2*SIN(2*PI()*((A4)+(0))/(0.5*(Inputs!$C$39+Inputs!$C$40))))+Inputs!$C$38*SIN(2*PI()*(A4)/Inputs!$C$39)*SIN(2*PI()*(0)/Inputs!$C$40)+-Inputs!$C$41*EXP(-(((0)-Inputs!$C$43)^2)/(2*Inputs!$C$44^2))*EXP(-(((A4)-Inputs!$C$42)^2)/(2*Inputs!$C$45^2))+Inputs!$C$48*(0.7*(0.45*SIN(2*PI()*(((A4)/Inputs!$C$49)+Inputs!$C$47*0.137))+0.35*COS(2*PI()*(((0)/Inputs!$C$50)+Inputs!$C$47*0.173))+0.2*SIN(2*PI()*(((A4)+(0))/(0.5*(Inputs!$C$49+Inputs!$C$50))+Inputs!$C$47*0.097)))+0.3*(2*((SIN(((A4)*12.9898+(0)*78.233+Inputs!$C$47*37.719))*43758.5453)-INT((SIN(((A4)*12.9898+(0)*78.233+Inputs!$C$47*37.719))*43758.5453)))-1))) -> 0 | Y4: =IF(OR(Inputs!$C$27=TRUE,Inputs!$C$27="TRUE",Inputs!$C$27=1),1,0)*(Inputs!$C$51*(115*EXP(-(((Inputs!$C$6)-25)^2)/(4.5^2))+70*EXP(-(((Inputs!$C$6)+38)^2)/(7^2))*(0.55+0.45*SIN(2*PI()*(A4)/45))+24*SIN(2*PI()*(Inputs!$C$6)/9+(A4)/18)*EXP(-(((Inputs!$C$6)+5)^2)/(22^2))+18*SIN(2*PI()*(A4)/70))+Inputs!$C$28*EXP(-(((A4)-Inputs!$C$29)^2)/(2*Inputs!$C$31^2))*EXP(-(((Inputs!$C$6)-Inputs!$C$30)^2)/(2*Inputs!$C$32^2))+-Inputs!$C$33*EXP(-(((((A4)-Inputs!$C$34)^2)+(((Inputs!$C$6)-Inputs!$C$35)^2))/(2*Inputs!$C$36^2)))+Inputs!$C$37*(0.55*SIN(2*PI()*(A4)/Inputs!$C$39)+0.35*COS(2*PI()*(Inputs!$C$6)/Inputs!$C$40)+0.2*SIN(2*PI()*((A4)+(Inputs!$C$6))/(0.5*(Inputs!$C$39+Inputs!$C$40))))+Inputs!$C$38*SIN(2*PI()*(A4)/Inputs!$C$39)*SIN(2*PI()*(Inputs!$C$6)/Inputs!$C$40)+-Inputs!$C$41*EXP(-(((Inputs!$C$6)-Inputs!$C$43)^2)/(2*Inputs!$C$44^2))*EXP(-(((A4)-Inputs!$C$42)^2)/(2*Inputs!$C$45^2))+Inputs!$C$48*(0.7*(0.45*SIN(2*PI()*(((A4)/Inputs!$C$49)+Inputs!$C$47*0.137))+0.35*COS(2*PI()*(((Inputs!$C$6)/Inputs!$C$50)+Inputs!$C$47*0.173))+0.2*SIN(2*PI()*(((A4)+(Inputs!$C$6))/(0.5*(Inputs!$C$49+Inputs!$C$50))+Inputs!$C$47*0.097)))+0.3*(2*((SIN(((A4)*12.9898+(Inputs!$C$6)*78.233+Inputs!$C$47*37.719))*43758.5453)-INT((SIN(((A4)*12.9898+(Inputs!$C$6)*78.233+Inputs!$C$47*37.719))*43758.5453)))-1))) -> 0 | Z4: =B4-X4/1000 -> 403.86778 | AA4: =SQRT(A4^2+Inputs!$C$6^2+(B4-Y4/1000)^2) -> 408.91953 | AB4: =(AA4-Z4)*1000 -> 5051.7521 | AC4: =AB4/Inputs!$C$12 -> 2838.063 | AD4: =2*AB4/Inputs!$C$21*1000000 -> 33.701662 | AE4: =DEGREES(ATAN(H4/(B4-Y4/1000))) -> 9.0154589 | AF4: =DEGREES((2*PI()/Inputs!$C$13)*Inputs!$C$15*SIN(RADIANS(AE4))) -> 56.412341 | AG4: =(Z4/AA4)^4 -> 0.95149258 | AH4: =10*LOG10(AG4) -> -0.21594592 | AI4: =AC4-F4 -> 0 | AJ4: =AD4-G4 -> 0 | AK4: =Y4-X4 -> 0 | AL4: =1000*(AA5-AA3)/(A5-A3)*Inputs!$C$11 -> -1095.095 | AM4: =-2*AL4/Inputs!$C$13 -> 438.03801 | AN4: =-2*AL4/Inputs!$C$14 -> 65.771473 | AO4: =ABS(AM4) -> 438.03801 | AP4: =ABS(AN4) -> 65.771473 | AQ4: =IF(OR(Inputs!$C$27=TRUE,Inputs!$C$27="TRUE",Inputs!$C$27=1),Inputs!$C$46/Inputs!$C$12,0) -> 0 | AR4: =AC4-AQ4 -> 2838.063 | AS4: =AC4+AQ4 -> 2838.063
A5: =Inputs!$C$7+3*(Inputs!$C$8-Inputs!$C$7)/240 -> -58.5 | B5: =Inputs!$C$5+Inputs!$C$9*(A5/Inputs!$C$10)^2 -> 403.8025 | C5: =B5 -> 403.8025 | D5: =SQRT(A5^2+Inputs!$C$6^2+B5^2) -> 408.78321 | E5: =(D5-C5)*1000 -> 4980.7054 | F5: =E5/Inputs!$C$12 -> 2798.1491 | G5: =2*E5/Inputs!$C$21*1000000 -> 33.22769 | H5: =SQRT(A5^2+Inputs!$C$6^2) -> 63.618001 | I5: =DEGREES(ATAN(H5/B5)) -> 8.9532041 | J5: =DEGREES((2*PI()/Inputs!$C$13)*Inputs!$C$15*SIN(RADIANS(I5))) -> 56.025981 | K5: =(C5/D5)^4 -> 0.95214663 | L5: =10*LOG10(K5) -> -0.21296165 | M5: =2*(Inputs!$C$9/(Inputs!$C$10^2))*A5 -> -0.13 | N5: =M5*Inputs!$C$11 -> -0.52 | O5: =1000*((A5*Inputs!$C$11)+(B5*N5))/D5 -> -1086.0948 | P5: =-2*O5/Inputs!$C$13 -> 434.43791 | Q5: =-2*O5/Inputs!$C$14 -> 65.230917 | R5: =F5-Inputs!$C$16/2 -> 2783.1491 | S5: =F5+Inputs!$C$16/2 -> 2813.1491 | T5: =F5-Inputs!$C$17/2 -> 2648.1491 | U5: =F5+Inputs!$C$17/2 -> 2948.1491 | V5: =ABS(P5) -> 434.43791 | W5: =ABS(Q5) -> 65.230917 | X5: =IF(OR(Inputs!$C$27=TRUE,Inputs!$C$27="TRUE",Inputs!$C$27=1),1,0)*(Inputs!$C$51*(115*EXP(-(((0)-25)^2)/(4.5^2))+70*EXP(-(((0)+38)^2)/(7^2))*(0.55+0.45*SIN(2*PI()*(A5)/45))+24*SIN(2*PI()*(0)/9+(A5)/18)*EXP(-(((0)+5)^2)/(22^2))+18*SIN(2*PI()*(A5)/70))+Inputs!$C$28*EXP(-(((A5)-Inputs!$C$29)^2)/(2*Inputs!$C$31^2))*EXP(-(((0)-Inputs!$C$30)^2)/(2*Inputs!$C$32^2))+-Inputs!$C$33*EXP(-(((((A5)-Inputs!$C$34)^2)+(((0)-Inputs!$C$35)^2))/(2*Inputs!$C$36^2)))+Inputs!$C$37*(0.55*SIN(2*PI()*(A5)/Inputs!$C$39)+0.35*COS(2*PI()*(0)/Inputs!$C$40)+0.2*SIN(2*PI()*((A5)+(0))/(0.5*(Inputs!$C$39+Inputs!$C$40))))+Inputs!$C$38*SIN(2*PI()*(A5)/Inputs!$C$39)*SIN(2*PI()*(0)/Inputs!$C$40)+-Inputs!$C$41*EXP(-(((0)-Inputs!$C$43)^2)/(2*Inputs!$C$44^2))*EXP(-(((A5)-Inputs!$C$42)^2)/(2*Inputs!$C$45^2))+Inputs!$C$48*(0.7*(0.45*SIN(2*PI()*(((A5)/Inputs!$C$49)+Inputs!$C$47*0.137))+0.35*COS(2*PI()*(((0)/Inputs!$C$50)+Inputs!$C$47*0.173))+0.2*SIN(2*PI()*(((A5)+(0))/(0.5*(Inputs!$C$49+Inputs!$C$50))+Inputs!$C$47*0.097)))+0.3*(2*((SIN(((A5)*12.9898+(0)*78.233+Inputs!$C$47*37.719))*43758.5453)-INT((SIN(((A5)*12.9898+(0)*78.233+Inputs!$C$47*37.719))*43758.5453)))-1))) -> 0 | Y5: =IF(OR(Inputs!$C$27=TRUE,Inputs!$C$27="TRUE",Inputs!$C$27=1),1,0)*(Inputs!$C$51*(115*EXP(-(((Inputs!$C$6)-25)^2)/(4.5^2))+70*EXP(-(((Inputs!$C$6)+38)^2)/(7^2))*(0.55+0.45*SIN(2*PI()*(A5)/45))+24*SIN(2*PI()*(Inputs!$C$6)/9+(A5)/18)*EXP(-(((Inputs!$C$6)+5)^2)/(22^2))+18*SIN(2*PI()*(A5)/70))+Inputs!$C$28*EXP(-(((A5)-Inputs!$C$29)^2)/(2*Inputs!$C$31^2))*EXP(-(((Inputs!$C$6)-Inputs!$C$30)^2)/(2*Inputs!$C$32^2))+-Inputs!$C$33*EXP(-(((((A5)-Inputs!$C$34)^2)+(((Inputs!$C$6)-Inputs!$C$35)^2))/(2*Inputs!$C$36^2)))+Inputs!$C$37*(0.55*SIN(2*PI()*(A5)/Inputs!$C$39)+0.35*COS(2*PI()*(Inputs!$C$6)/Inputs!$C$40)+0.2*SIN(2*PI()*((A5)+(Inputs!$C$6))/(0.5*(Inputs!$C$39+Inputs!$C$40))))+Inputs!$C$38*SIN(2*PI()*(A5)/Inputs!$C$39)*SIN(2*PI()*(Inputs!$C$6)/Inputs!$C$40)+-Inputs!$C$41*EXP(-(((Inputs!$C$6)-Inputs!$C$43)^2)/(2*Inputs!$C$44^2))*EXP(-(((A5)-Inputs!$C$42)^2)/(2*Inputs!$C$45^2))+Inputs!$C$48*(0.7*(0.45*SIN(2*PI()*(((A5)/Inputs!$C$49)+Inputs!$C$47*0.137))+0.35*COS(2*PI()*(((Inputs!$C$6)/Inputs!$C$50)+Inputs!$C$47*0.173))+0.2*SIN(2*PI()*(((A5)+(Inputs!$C$6))/(0.5*(Inputs!$C$49+Inputs!$C$50))+Inputs!$C$47*0.097)))+0.3*(2*((SIN(((A5)*12.9898+(Inputs!$C$6)*78.233+Inputs!$C$47*37.719))*43758.5453)-INT((SIN(((A5)*12.9898+(Inputs!$C$6)*78.233+Inputs!$C$47*37.719))*43758.5453)))-1))) -> 0 | Z5: =B5-X5/1000 -> 403.8025 | AA5: =SQRT(A5^2+Inputs!$C$6^2+(B5-Y5/1000)^2) -> 408.78321 | AB5: =(AA5-Z5)*1000 -> 4980.7054 | AC5: =AB5/Inputs!$C$12 -> 2798.1491 | AD5: =2*AB5/Inputs!$C$21*1000000 -> 33.22769 | AE5: =DEGREES(ATAN(H5/(B5-Y5/1000))) -> 8.9532041 | AF5: =DEGREES((2*PI()/Inputs!$C$13)*Inputs!$C$15*SIN(RADIANS(AE5))) -> 56.025981 | AG5: =(Z5/AA5)^4 -> 0.95214663 | AH5: =10*LOG10(AG5) -> -0.21296165 | AI5: =AC5-F5 -> 0 | AJ5: =AD5-G5 -> 0 | AK5: =Y5-X5 -> 0 | AL5: =1000*(AA6-AA4)/(A6-A4)*Inputs!$C$11 -> -1086.0936 | AM5: =-2*AL5/Inputs!$C$13 -> 434.43745 | AN5: =-2*AL5/Inputs!$C$14 -> 65.230848 | AO5: =ABS(AM5) -> 434.43745 | AP5: =ABS(AN5) -> 65.230848 | AQ5: =IF(OR(Inputs!$C$27=TRUE,Inputs!$C$27="TRUE",Inputs!$C$27=1),Inputs!$C$46/Inputs!$C$12,0) -> 0 | AR5: =AC5-AQ5 -> 2798.1491 | AS5: =AC5+AQ5 -> 2798.1491
A6: =Inputs!$C$7+4*(Inputs!$C$8-Inputs!$C$7)/240 -> -58 | B6: =Inputs!$C$5+Inputs!$C$9*(A6/Inputs!$C$10)^2 -> 403.73778 | C6: =B6 -> 403.73778 | D6: =SQRT(A6^2+Inputs!$C$6^2+B6^2) -> 408.64801 | E6: =(D6-C6)*1000 -> 4910.2287 | F6: =E6/Inputs!$C$12 -> 2758.5555 | G6: =2*E6/Inputs!$C$21*1000000 -> 32.75752 | H6: =SQRT(A6^2+Inputs!$C$6^2) -> 63.158531 | I6: =DEGREES(ATAN(H6/B6)) -> 8.8909798 | J6: =DEGREES((2*PI()/Inputs!$C$13)*Inputs!$C$15*SIN(RADIANS(I6))) -> 55.639745 | K6: =(C6/D6)^4 -> 0.9527962 | L6: =10*LOG10(K6) -> -0.20999985 | M6: =2*(Inputs!$C$9/(Inputs!$C$10^2))*A6 -> -0.12888889 | N6: =M6*Inputs!$C$11 -> -0.51555556 | O6: =1000*((A6*Inputs!$C$11)+(B6*N6))/D6 -> -1077.0865 | P6: =-2*O6/Inputs!$C$13 -> 430.8346 | Q6: =-2*O6/Inputs!$C$14 -> 64.68988 | R6: =F6-Inputs!$C$16/2 -> 2743.5555 | S6: =F6+Inputs!$C$16/2 -> 2773.5555 | T6: =F6-Inputs!$C$17/2 -> 2608.5555 | U6: =F6+Inputs!$C$17/2 -> 2908.5555 | V6: =ABS(P6) -> 430.8346 | W6: =ABS(Q6) -> 64.68988 | X6: =IF(OR(Inputs!$C$27=TRUE,Inputs!$C$27="TRUE",Inputs!$C$27=1),1,0)*(Inputs!$C$51*(115*EXP(-(((0)-25)^2)/(4.5^2))+70*EXP(-(((0)+38)^2)/(7^2))*(0.55+0.45*SIN(2*PI()*(A6)/45))+24*SIN(2*PI()*(0)/9+(A6)/18)*EXP(-(((0)+5)^2)/(22^2))+18*SIN(2*PI()*(A6)/70))+Inputs!$C$28*EXP(-(((A6)-Inputs!$C$29)^2)/(2*Inputs!$C$31^2))*EXP(-(((0)-Inputs!$C$30)^2)/(2*Inputs!$C$32^2))+-Inputs!$C$33*EXP(-(((((A6)-Inputs!$C$34)^2)+(((0)-Inputs!$C$35)^2))/(2*Inputs!$C$36^2)))+Inputs!$C$37*(0.55*SIN(2*PI()*(A6)/Inputs!$C$39)+0.35*COS(2*PI()*(0)/Inputs!$C$40)+0.2*SIN(2*PI()*((A6)+(0))/(0.5*(Inputs!$C$39+Inputs!$C$40))))+Inputs!$C$38*SIN(2*PI()*(A6)/Inputs!$C$39)*SIN(2*PI()*(0)/Inputs!$C$40)+-Inputs!$C$41*EXP(-(((0)-Inputs!$C$43)^2)/(2*Inputs!$C$44^2))*EXP(-(((A6)-Inputs!$C$42)^2)/(2*Inputs!$C$45^2))+Inputs!$C$48*(0.7*(0.45*SIN(2*PI()*(((A6)/Inputs!$C$49)+Inputs!$C$47*0.137))+0.35*COS(2*PI()*(((0)/Inputs!$C$50)+Inputs!$C$47*0.173))+0.2*SIN(2*PI()*(((A6)+(0))/(0.5*(Inputs!$C$49+Inputs!$C$50))+Inputs!$C$47*0.097)))+0.3*(2*((SIN(((A6)*12.9898+(0)*78.233+Inputs!$C$47*37.719))*43758.5453)-INT((SIN(((A6)*12.9898+(0)*78.233+Inputs!$C$47*37.719))*43758.5453)))-1))) -> 0 | Y6: =IF(OR(Inputs!$C$27=TRUE,Inputs!$C$27="TRUE",Inputs!$C$27=1),1,0)*(Inputs!$C$51*(115*EXP(-(((Inputs!$C$6)-25)^2)/(4.5^2))+70*EXP(-(((Inputs!$C$6)+38)^2)/(7^2))*(0.55+0.45*SIN(2*PI()*(A6)/45))+24*SIN(2*PI()*(Inputs!$C$6)/9+(A6)/18)*EXP(-(((Inputs!$C$6)+5)^2)/(22^2))+18*SIN(2*PI()*(A6)/70))+Inputs!$C$28*EXP(-(((A6)-Inputs!$C$29)^2)/(2*Inputs!$C$31^2))*EXP(-(((Inputs!$C$6)-Inputs!$C$30)^2)/(2*Inputs!$C$32^2))+-Inputs!$C$33*EXP(-(((((A6)-Inputs!$C$34)^2)+(((Inputs!$C$6)-Inputs!$C$35)^2))/(2*Inputs!$C$36^2)))+Inputs!$C$37*(0.55*SIN(2*PI()*(A6)/Inputs!$C$39)+0.35*COS(2*PI()*(Inputs!$C$6)/Inputs!$C$40)+0.2*SIN(2*PI()*((A6)+(Inputs!$C$6))/(0.5*(Inputs!$C$39+Inputs!$C$40))))+Inputs!$C$38*SIN(2*PI()*(A6)/Inputs!$C$39)*SIN(2*PI()*(Inputs!$C$6)/Inputs!$C$40)+-Inputs!$C$41*EXP(-(((Inputs!$C$6)-Inputs!$C$43)^2)/(2*Inputs!$C$44^2))*EXP(-(((A6)-Inputs!$C$42)^2)/(2*Inputs!$C$45^2))+Inputs!$C$48*(0.7*(0.45*SIN(2*PI()*(((A6)/Inputs!$C$49)+Inputs!$C$47*0.137))+0.35*COS(2*PI()*(((Inputs!$C$6)/Inputs!$C$50)+Inputs!$C$47*0.173))+0.2*SIN(2*PI()*(((A6)+(Inputs!$C$6))/(0.5*(Inputs!$C$49+Inputs!$C$50))+Inputs!$C$47*0.097)))+0.3*(2*((SIN(((A6)*12.9898+(Inputs!$C$6)*78.233+Inputs!$C$47*37.719))*43758.5453)-INT((SIN(((A6)*12.9898+(Inputs!$C$6)*78.233+Inputs!$C$47*37.719))*43758.5453)))-1))) -> 0 | Z6: =B6-X6/1000 -> 403.73778 | AA6: =SQRT(A6^2+Inputs!$C$6^2+(B6-Y6/1000)^2) -> 408.64801 | AB6: =(AA6-Z6)*1000 -> 4910.2287 | AC6: =AB6/Inputs!$C$12 -> 2758.5555 | AD6: =2*AB6/Inputs!$C$21*1000000 -> 32.75752 | AE6: =DEGREES(ATAN(H6/(B6-Y6/1000))) -> 8.8909798 | AF6: =DEGREES((2*PI()/Inputs!$C$13)*Inputs!$C$15*SIN(RADIANS(AE6))) -> 55.639745 | AG6: =(Z6/AA6)^4 -> 0.9527962 | AH6: =10*LOG10(AG6) -> -0.20999985 | AI6: =AC6-F6 -> 0 | AJ6: =AD6-G6 -> 0 | AK6: =Y6-X6 -> 0 | AL6: =1000*(AA7-AA5)/(A7-A5)*Inputs!$C$11 -> -1077.0854 | AM6: =-2*AL6/Inputs!$C$13 -> 430.83415 | AN6: =-2*AL6/Inputs!$C$14 -> 64.689812 | AO6: =ABS(AM6) -> 430.83415 | AP6: =ABS(AN6) -> 64.689812 | AQ6: =IF(OR(Inputs!$C$27=TRUE,Inputs!$C$27="TRUE",Inputs!$C$27=1),Inputs!$C$46/Inputs!$C$12,0) -> 0 | AR6: =AC6-AQ6 -> 2758.5555 | AS6: =AC6+AQ6 -> 2758.5555
A7: =Inputs!$C$7+5*(Inputs!$C$8-Inputs!$C$7)/240 -> -57.5 | B7: =Inputs!$C$5+Inputs!$C$9*(A7/Inputs!$C$10)^2 -> 403.67361 | C7: =B7 -> 403.67361 | D7: =SQRT(A7^2+Inputs!$C$6^2+B7^2) -> 408.51393 | E7: =(D7-C7)*1000 -> 4840.3229 | F7: =E7/Inputs!$C$12 -> 2719.2825 | G7: =2*E7/Inputs!$C$21*1000000 -> 32.291159 | H7: =SQRT(A7^2+Inputs!$C$6^2) -> 62.699681 | I7: =DEGREES(ATAN(H7/B7)) -> 8.8287885 | J7: =DEGREES((2*PI()/Inputs!$C$13)*Inputs!$C$15*SIN(RADIANS(I7))) -> 55.253648 | K7: =(C7/D7)^4 -> 0.95344126 | L7: =10*LOG10(K7) -> -0.20706059 | M7: =2*(Inputs!$C$9/(Inputs!$C$10^2))*A7 -> -0.12777778 | N7: =M7*Inputs!$C$11 -> -0.51111111 | O7: =1000*((A7*Inputs!$C$11)+(B7*N7))/D7 -> -1068.0714 | P7: =-2*O7/Inputs!$C$13 -> 427.22858 | Q7: =-2*O7/Inputs!$C$14 -> 64.148435 | R7: =F7-Inputs!$C$16/2 -> 2704.2825 | S7: =F7+Inputs!$C$16/2 -> 2734.2825 | T7: =F7-Inputs!$C$17/2 -> 2569.2825 | U7: =F7+Inputs!$C$17/2 -> 2869.2825 | V7: =ABS(P7) -> 427.22858 | W7: =ABS(Q7) -> 64.148435 | X7: =IF(OR(Inputs!$C$27=TRUE,Inputs!$C$27="TRUE",Inputs!$C$27=1),1,0)*(Inputs!$C$51*(115*EXP(-(((0)-25)^2)/(4.5^2))+70*EXP(-(((0)+38)^2)/(7^2))*(0.55+0.45*SIN(2*PI()*(A7)/45))+24*SIN(2*PI()*(0)/9+(A7)/18)*EXP(-(((0)+5)^2)/(22^2))+18*SIN(2*PI()*(A7)/70))+Inputs!$C$28*EXP(-(((A7)-Inputs!$C$29)^2)/(2*Inputs!$C$31^2))*EXP(-(((0)-Inputs!$C$30)^2)/(2*Inputs!$C$32^2))+-Inputs!$C$33*EXP(-(((((A7)-Inputs!$C$34)^2)+(((0)-Inputs!$C$35)^2))/(2*Inputs!$C$36^2)))+Inputs!$C$37*(0.55*SIN(2*PI()*(A7)/Inputs!$C$39)+0.35*COS(2*PI()*(0)/Inputs!$C$40)+0.2*SIN(2*PI()*((A7)+(0))/(0.5*(Inputs!$C$39+Inputs!$C$40))))+Inputs!$C$38*SIN(2*PI()*(A7)/Inputs!$C$39)*SIN(2*PI()*(0)/Inputs!$C$40)+-Inputs!$C$41*EXP(-(((0)-Inputs!$C$43)^2)/(2*Inputs!$C$44^2))*EXP(-(((A7)-Inputs!$C$42)^2)/(2*Inputs!$C$45^2))+Inputs!$C$48*(0.7*(0.45*SIN(2*PI()*(((A7)/Inputs!$C$49)+Inputs!$C$47*0.137))+0.35*COS(2*PI()*(((0)/Inputs!$C$50)+Inputs!$C$47*0.173))+0.2*SIN(2*PI()*(((A7)+(0))/(0.5*(Inputs!$C$49+Inputs!$C$50))+Inputs!$C$47*0.097)))+0.3*(2*((SIN(((A7)*12.9898+(0)*78.233+Inputs!$C$47*37.719))*43758.5453)-INT((SIN(((A7)*12.9898+(0)*78.233+Inputs!$C$47*37.719))*43758.5453)))-1))) -> 0 | Y7: =IF(OR(Inputs!$C$27=TRUE,Inputs!$C$27="TRUE",Inputs!$C$27=1),1,0)*(Inputs!$C$51*(115*EXP(-(((Inputs!$C$6)-25)^2)/(4.5^2))+70*EXP(-(((Inputs!$C$6)+38)^2)/(7^2))*(0.55+0.45*SIN(2*PI()*(A7)/45))+24*SIN(2*PI()*(Inputs!$C$6)/9+(A7)/18)*EXP(-(((Inputs!$C$6)+5)^2)/(22^2))+18*SIN(2*PI()*(A7)/70))+Inputs!$C$28*EXP(-(((A7)-Inputs!$C$29)^2)/(2*Inputs!$C$31^2))*EXP(-(((Inputs!$C$6)-Inputs!$C$30)^2)/(2*Inputs!$C$32^2))+-Inputs!$C$33*EXP(-(((((A7)-Inputs!$C$34)^2)+(((Inputs!$C$6)-Inputs!$C$35)^2))/(2*Inputs!$C$36^2)))+Inputs!$C$37*(0.55*SIN(2*PI()*(A7)/Inputs!$C$39)+0.35*COS(2*PI()*(Inputs!$C$6)/Inputs!$C$40)+0.2*SIN(2*PI()*((A7)+(Inputs!$C$6))/(0.5*(Inputs!$C$39+Inputs!$C$40))))+Inputs!$C$38*SIN(2*PI()*(A7)/Inputs!$C$39)*SIN(2*PI()*(Inputs!$C$6)/Inputs!$C$40)+-Inputs!$C$41*EXP(-(((Inputs!$C$6)-Inputs!$C$43)^2)/(2*Inputs!$C$44^2))*EXP(-(((A7)-Inputs!$C$42)^2)/(2*Inputs!$C$45^2))+Inputs!$C$48*(0.7*(0.45*SIN(2*PI()*(((A7)/Inputs!$C$49)+Inputs!$C$47*0.137))+0.35*COS(2*PI()*(((Inputs!$C$6)/Inputs!$C$50)+Inputs!$C$47*0.173))+0.2*SIN(2*PI()*(((A7)+(Inputs!$C$6))/(0.5*(Inputs!$C$49+Inputs!$C$50))+Inputs!$C$47*0.097)))+0.3*(2*((SIN(((A7)*12.9898+(Inputs!$C$6)*78.233+Inputs!$C$47*37.719))*43758.5453)-INT((SIN(((A7)*12.9898+(Inputs!$C$6)*78.233+Inputs!$C$47*37.719))*43758.5453)))-1))) -> 0 | Z7: =B7-X7/1000 -> 403.67361 | AA7: =SQRT(A7^2+Inputs!$C$6^2+(B7-Y7/1000)^2) -> 408.51393 | AB7: =(AA7-Z7)*1000 -> 4840.3229 | AC7: =AB7/Inputs!$C$12 -> 2719.2825 | AD7: =2*AB7/Inputs!$C$21*1000000 -> 32.291159 | AE7: =DEGREES(ATAN(H7/(B7-Y7/1000))) -> 8.8287885 | AF7: =DEGREES((2*PI()/Inputs!$C$13)*Inputs!$C$15*SIN(RADIANS(AE7))) -> 55.253648 | AG7: =(Z7/AA7)^4 -> 0.95344126 | AH7: =10*LOG10(AG7) -> -0.20706059 | AI7: =AC7-F7 -> 0 | AJ7: =AD7-G7 -> 0 | AK7: =Y7-X7 -> 0 | AL7: =1000*(AA8-AA6)/(A8-A6)*Inputs!$C$11 -> -1068.0703 | AM7: =-2*AL7/Inputs!$C$13 -> 427.22813 | AN7: =-2*AL7/Inputs!$C$14 -> 64.148368 | AO7: =ABS(AM7) -> 427.22813 | AP7: =ABS(AN7) -> 64.148368 | AQ7: =IF(OR(Inputs!$C$27=TRUE,Inputs!$C$27="TRUE",Inputs!$C$27=1),Inputs!$C$46/Inputs!$C$12,0) -> 0 | AR7: =AC7-AQ7 -> 2719.2825 | AS7: =AC7+AQ7 -> 2719.2825
A8: =Inputs!$C$7+6*(Inputs!$C$8-Inputs!$C$7)/240 -> -57 | B8: =Inputs!$C$5+Inputs!$C$9*(A8/Inputs!$C$10)^2 -> 403.61 | C8: =B8 -> 403.61 | D8: =SQRT(A8^2+Inputs!$C$6^2+B8^2) -> 408.38099 | E8: =(D8-C8)*1000 -> 4770.9889 | F8: =E8/Inputs!$C$12 -> 2680.3308 | G8: =2*E8/Inputs!$C$21*1000000 -> 31.828612 | H8: =SQRT(A8^2+Inputs!$C$6^2) -> 62.241465 | I8: =DEGREES(ATAN(H8/B8)) -> 8.7666324 | J8: =DEGREES((2*PI()/Inputs!$C$13)*Inputs!$C$15*SIN(RADIANS(I8))) -> 54.867705 | K8: =(C8/D8)^4 -> 0.95408179 | L8: =10*LOG10(K8) -> -0.20414394 | M8: =2*(Inputs!$C$9/(Inputs!$C$10^2))*A8 -> -0.12666667 | N8: =M8*Inputs!$C$11 -> -0.50666667 | O8: =1000*((A8*Inputs!$C$11)+(B8*N8))/D8 -> -1059.0496 | P8: =-2*O8/Inputs!$C$13 -> 423.61985 | Q8: =-2*O8/Inputs!$C$14 -> 63.606584 | R8: =F8-Inputs!$C$16/2 -> 2665.3308 | S8: =F8+Inputs!$C$16/2 -> 2695.3308 | T8: =F8-Inputs!$C$17/2 -> 2530.3308 | U8: =F8+Inputs!$C$17/2 -> 2830.3308 | V8: =ABS(P8) -> 423.61985 | W8: =ABS(Q8) -> 63.606584 | X8: =IF(OR(Inputs!$C$27=TRUE,Inputs!$C$27="TRUE",Inputs!$C$27=1),1,0)*(Inputs!$C$51*(115*EXP(-(((0)-25)^2)/(4.5^2))+70*EXP(-(((0)+38)^2)/(7^2))*(0.55+0.45*SIN(2*PI()*(A8)/45))+24*SIN(2*PI()*(0)/9+(A8)/18)*EXP(-(((0)+5)^2)/(22^2))+18*SIN(2*PI()*(A8)/70))+Inputs!$C$28*EXP(-(((A8)-Inputs!$C$29)^2)/(2*Inputs!$C$31^2))*EXP(-(((0)-Inputs!$C$30)^2)/(2*Inputs!$C$32^2))+-Inputs!$C$33*EXP(-(((((A8)-Inputs!$C$34)^2)+(((0)-Inputs!$C$35)^2))/(2*Inputs!$C$36^2)))+Inputs!$C$37*(0.55*SIN(2*PI()*(A8)/Inputs!$C$39)+0.35*COS(2*PI()*(0)/Inputs!$C$40)+0.2*SIN(2*PI()*((A8)+(0))/(0.5*(Inputs!$C$39+Inputs!$C$40))))+Inputs!$C$38*SIN(2*PI()*(A8)/Inputs!$C$39)*SIN(2*PI()*(0)/Inputs!$C$40)+-Inputs!$C$41*EXP(-(((0)-Inputs!$C$43)^2)/(2*Inputs!$C$44^2))*EXP(-(((A8)-Inputs!$C$42)^2)/(2*Inputs!$C$45^2))+Inputs!$C$48*(0.7*(0.45*SIN(2*PI()*(((A8)/Inputs!$C$49)+Inputs!$C$47*0.137))+0.35*COS(2*PI()*(((0)/Inputs!$C$50)+Inputs!$C$47*0.173))+0.2*SIN(2*PI()*(((A8)+(0))/(0.5*(Inputs!$C$49+Inputs!$C$50))+Inputs!$C$47*0.097)))+0.3*(2*((SIN(((A8)*12.9898+(0)*78.233+Inputs!$C$47*37.719))*43758.5453)-INT((SIN(((A8)*12.9898+(0)*78.233+Inputs!$C$47*37.719))*43758.5453)))-1))) -> 0 | Y8: =IF(OR(Inputs!$C$27=TRUE,Inputs!$C$27="TRUE",Inputs!$C$27=1),1,0)*(Inputs!$C$51*(115*EXP(-(((Inputs!$C$6)-25)^2)/(4.5^2))+70*EXP(-(((Inputs!$C$6)+38)^2)/(7^2))*(0.55+0.45*SIN(2*PI()*(A8)/45))+24*SIN(2*PI()*(Inputs!$C$6)/9+(A8)/18)*EXP(-(((Inputs!$C$6)+5)^2)/(22^2))+18*SIN(2*PI()*(A8)/70))+Inputs!$C$28*EXP(-(((A8)-Inputs!$C$29)^2)/(2*Inputs!$C$31^2))*EXP(-(((Inputs!$C$6)-Inputs!$C$30)^2)/(2*Inputs!$C$32^2))+-Inputs!$C$33*EXP(-(((((A8)-Inputs!$C$34)^2)+(((Inputs!$C$6)-Inputs!$C$35)^2))/(2*Inputs!$C$36^2)))+Inputs!$C$37*(0.55*SIN(2*PI()*(A8)/Inputs!$C$39)+0.35*COS(2*PI()*(Inputs!$C$6)/Inputs!$C$40)+0.2*SIN(2*PI()*((A8)+(Inputs!$C$6))/(0.5*(Inputs!$C$39+Inputs!$C$40))))+Inputs!$C$38*SIN(2*PI()*(A8)/Inputs!$C$39)*SIN(2*PI()*(Inputs!$C$6)/Inputs!$C$40)+-Inputs!$C$41*EXP(-(((Inputs!$C$6)-Inputs!$C$43)^2)/(2*Inputs!$C$44^2))*EXP(-(((A8)-Inputs!$C$42)^2)/(2*Inputs!$C$45^2))+Inputs!$C$48*(0.7*(0.45*SIN(2*PI()*(((A8)/Inputs!$C$49)+Inputs!$C$47*0.137))+0.35*COS(2*PI()*(((Inputs!$C$6)/Inputs!$C$50)+Inputs!$C$47*0.173))+0.2*SIN(2*PI()*(((A8)+(Inputs!$C$6))/(0.5*(Inputs!$C$49+Inputs!$C$50))+Inputs!$C$47*0.097)))+0.3*(2*((SIN(((A8)*12.9898+(Inputs!$C$6)*78.233+Inputs!$C$47*37.719))*43758.5453)-INT((SIN(((A8)*12.9898+(Inputs!$C$6)*78.233+Inputs!$C$47*37.719))*43758.5453)))-1))) -> 0 | Z8: =B8-X8/1000 -> 403.61 | AA8: =SQRT(A8^2+Inputs!$C$6^2+(B8-Y8/1000)^2) -> 408.38099 | AB8: =(AA8-Z8)*1000 -> 4770.9889 | AC8: =AB8/Inputs!$C$12 -> 2680.3308 | AD8: =2*AB8/Inputs!$C$21*1000000 -> 31.828612 | AE8: =DEGREES(ATAN(H8/(B8-Y8/1000))) -> 8.7666324 | AF8: =DEGREES((2*PI()/Inputs!$C$13)*Inputs!$C$15*SIN(RADIANS(AE8))) -> 54.867705 | AG8: =(Z8/AA8)^4 -> 0.95408179 | AH8: =10*LOG10(AG8) -> -0.20414394 | AI8: =AC8-F8 -> 0 | AJ8: =AD8-G8 -> 0 | AK8: =Y8-X8 -> 0 | AL8: =1000*(AA9-AA7)/(A9-A7)*Inputs!$C$11 -> -1059.0485 | AM8: =-2*AL8/Inputs!$C$13 -> 423.6194 | AN8: =-2*AL8/Inputs!$C$14 -> 63.606517 | AO8: =ABS(AM8) -> 423.6194 | AP8: =ABS(AN8) -> 63.606517 | AQ8: =IF(OR(Inputs!$C$27=TRUE,Inputs!$C$27="TRUE",Inputs!$C$27=1),Inputs!$C$46/Inputs!$C$12,0) -> 0 | AR8: =AC8-AQ8 -> 2680.3308 | AS8: =AC8+AQ8 -> 2680.3308
A9: =Inputs!$C$7+7*(Inputs!$C$8-Inputs!$C$7)/240 -> -56.5 | B9: =Inputs!$C$5+Inputs!$C$9*(A9/Inputs!$C$10)^2 -> 403.54694 | C9: =B9 -> 403.54694 | D9: =SQRT(A9^2+Inputs!$C$6^2+B9^2) -> 408.24917 | E9: =(D9-C9)*1000 -> 4702.2275 | F9: =E9/Inputs!$C$12 -> 2641.7008 | G9: =2*E9/Inputs!$C$21*1000000 -> 31.369885 | H9: =SQRT(A9^2+Inputs!$C$6^2) -> 61.783898 | I9: =DEGREES(ATAN(H9/B9)) -> 8.704514 | J9: =DEGREES((2*PI()/Inputs!$C$13)*Inputs!$C$15*SIN(RADIANS(I9))) -> 54.481931 | K9: =(C9/D9)^4 -> 0.95471776 | L9: =10*LOG10(K9) -> -0.20124997 | M9: =2*(Inputs!$C$9/(Inputs!$C$10^2))*A9 -> -0.12555556 | N9: =M9*Inputs!$C$11 -> -0.50222222 | O9: =1000*((A9*Inputs!$C$11)+(B9*N9))/D9 -> -1050.0211 | P9: =-2*O9/Inputs!$C$13 -> 420.00844 | Q9: =-2*O9/Inputs!$C$14 -> 63.06433 | R9: =F9-Inputs!$C$16/2 -> 2626.7008 | S9: =F9+Inputs!$C$16/2 -> 2656.7008 | T9: =F9-Inputs!$C$17/2 -> 2491.7008 | U9: =F9+Inputs!$C$17/2 -> 2791.7008 | V9: =ABS(P9) -> 420.00844 | W9: =ABS(Q9) -> 63.06433 | X9: =IF(OR(Inputs!$C$27=TRUE,Inputs!$C$27="TRUE",Inputs!$C$27=1),1,0)*(Inputs!$C$51*(115*EXP(-(((0)-25)^2)/(4.5^2))+70*EXP(-(((0)+38)^2)/(7^2))*(0.55+0.45*SIN(2*PI()*(A9)/45))+24*SIN(2*PI()*(0)/9+(A9)/18)*EXP(-(((0)+5)^2)/(22^2))+18*SIN(2*PI()*(A9)/70))+Inputs!$C$28*EXP(-(((A9)-Inputs!$C$29)^2)/(2*Inputs!$C$31^2))*EXP(-(((0)-Inputs!$C$30)^2)/(2*Inputs!$C$32^2))+-Inputs!$C$33*EXP(-(((((A9)-Inputs!$C$34)^2)+(((0)-Inputs!$C$35)^2))/(2*Inputs!$C$36^2)))+Inputs!$C$37*(0.55*SIN(2*PI()*(A9)/Inputs!$C$39)+0.35*COS(2*PI()*(0)/Inputs!$C$40)+0.2*SIN(2*PI()*((A9)+(0))/(0.5*(Inputs!$C$39+Inputs!$C$40))))+Inputs!$C$38*SIN(2*PI()*(A9)/Inputs!$C$39)*SIN(2*PI()*(0)/Inputs!$C$40)+-Inputs!$C$41*EXP(-(((0)-Inputs!$C$43)^2)/(2*Inputs!$C$44^2))*EXP(-(((A9)-Inputs!$C$42)^2)/(2*Inputs!$C$45^2))+Inputs!$C$48*(0.7*(0.45*SIN(2*PI()*(((A9)/Inputs!$C$49)+Inputs!$C$47*0.137))+0.35*COS(2*PI()*(((0)/Inputs!$C$50)+Inputs!$C$47*0.173))+0.2*SIN(2*PI()*(((A9)+(0))/(0.5*(Inputs!$C$49+Inputs!$C$50))+Inputs!$C$47*0.097)))+0.3*(2*((SIN(((A9)*12.9898+(0)*78.233+Inputs!$C$47*37.719))*43758.5453)-INT((SIN(((A9)*12.9898+(0)*78.233+Inputs!$C$47*37.719))*43758.5453)))-1))) -> 0 | Y9: =IF(OR(Inputs!$C$27=TRUE,Inputs!$C$27="TRUE",Inputs!$C$27=1),1,0)*(Inputs!$C$51*(115*EXP(-(((Inputs!$C$6)-25)^2)/(4.5^2))+70*EXP(-(((Inputs!$C$6)+38)^2)/(7^2))*(0.55+0.45*SIN(2*PI()*(A9)/45))+24*SIN(2*PI()*(Inputs!$C$6)/9+(A9)/18)*EXP(-(((Inputs!$C$6)+5)^2)/(22^2))+18*SIN(2*PI()*(A9)/70))+Inputs!$C$28*EXP(-(((A9)-Inputs!$C$29)^2)/(2*Inputs!$C$31^2))*EXP(-(((Inputs!$C$6)-Inputs!$C$30)^2)/(2*Inputs!$C$32^2))+-Inputs!$C$33*EXP(-(((((A9)-Inputs!$C$34)^2)+(((Inputs!$C$6)-Inputs!$C$35)^2))/(2*Inputs!$C$36^2)))+Inputs!$C$37*(0.55*SIN(2*PI()*(A9)/Inputs!$C$39)+0.35*COS(2*PI()*(Inputs!$C$6)/Inputs!$C$40)+0.2*SIN(2*PI()*((A9)+(Inputs!$C$6))/(0.5*(Inputs!$C$39+Inputs!$C$40))))+Inputs!$C$38*SIN(2*PI()*(A9)/Inputs!$C$39)*SIN(2*PI()*(Inputs!$C$6)/Inputs!$C$40)+-Inputs!$C$41*EXP(-(((Inputs!$C$6)-Inputs!$C$43)^2)/(2*Inputs!$C$44^2))*EXP(-(((A9)-Inputs!$C$42)^2)/(2*Inputs!$C$45^2))+Inputs!$C$48*(0.7*(0.45*SIN(2*PI()*(((A9)/Inputs!$C$49)+Inputs!$C$47*0.137))+0.35*COS(2*PI()*(((Inputs!$C$6)/Inputs!$C$50)+Inputs!$C$47*0.173))+0.2*SIN(2*PI()*(((A9)+(Inputs!$C$6))/(0.5*(Inputs!$C$49+Inputs!$C$50))+Inputs!$C$47*0.097)))+0.3*(2*((SIN(((A9)*12.9898+(Inputs!$C$6)*78.233+Inputs!$C$47*37.719))*43758.5453)-INT((SIN(((A9)*12.9898+(Inputs!$C$6)*78.233+Inputs!$C$47*37.719))*43758.5453)))-1))) -> 0 | Z9: =B9-X9/1000 -> 403.54694 | AA9: =SQRT(A9^2+Inputs!$C$6^2+(B9-Y9/1000)^2) -> 408.24917 | AB9: =(AA9-Z9)*1000 -> 4702.2275 | AC9: =AB9/Inputs!$C$12 -> 2641.7008 | AD9: =2*AB9/Inputs!$C$21*1000000 -> 31.369885 | AE9: =DEGREES(ATAN(H9/(B9-Y9/1000))) -> 8.704514 | AF9: =DEGREES((2*PI()/Inputs!$C$13)*Inputs!$C$15*SIN(RADIANS(AE9))) -> 54.481931 | AG9: =(Z9/AA9)^4 -> 0.95471776 | AH9: =10*LOG10(AG9) -> -0.20124997 | AI9: =AC9-F9 -> 0 | AJ9: =AD9-G9 -> 0 | AK9: =Y9-X9 -> 0 | AL9: =1000*(AA10-AA8)/(A10-A8)*Inputs!$C$11 -> -1050.02 | AM9: =-2*AL9/Inputs!$C$13 -> 420.00799 | AN9: =-2*AL9/Inputs!$C$14 -> 63.064263 | AO9: =ABS(AM9) -> 420.00799 | AP9: =ABS(AN9) -> 63.064263 | AQ9: =IF(OR(Inputs!$C$27=TRUE,Inputs!$C$27="TRUE",Inputs!$C$27=1),Inputs!$C$46/Inputs!$C$12,0) -> 0 | AR9: =AC9-AQ9 -> 2641.7008 | AS9: =AC9+AQ9 -> 2641.7008
A10: =Inputs!$C$7+8*(Inputs!$C$8-Inputs!$C$7)/240 -> -56 | B10: =Inputs!$C$5+Inputs!$C$9*(A10/Inputs!$C$10)^2 -> 403.48444 | C10: =B10 -> 403.48444 | D10: =SQRT(A10^2+Inputs!$C$6^2+B10^2) -> 408.11848 | E10: =(D10-C10)*1000 -> 4634.0395 | F10: =E10/Inputs!$C$12 -> 2603.393 | G10: =2*E10/Inputs!$C$21*1000000 -> 30.914984 | H10: =SQRT(A10^2+Inputs!$C$6^2) -> 61.326992 | I10: =DEGREES(ATAN(H10/B10)) -> 8.6424357 | J10: =DEGREES((2*PI()/Inputs!$C$13)*Inputs!$C$15*SIN(RADIANS(I10))) -> 54.096342 | K10: =(C10/D10)^4 -> 0.95534916 | L10: =10*LOG10(K10) -> -0.19837875 | M10: =2*(Inputs!$C$9/(Inputs!$C$10^2))*A10 -> -0.12444444 | N10: =M10*Inputs!$C$11 -> -0.49777778 | O10: =1000*((A10*Inputs!$C$11)+(B10*N10))/D10 -> -1040.9859 | P10: =-2*O10/Inputs!$C$13 -> 416.39436 | Q10: =-2*O10/Inputs!$C$14 -> 62.521676 | R10: =F10-Inputs!$C$16/2 -> 2588.393 | S10: =F10+Inputs!$C$16/2 -> 2618.393 | T10: =F10-Inputs!$C$17/2 -> 2453.393 | U10: =F10+Inputs!$C$17/2 -> 2753.393 | V10: =ABS(P10) -> 416.39436 | W10: =ABS(Q10) -> 62.521676 | X10: =IF(OR(Inputs!$C$27=TRUE,Inputs!$C$27="TRUE",Inputs!$C$27=1),1,0)*(Inputs!$C$51*(115*EXP(-(((0)-25)^2)/(4.5^2))+70*EXP(-(((0)+38)^2)/(7^2))*(0.55+0.45*SIN(2*PI()*(A10)/45))+24*SIN(2*PI()*(0)/9+(A10)/18)*EXP(-(((0)+5)^2)/(22^2))+18*SIN(2*PI()*(A10)/70))+Inputs!$C$28*EXP(-(((A10)-Inputs!$C$29)^2)/(2*Inputs!$C$31^2))*EXP(-(((0)-Inputs!$C$30)^2)/(2*Inputs!$C$32^2))+-Inputs!$C$33*EXP(-(((((A10)-Inputs!$C$34)^2)+(((0)-Inputs!$C$35)^2))/(2*Inputs!$C$36^2)))+Inputs!$C$37*(0.55*SIN(2*PI()*(A10)/Inputs!$C$39)+0.35*COS(2*PI()*(0)/Inputs!$C$40)+0.2*SIN(2*PI()*((A10)+(0))/(0.5*(Inputs!$C$39+Inputs!$C$40))))+Inputs!$C$38*SIN(2*PI()*(A10)/Inputs!$C$39)*SIN(2*PI()*(0)/Inputs!$C$40)+-Inputs!$C$41*EXP(-(((0)-Inputs!$C$43)^2)/(2*Inputs!$C$44^2))*EXP(-(((A10)-Inputs!$C$42)^2)/(2*Inputs!$C$45^2))+Inputs!$C$48*(0.7*(0.45*SIN(2*PI()*(((A10)/Inputs!$C$49)+Inputs!$C$47*0.137))+0.35*COS(2*PI()*(((0)/Inputs!$C$50)+Inputs!$C$47*0.173))+0.2*SIN(2*PI()*(((A10)+(0))/(0.5*(Inputs!$C$49+Inputs!$C$50))+Inputs!$C$47*0.097)))+0.3*(2*((SIN(((A10)*12.9898+(0)*78.233+Inputs!$C$47*37.719))*43758.5453)-INT((SIN(((A10)*12.9898+(0)*78.233+Inputs!$C$47*37.719))*43758.5453)))-1))) -> 0 | Y10: =IF(OR(Inputs!$C$27=TRUE,Inputs!$C$27="TRUE",Inputs!$C$27=1),1,0)*(Inputs!$C$51*(115*EXP(-(((Inputs!$C$6)-25)^2)/(4.5^2))+70*EXP(-(((Inputs!$C$6)+38)^2)/(7^2))*(0.55+0.45*SIN(2*PI()*(A10)/45))+24*SIN(2*PI()*(Inputs!$C$6)/9+(A10)/18)*EXP(-(((Inputs!$C$6)+5)^2)/(22^2))+18*SIN(2*PI()*(A10)/70))+Inputs!$C$28*EXP(-(((A10)-Inputs!$C$29)^2)/(2*Inputs!$C$31^2))*EXP(-(((Inputs!$C$6)-Inputs!$C$30)^2)/(2*Inputs!$C$32^2))+-Inputs!$C$33*EXP(-(((((A10)-Inputs!$C$34)^2)+(((Inputs!$C$6)-Inputs!$C$35)^2))/(2*Inputs!$C$36^2)))+Inputs!$C$37*(0.55*SIN(2*PI()*(A10)/Inputs!$C$39)+0.35*COS(2*PI()*(Inputs!$C$6)/Inputs!$C$40)+0.2*SIN(2*PI()*((A10)+(Inputs!$C$6))/(0.5*(Inputs!$C$39+Inputs!$C$40))))+Inputs!$C$38*SIN(2*PI()*(A10)/Inputs!$C$39)*SIN(2*PI()*(Inputs!$C$6)/Inputs!$C$40)+-Inputs!$C$41*EXP(-(((Inputs!$C$6)-Inputs!$C$43)^2)/(2*Inputs!$C$44^2))*EXP(-(((A10)-Inputs!$C$42)^2)/(2*Inputs!$C$45^2))+Inputs!$C$48*(0.7*(0.45*SIN(2*PI()*(((A10)/Inputs!$C$49)+Inputs!$C$47*0.137))+0.35*COS(2*PI()*(((Inputs!$C$6)/Inputs!$C$50)+Inputs!$C$47*0.173))+0.2*SIN(2*PI()*(((A10)+(Inputs!$C$6))/(0.5*(Inputs!$C$49+Inputs!$C$50))+Inputs!$C$47*0.097)))+0.3*(2*((SIN(((A10)*12.9898+(Inputs!$C$6)*78.233+Inputs!$C$47*37.719))*43758.5453)-INT((SIN(((A10)*12.9898+(Inputs!$C$6)*78.233+Inputs!$C$47*37.719))*43758.5453)))-1))) -> 0 | Z10: =B10-X10/1000 -> 403.48444 | AA10: =SQRT(A10^2+Inputs!$C$6^2+(B10-Y10/1000)^2) -> 408.11848 | AB10: =(AA10-Z10)*1000 -> 4634.0395 | AC10: =AB10/Inputs!$C$12 -> 2603.393 | AD10: =2*AB10/Inputs!$C$21*1000000 -> 30.914984 | AE10: =DEGREES(ATAN(H10/(B10-Y10/1000))) -> 8.6424357 | AF10: =DEGREES((2*PI()/Inputs!$C$13)*Inputs!$C$15*SIN(RADIANS(AE10))) -> 54.096342 | AG10: =(Z10/AA10)^4 -> 0.95534916 | AH10: =10*LOG10(AG10) -> -0.19837875 | AI10: =AC10-F10 -> 0 | AJ10: =AD10-G10 -> 0 | AK10: =Y10-X10 -> 0 | AL10: =1000*(AA11-AA9)/(A11-A9)*Inputs!$C$11 -> -1040.9848 | AM10: =-2*AL10/Inputs!$C$13 -> 416.39392 | AN10: =-2*AL10/Inputs!$C$14 -> 62.52161 | AO10: =ABS(AM10) -> 416.39392 | AP10: =ABS(AN10) -> 62.52161 | AQ10: =IF(OR(Inputs!$C$27=TRUE,Inputs!$C$27="TRUE",Inputs!$C$27=1),Inputs!$C$46/Inputs!$C$12,0) -> 0 | AR10: =AC10-AQ10 -> 2603.393 | AS10: =AC10+AQ10 -> 2603.393
A11: =Inputs!$C$7+9*(Inputs!$C$8-Inputs!$C$7)/240 -> -55.5 | B11: =Inputs!$C$5+Inputs!$C$9*(A11/Inputs!$C$10)^2 -> 403.4225 | C11: =B11 -> 403.4225 | D11: =SQRT(A11^2+Inputs!$C$6^2+B11^2) -> 407.98893 | E11: =(D11-C11)*1000 -> 4566.4257 | F11: =E11/Inputs!$C$12 -> 2565.4077 | G11: =2*E11/Inputs!$C$21*1000000 -> 30.463913 | H11: =SQRT(A11^2+Inputs!$C$6^2) -> 60.870765 | I11: =DEGREES(ATAN(H11/B11)) -> 8.5804002 | J11: =DEGREES((2*PI()/Inputs!$C$13)*Inputs!$C$15*SIN(RADIANS(I11))) -> 53.710956 | K11: =(C11/D11)^4 -> 0.95597595 | L11: =10*LOG10(K11) -> -0.19553034 | M11: =2*(Inputs!$C$9/(Inputs!$C$10^2))*A11 -> -0.12333333 | N11: =M11*Inputs!$C$11 -> -0.49333333 | O11: =1000*((A11*Inputs!$C$11)+(B11*N11))/D11 -> -1031.9441 | P11: =-2*O11/Inputs!$C$13 -> 412.77764 | Q11: =-2*O11/Inputs!$C$14 -> 61.978625 | R11: =F11-Inputs!$C$16/2 -> 2550.4077 | S11: =F11+Inputs!$C$16/2 -> 2580.4077 | T11: =F11-Inputs!$C$17/2 -> 2415.4077 | U11: =F11+Inputs!$C$17/2 -> 2715.4077 | V11: =ABS(P11) -> 412.77764 | W11: =ABS(Q11) -> 61.978625 | X11: =IF(OR(Inputs!$C$27=TRUE,Inputs!$C$27="TRUE",Inputs!$C$27=1),1,0)*(Inputs!$C$51*(115*EXP(-(((0)-25)^2)/(4.5^2))+70*EXP(-(((0)+38)^2)/(7^2))*(0.55+0.45*SIN(2*PI()*(A11)/45))+24*SIN(2*PI()*(0)/9+(A11)/18)*EXP(-(((0)+5)^2)/(22^2))+18*SIN(2*PI()*(A11)/70))+Inputs!$C$28*EXP(-(((A11)-Inputs!$C$29)^2)/(2*Inputs!$C$31^2))*EXP(-(((0)-Inputs!$C$30)^2)/(2*Inputs!$C$32^2))+-Inputs!$C$33*EXP(-(((((A11)-Inputs!$C$34)^2)+(((0)-Inputs!$C$35)^2))/(2*Inputs!$C$36^2)))+Inputs!$C$37*(0.55*SIN(2*PI()*(A11)/Inputs!$C$39)+0.35*COS(2*PI()*(0)/Inputs!$C$40)+0.2*SIN(2*PI()*((A11)+(0))/(0.5*(Inputs!$C$39+Inputs!$C$40))))+Inputs!$C$38*SIN(2*PI()*(A11)/Inputs!$C$39)*SIN(2*PI()*(0)/Inputs!$C$40)+-Inputs!$C$41*EXP(-(((0)-Inputs!$C$43)^2)/(2*Inputs!$C$44^2))*EXP(-(((A11)-Inputs!$C$42)^2)/(2*Inputs!$C$45^2))+Inputs!$C$48*(0.7*(0.45*SIN(2*PI()*(((A11)/Inputs!$C$49)+Inputs!$C$47*0.137))+0.35*COS(2*PI()*(((0)/Inputs!$C$50)+Inputs!$C$47*0.173))+0.2*SIN(2*PI()*(((A11)+(0))/(0.5*(Inputs!$C$49+Inputs!$C$50))+Inputs!$C$47*0.097)))+0.3*(2*((SIN(((A11)*12.9898+(0)*78.233+Inputs!$C$47*37.719))*43758.5453)-INT((SIN(((A11)*12.9898+(0)*78.233+Inputs!$C$47*37.719))*43758.5453)))-1))) -> 0 | Y11: =IF(OR(Inputs!$C$27=TRUE,Inputs!$C$27="TRUE",Inputs!$C$27=1),1,0)*(Inputs!$C$51*(115*EXP(-(((Inputs!$C$6)-25)^2)/(4.5^2))+70*EXP(-(((Inputs!$C$6)+38)^2)/(7^2))*(0.55+0.45*SIN(2*PI()*(A11)/45))+24*SIN(2*PI()*(Inputs!$C$6)/9+(A11)/18)*EXP(-(((Inputs!$C$6)+5)^2)/(22^2))+18*SIN(2*PI()*(A11)/70))+Inputs!$C$28*EXP(-(((A11)-Inputs!$C$29)^2)/(2*Inputs!$C$31^2))*EXP(-(((Inputs!$C$6)-Inputs!$C$30)^2)/(2*Inputs!$C$32^2))+-Inputs!$C$33*EXP(-(((((A11)-Inputs!$C$34)^2)+(((Inputs!$C$6)-Inputs!$C$35)^2))/(2*Inputs!$C$36^2)))+Inputs!$C$37*(0.55*SIN(2*PI()*(A11)/Inputs!$C$39)+0.35*COS(2*PI()*(Inputs!$C$6)/Inputs!$C$40)+0.2*SIN(2*PI()*((A11)+(Inputs!$C$6))/(0.5*(Inputs!$C$39+Inputs!$C$40))))+Inputs!$C$38*SIN(2*PI()*(A11)/Inputs!$C$39)*SIN(2*PI()*(Inputs!$C$6)/Inputs!$C$40)+-Inputs!$C$41*EXP(-(((Inputs!$C$6)-Inputs!$C$43)^2)/(2*Inputs!$C$44^2))*EXP(-(((A11)-Inputs!$C$42)^2)/(2*Inputs!$C$45^2))+Inputs!$C$48*(0.7*(0.45*SIN(2*PI()*(((A11)/Inputs!$C$49)+Inputs!$C$47*0.137))+0.35*COS(2*PI()*(((Inputs!$C$6)/Inputs!$C$50)+Inputs!$C$47*0.173))+0.2*SIN(2*PI()*(((A11)+(Inputs!$C$6))/(0.5*(Inputs!$C$49+Inputs!$C$50))+Inputs!$C$47*0.097)))+0.3*(2*((SIN(((A11)*12.9898+(Inputs!$C$6)*78.233+Inputs!$C$47*37.719))*43758.5453)-INT((SIN(((A11)*12.9898+(Inputs!$C$6)*78.233+Inputs!$C$47*37.719))*43758.5453)))-1))) -> 0 | Z11: =B11-X11/1000 -> 403.4225 | AA11: =SQRT(A11^2+Inputs!$C$6^2+(B11-Y11/1000)^2) -> 407.98893 | AB11: =(AA11-Z11)*1000 -> 4566.4257 | AC11: =AB11/Inputs!$C$12 -> 2565.4077 | AD11: =2*AB11/Inputs!$C$21*1000000 -> 30.463913 | AE11: =DEGREES(ATAN(H11/(B11-Y11/1000))) -> 8.5804002 | AF11: =DEGREES((2*PI()/Inputs!$C$13)*Inputs!$C$15*SIN(RADIANS(AE11))) -> 53.710956 | AG11: =(Z11/AA11)^4 -> 0.95597595 | AH11: =10*LOG10(AG11) -> -0.19553034 | AI11: =AC11-F11 -> 0 | AJ11: =AD11-G11 -> 0 | AK11: =Y11-X11 -> 0 | AL11: =1000*(AA12-AA10)/(A12-A10)*Inputs!$C$11 -> -1031.943 | AM11: =-2*AL11/Inputs!$C$13 -> 412.7772 | AN11: =-2*AL11/Inputs!$C$14 -> 61.978559 | AO11: =ABS(AM11) -> 412.7772 | AP11: =ABS(AN11) -> 61.978559 | AQ11: =IF(OR(Inputs!$C$27=TRUE,Inputs!$C$27="TRUE",Inputs!$C$27=1),Inputs!$C$46/Inputs!$C$12,0) -> 0 | AR11: =AC11-AQ11 -> 2565.4077 | AS11: =AC11+AQ11 -> 2565.4077
A12: =Inputs!$C$7+10*(Inputs!$C$8-Inputs!$C$7)/240 -> -55 | B12: =Inputs!$C$5+Inputs!$C$9*(A12/Inputs!$C$10)^2 -> 403.36111 | C12: =B12 -> 403.36111 | D12: =SQRT(A12^2+Inputs!$C$6^2+B12^2) -> 407.8605 | E12: =(D12-C12)*1000 -> 4499.387 | F12: =E12/Inputs!$C$12 -> 2527.7455 | G12: =2*E12/Inputs!$C$21*1000000 -> 30.016679 | H12: =SQRT(A12^2+Inputs!$C$6^2) -> 60.41523 | I12: =DEGREES(ATAN(H12/B12)) -> 8.5184101 | J12: =DEGREES((2*PI()/Inputs!$C$13)*Inputs!$C$15*SIN(RADIANS(I12))) -> 53.325789 | K12: =(C12/D12)^4 -> 0.95659811 | L12: =10*LOG10(K12) -> -0.19270483 | M12: =2*(Inputs!$C$9/(Inputs!$C$10^2))*A12 -> -0.12222222 | N12: =M12*Inputs!$C$11 -> -0.48888889 | O12: =1000*((A12*Inputs!$C$11)+(B12*N12))/D12 -> -1022.8957 | P12: =-2*O12/Inputs!$C$13 -> 409.1583 | Q12: =-2*O12/Inputs!$C$14 -> 61.435179 | R12: =F12-Inputs!$C$16/2 -> 2512.7455 | S12: =F12+Inputs!$C$16/2 -> 2542.7455 | T12: =F12-Inputs!$C$17/2 -> 2377.7455 | U12: =F12+Inputs!$C$17/2 -> 2677.7455 | V12: =ABS(P12) -> 409.1583 | W12: =ABS(Q12) -> 61.435179 | X12: =IF(OR(Inputs!$C$27=TRUE,Inputs!$C$27="TRUE",Inputs!$C$27=1),1,0)*(Inputs!$C$51*(115*EXP(-(((0)-25)^2)/(4.5^2))+70*EXP(-(((0)+38)^2)/(7^2))*(0.55+0.45*SIN(2*PI()*(A12)/45))+24*SIN(2*PI()*(0)/9+(A12)/18)*EXP(-(((0)+5)^2)/(22^2))+18*SIN(2*PI()*(A12)/70))+Inputs!$C$28*EXP(-(((A12)-Inputs!$C$29)^2)/(2*Inputs!$C$31^2))*EXP(-(((0)-Inputs!$C$30)^2)/(2*Inputs!$C$32^2))+-Inputs!$C$33*EXP(-(((((A12)-Inputs!$C$34)^2)+(((0)-Inputs!$C$35)^2))/(2*Inputs!$C$36^2)))+Inputs!$C$37*(0.55*SIN(2*PI()*(A12)/Inputs!$C$39)+0.35*COS(2*PI()*(0)/Inputs!$C$40)+0.2*SIN(2*PI()*((A12)+(0))/(0.5*(Inputs!$C$39+Inputs!$C$40))))+Inputs!$C$38*SIN(2*PI()*(A12)/Inputs!$C$39)*SIN(2*PI()*(0)/Inputs!$C$40)+-Inputs!$C$41*EXP(-(((0)-Inputs!$C$43)^2)/(2*Inputs!$C$44^2))*EXP(-(((A12)-Inputs!$C$42)^2)/(2*Inputs!$C$45^2))+Inputs!$C$48*(0.7*(0.45*SIN(2*PI()*(((A12)/Inputs!$C$49)+Inputs!$C$47*0.137))+0.35*COS(2*PI()*(((0)/Inputs!$C$50)+Inputs!$C$47*0.173))+0.2*SIN(2*PI()*(((A12)+(0))/(0.5*(Inputs!$C$49+Inputs!$C$50))+Inputs!$C$47*0.097)))+0.3*(2*((SIN(((A12)*12.9898+(0)*78.233+Inputs!$C$47*37.719))*43758.5453)-INT((SIN(((A12)*12.9898+(0)*78.233+Inputs!$C$47*37.719))*43758.5453)))-1))) -> 0 | Y12: =IF(OR(Inputs!$C$27=TRUE,Inputs!$C$27="TRUE",Inputs!$C$27=1),1,0)*(Inputs!$C$51*(115*EXP(-(((Inputs!$C$6)-25)^2)/(4.5^2))+70*EXP(-(((Inputs!$C$6)+38)^2)/(7^2))*(0.55+0.45*SIN(2*PI()*(A12)/45))+24*SIN(2*PI()*(Inputs!$C$6)/9+(A12)/18)*EXP(-(((Inputs!$C$6)+5)^2)/(22^2))+18*SIN(2*PI()*(A12)/70))+Inputs!$C$28*EXP(-(((A12)-Inputs!$C$29)^2)/(2*Inputs!$C$31^2))*EXP(-(((Inputs!$C$6)-Inputs!$C$30)^2)/(2*Inputs!$C$32^2))+-Inputs!$C$33*EXP(-(((((A12)-Inputs!$C$34)^2)+(((Inputs!$C$6)-Inputs!$C$35)^2))/(2*Inputs!$C$36^2)))+Inputs!$C$37*(0.55*SIN(2*PI()*(A12)/Inputs!$C$39)+0.35*COS(2*PI()*(Inputs!$C$6)/Inputs!$C$40)+0.2*SIN(2*PI()*((A12)+(Inputs!$C$6))/(0.5*(Inputs!$C$39+Inputs!$C$40))))+Inputs!$C$38*SIN(2*PI()*(A12)/Inputs!$C$39)*SIN(2*PI()*(Inputs!$C$6)/Inputs!$C$40)+-Inputs!$C$41*EXP(-(((Inputs!$C$6)-Inputs!$C$43)^2)/(2*Inputs!$C$44^2))*EXP(-(((A12)-Inputs!$C$42)^2)/(2*Inputs!$C$45^2))+Inputs!$C$48*(0.7*(0.45*SIN(2*PI()*(((A12)/Inputs!$C$49)+Inputs!$C$47*0.137))+0.35*COS(2*PI()*(((Inputs!$C$6)/Inputs!$C$50)+Inputs!$C$47*0.173))+0.2*SIN(2*PI()*(((A12)+(Inputs!$C$6))/(0.5*(Inputs!$C$49+Inputs!$C$50))+Inputs!$C$47*0.097)))+0.3*(2*((SIN(((A12)*12.9898+(Inputs!$C$6)*78.233+Inputs!$C$47*37.719))*43758.5453)-INT((SIN(((A12)*12.9898+(Inputs!$C$6)*78.233+Inputs!$C$47*37.719))*43758.5453)))-1))) -> 0 | Z12: =B12-X12/1000 -> 403.36111 | AA12: =SQRT(A12^2+Inputs!$C$6^2+(B12-Y12/1000)^2) -> 407.8605 | AB12: =(AA12-Z12)*1000 -> 4499.387 | AC12: =AB12/Inputs!$C$12 -> 2527.7455 | AD12: =2*AB12/Inputs!$C$21*1000000 -> 30.016679 | AE12: =DEGREES(ATAN(H12/(B12-Y12/1000))) -> 8.5184101 | AF12: =DEGREES((2*PI()/Inputs!$C$13)*Inputs!$C$15*SIN(RADIANS(AE12))) -> 53.325789 | AG12: =(Z12/AA12)^4 -> 0.95659811 | AH12: =10*LOG10(AG12) -> -0.19270483 | AI12: =AC12-F12 -> 0 | AJ12: =AD12-G12 -> 0 | AK12: =Y12-X12 -> 0 | AL12: =1000*(AA13-AA11)/(A13-A11)*Inputs!$C$11 -> -1022.8947 | AM12: =-2*AL12/Inputs!$C$13 -> 409.15786 | AN12: =-2*AL12/Inputs!$C$14 -> 61.435114 | AO12: =ABS(AM12) -> 409.15786 | AP12: =ABS(AN12) -> 61.435114 | AQ12: =IF(OR(Inputs!$C$27=TRUE,Inputs!$C$27="TRUE",Inputs!$C$27=1),Inputs!$C$46/Inputs!$C$12,0) -> 0 | AR12: =AC12-AQ12 -> 2527.7455 | AS12: =AC12+AQ12 -> 2527.7455
